Workbook

Sheet Example Sheet
B1: Sample Descriptions
B3: Well Name | C3: Depth (mMD) | D3: % Sandstone | E3: Grain Size | F3: Max Grain Size | G3: % Fluor | H3: Brightness | I3: Gas (U) | J3: FeCO3 in SLTST | K3: FeCO3 in SST | L3: Date | M3: Time | P3: Short Hand
B4: Teringie_6_ops | C4: 1596 | D4: 50 | E4: vf-f | F4: F | I4: 5 | J4: mnr | L4: 45161 | M4: 0.54166667 | P4: f | Q4: fine
B5: Teringie_6_ops | C5: 1599 | D5: 60 | E5: vf-f, tr med | F5: M | I5: 5 | J5: mnr | L5: 45161 | M5: 0.54861111 | P5: med | Q5: medium
B6: Teringie_6_ops | C6: 1602 | D6: 65 | E6: vf-f | F6: F | I6: 5 | J6: mnr | L6: 45161 | M6: 0.55208333 | P6: crs | Q6: coarse
B7: Teringie_6_ops | C7: 1605 | D7: 50 | E7: vf, occ f | F7: F | I7: 6 | J7: tr | L7: 45161 | M7: 0.5625 | P7: v | Q7: very
B8: Teringie_6_ops | C8: 1608 | D8: 30 | E8: vf-f | F8: F | I8: 7 | J8: tr | K8: tr | L8: 45161 | M8: 0.58333333 | P8: - | Q8: to
B9: Teringie_6_ops | C9: 1611 | D9: 40 | E9: vf-f | F9: F | G9: Tr | I9: 7 | J9: tr | K9: tr | L9: 45161 | M9: 0.60416667 | P9: occ | Q9: occasional
B10: Teringie_6_ops | C10: 1614 | D10: 60 | E10: vf-f | F10: F | G10: 10 | H10: pl-mod bri | I10: 8 | J10: tr | L10: 45161 | M10: 0.625 | P10: mnr | Q10: minor
B11: Teringie_6_ops | C11: 1617 | D11: 40 | E11: vf-f | F11: F | G11: Tr | H11: pl-mod bri | I11: 7 | J11: tr | K11: mnr | L11: 45161 | M11: 0.64583333 | P11: rr | Q11: rare
B12: Teringie_6_ops | C12: 1620 | D12: 30 | E12: vf-f | F12: F | G12: 10 | H12: pl-mod bri | I12: 7 | J12: mnr | K12: mnr | L12: 45161 | M12: 0.66666667 | P12: tr | Q12: trace
B13: Teringie_6_ops | C13: 1623 | D13: 30 | E13: vff-f | F13: F | G13: 10 | H13: pl-mod bri | I13: 5 | J13: mnr | K13: tr | L13: 45161 | M13: 0.6875 | P13: mod | Q13: moderately
B14: Teringie_6_ops | C14: 1626 | D14: 80 | E14: vf-med, tr crs-v crs | F14: C | G14: 80 | H14: mod bri | I14: 77 | J14: tr | L14: 45161 | M14: 0.70833333 | P14: bri | Q14: bright
B15: Teringie_6_ops | C15: 1629 | D15: 90 | E15: f-med, tr crs-v crs | F15: C | G15: 100 | H15: mod bri-bri | I15: 100 | L15: 45161 | M15: 0.72916667 | P15: dll | Q15: dull
B16: Teringie_6_ops | C16: 1632 | D16: 95 | E16: f-med, tr crs-v crs | F16: C | G16: 100 | H16: mod bri-bri | I16: 94 | L16: 45161 | M16: 0.75 | P16: com | Q16: common
B17: Teringie_6_ops | C17: 1635 | D17: 100 | E17: f-med,tr crs | F17: C | G17: 100 | H17: mod bri-bri | I17: 102 | L17: 45161 | M17: 0.77083333 | P17: i/p | Q17: in part
P18: dom | Q18: dominantly
P19: pl | Q19: pale

Sheet Input Sheet
B1: Sample Descriptions
B3: Depth (mMD) | C3: % Sandstone | D3: Grain Size | E3: Max Grain Size | F3: % Fluor | G3: Brightness | H3: Gas (U) | I3: FeCO3 in SLTST | J3: FeCO3 in SST | K3: Date | L3: Time | O3: Short Hand
B4: 1715 | C4: 35 | D4: f | E4: =IF(ISNUMBER(SEARCH("v crs",D4))=TRUE,"VC",IF(ISNUMBER(SEARCH("crs",D4))=TRUE,"C",IF(ISNUMBER(SEARCH("med",D4))=TRUE,"M",IF(ISNUMBER(SEARCH("vf",D4))=TRUE,"VF",IF(ISNUMBER(SEARCH("f",D4))=TRUE,"F",""))))) -> F | F4: 5 | G4: dim | H4: 22.6 | I4: tr | O4: f | P4: fine | Q4: =IF(C4="","",IF(OR(K4="",AND(ISNUMBER(Q4),C4=Q4)),Q4,C4)) | R4: =IF(C4="","",IF(OR(L4="",AND(ISNUMBER(R4),C4=R4)),R4,C4))
B5: 1720 | C5: 35 | D5: f | E5: =IF(ISNUMBER(SEARCH("v crs",D5))=TRUE,"VC",IF(ISNUMBER(SEARCH("crs",D5))=TRUE,"C",IF(ISNUMBER(SEARCH("med",D5))=TRUE,"M",IF(ISNUMBER(SEARCH("vf",D5))=TRUE,"VF",IF(ISNUMBER(SEARCH("f",D5))=TRUE,"F",""))))) -> F | F5: 5 | G5: dim | H5: 22.6 | O5: med | P5: medium | Q5: =IF(C5="","",IF(OR(K5="",AND(ISNUMBER(Q5),C5=Q5)),Q5,C5)) | R5: =IF(C5="","",IF(OR(L5="",AND(ISNUMBER(R5),C5=R5)),R5,C5))
B6: 1785 | C6: 40 | D6: f | E6: =IF(ISNUMBER(SEARCH("v crs",D6))=TRUE,"VC",IF(ISNUMBER(SEARCH("crs",D6))=TRUE,"C",IF(ISNUMBER(SEARCH("med",D6))=TRUE,"M",IF(ISNUMBER(SEARCH("vf",D6))=TRUE,"VF",IF(ISNUMBER(SEARCH("f",D6))=TRUE,"F",""))))) -> F | F6: 100 | G6: dim | H6: 39.4 | O6: crs | P6: coarse | Q6: =IF(C6="","",IF(OR(K6="",AND(ISNUMBER(Q6),C6=Q6)),Q6,C6)) | R6: =IF(C6="","",IF(OR(L6="",AND(ISNUMBER(R6),C6=R6)),R6,C6))
B7: 1790 | C7: 40 | D7: f | E7: =IF(ISNUMBER(SEARCH("v crs",D7))=TRUE,"VC",IF(ISNUMBER(SEARCH("crs",D7))=TRUE,"C",IF(ISNUMBER(SEARCH("med",D7))=TRUE,"M",IF(ISNUMBER(SEARCH("vf",D7))=TRUE,"VF",IF(ISNUMBER(SEARCH("f",D7))=TRUE,"F",""))))) -> F | F7: 100 | G7: dim | H7: 24 | O7: v | P7: very | Q7: =IF(C7="","",IF(OR(K7="",AND(ISNUMBER(Q7),C7=Q7)),Q7,C7)) | R7: =IF(C7="","",IF(OR(L7="",AND(ISNUMBER(R7),C7=R7)),R7,C7))
B8: 1795 | C8: 80 | D8: f | E8: =IF(ISNUMBER(SEARCH("v crs",D8))=TRUE,"VC",IF(ISNUMBER(SEARCH("crs",D8))=TRUE,"C",IF(ISNUMBER(SEARCH("med",D8))=TRUE,"M",IF(ISNUMBER(SEARCH("vf",D8))=TRUE,"VF",IF(ISNUMBER(SEARCH("f",D8))=TRUE,"F",""))))) -> F | F8: 100 | G8: dim | H8: 26.4 | O8: - | P8: to | Q8: =IF(C8="","",IF(OR(K8="",AND(ISNUMBER(Q8),C8=Q8)),Q8,C8)) | R8: =IF(C8="","",IF(OR(L8="",AND(ISNUMBER(R8),C8=R8)),R8,C8))
B9: 1800 | C9: 60 | D9: f | E9: =IF(ISNUMBER(SEARCH("v crs",D9))=TRUE,"VC",IF(ISNUMBER(SEARCH("crs",D9))=TRUE,"C",IF(ISNUMBER(SEARCH("med",D9))=TRUE,"M",IF(ISNUMBER(SEARCH("vf",D9))=TRUE,"VF",IF(ISNUMBER(SEARCH("f",D9))=TRUE,"F",""))))) -> F | F9: 100 | G9: dim | H9: 20.4 | O9: occ | P9: occasional | Q9: =IF(C9="","",IF(OR(K9="",AND(ISNUMBER(Q9),C9=Q9)),Q9,C9)) | R9: =IF(C9="","",IF(OR(L9="",AND(ISNUMBER(R9),C9=R9)),R9,C9))
B10: 1805 | C10: 60 | D10: f | E10: =IF(ISNUMBER(SEARCH("v crs",D10))=TRUE,"VC",IF(ISNUMBER(SEARCH("crs",D10))=TRUE,"C",IF(ISNUMBER(SEARCH("med",D10))=TRUE,"M",IF(ISNUMBER(SEARCH("vf",D10))=TRUE,"VF",IF(ISNUMBER(SEARCH("f",D10))=TRUE,"F",""))))) -> F | F10: 10 | G10: dim | H10: 14.5 | O10: mnr | P10: minor | Q10: =IF(C10="","",IF(OR(K10="",AND(ISNUMBER(Q10),C10=Q10)),Q10,C10)) | R10: =IF(C10="","",IF(OR(L10="",AND(ISNUMBER(R10),C10=R10)),R10,C10))
B11: 1810 | C11: 50 | D11: f | E11: =IF(ISNUMBER(SEARCH("v crs",D11))=TRUE,"VC",IF(ISNUMBER(SEARCH("crs",D11))=TRUE,"C",IF(ISNUMBER(SEARCH("med",D11))=TRUE,"M",IF(ISNUMBER(SEARCH("vf",D11))=TRUE,"VF",IF(ISNUMBER(SEARCH("f",D11))=TRUE,"F",""))))) -> F | F11: 10 | G11: dim | H11: 16.2 | O11: rr | P11: rare | Q11: =IF(C11="","",IF(OR(K11="",AND(ISNUMBER(Q11),C11=Q11)),Q11,C11)) | R11: =IF(C11="","",IF(OR(L11="",AND(ISNUMBER(R11),C11=R11)),R11,C11))
B12: 1895 | C12: 15 | D12: f | E12: =IF(ISNUMBER(SEARCH("v crs",D12))=TRUE,"VC",IF(ISNUMBER(SEARCH("crs",D12))=TRUE,"C",IF(ISNUMBER(SEARCH("med",D12))=TRUE,"M",IF(ISNUMBER(SEARCH("vf",D12))=TRUE,"VF",IF(ISNUMBER(SEARCH("f",D12))=TRUE,"F",""))))) -> F | F12: 20 | G12: dim | H12: 7.8 | I12: tr | O12: tr | P12: trace | Q12: =IF(C12="","",IF(OR(K12="",AND(ISNUMBER(Q12),C12=Q12)),Q12,C12)) | R12: =IF(C12="","",IF(OR(L12="",AND(ISNUMBER(R12),C12=R12)),R12,C12))
B13: 1900 | C13: 15 | D13: f | E13: =IF(ISNUMBER(SEARCH("v crs",D13))=TRUE,"VC",IF(ISNUMBER(SEARCH("crs",D13))=TRUE,"C",IF(ISNUMBER(SEARCH("med",D13))=TRUE,"M",IF(ISNUMBER(SEARCH("vf",D13))=TRUE,"VF",IF(ISNUMBER(SEARCH("f",D13))=TRUE,"F",""))))) -> F | F13: 50 | G13: dim | H13: 7.4 | O13: mod | P13: moderately | Q13: =IF(C13="","",IF(OR(K13="",AND(ISNUMBER(Q13),C13=Q13)),Q13,C13)) | R13: =IF(C13="","",IF(OR(L13="",AND(ISNUMBER(R13),C13=R13)),R13,C13))
B14: 1905 | C14: 10 | D14: f | E14: =IF(ISNUMBER(SEARCH("v crs",D14))=TRUE,"VC",IF(ISNUMBER(SEARCH("crs",D14))=TRUE,"C",IF(ISNUMBER(SEARCH("med",D14))=TRUE,"M",IF(ISNUMBER(SEARCH("vf",D14))=TRUE,"VF",IF(ISNUMBER(SEARCH("f",D14))=TRUE,"F",""))))) -> F | F14: 100 | G14: dull | H14: 17.9 | O14: bri | P14: bright | Q14: =IF(C14="","",IF(OR(K14="",AND(ISNUMBER(Q14),C14=Q14)),Q14,C14)) | R14: =IF(C14="","",IF(OR(L14="",AND(ISNUMBER(R14),C14=R14)),R14,C14))
B15: 1910 | C15: 10 | D15: f | E15: =IF(ISNUMBER(SEARCH("v crs",D15))=TRUE,"VC",IF(ISNUMBER(SEARCH("crs",D15))=TRUE,"C",IF(ISNUMBER(SEARCH("med",D15))=TRUE,"M",IF(ISNUMBER(SEARCH("vf",D15))=TRUE,"VF",IF(ISNUMBER(SEARCH("f",D15))=TRUE,"F",""))))) -> F | F15: 100 | G15: dull | H15: 15.3 | I15: com | O15: dll | P15: dull | Q15: =IF(C15="","",IF(OR(K15="",AND(ISNUMBER(Q15),C15=Q15)),Q15,C15)) | R15: =IF(C15="","",IF(OR(L15="",AND(ISNUMBER(R15),C15=R15)),R15,C15))
B16: 1915 | C16: 20 | D16: f | E16: =IF(ISNUMBER(SEARCH("v crs",D16))=TRUE,"VC",IF(ISNUMBER(SEARCH("crs",D16))=TRUE,"C",IF(ISNUMBER(SEARCH("med",D16))=TRUE,"M",IF(ISNUMBER(SEARCH("vf",D16))=TRUE,"VF",IF(ISNUMBER(SEARCH("f",D16))=TRUE,"F",""))))) -> F | F16: 100 | G16: dull | H16: 20.4 | O16: com | P16: common | Q16: =IF(C16="","",IF(OR(K16="",AND(ISNUMBER(Q16),C16=Q16)),Q16,C16)) | R16: =IF(C16="","",IF(OR(L16="",AND(ISNUMBER(R16),C16=R16)),R16,C16))
B17: 1920 | C17: 20 | D17: f | E17: =IF(ISNUMBER(SEARCH("v crs",D17))=TRUE,"VC",IF(ISNUMBER(SEARCH("crs",D17))=TRUE,"C",IF(ISNUMBER(SEARCH("med",D17))=TRUE,"M",IF(ISNUMBER(SEARCH("vf",D17))=TRUE,"VF",IF(ISNUMBER(SEARCH("f",D17))=TRUE,"F",""))))) -> F | F17: 100 | G17: dull | H17: 10.8 | O17: i/p | P17: in part | Q17: =IF(C17="","",IF(OR(K17="",AND(ISNUMBER(Q17),C17=Q17)),Q17,C17)) | R17: =IF(C17="","",IF(OR(L17="",AND(ISNUMBER(R17),C17=R17)),R17,C17))
B18: 1925 | C18: 10 | D18: f | E18: =IF(ISNUMBER(SEARCH("v crs",D18))=TRUE,"VC",IF(ISNUMBER(SEARCH("crs",D18))=TRUE,"C",IF(ISNUMBER(SEARCH("med",D18))=TRUE,"M",IF(ISNUMBER(SEARCH("vf",D18))=TRUE,"VF",IF(ISNUMBER(SEARCH("f",D18))=TRUE,"F",""))))) -> F | F18: 100 | G18: dull | H18: 19.4 | K18: =IF(AND(C18<>"",C18<>Q18),TODAY(),IF(C18="","",K18)) | L18: =IF(AND(C18<>"",C18<>R18),NOW(),IF(C18="","",L18)) | O18: dom | P18: dominantly | Q18: =IF(C18="","",IF(OR(K18="",AND(ISNUMBER(Q18),C18=Q18)),Q18,C18)) | R18: =IF(C18="","",IF(OR(L18="",AND(ISNUMBER(R18),C18=R18)),R18,C18))
B19: 1930 | C19: 10 | D19: f | E19: =IF(ISNUMBER(SEARCH("v crs",D19))=TRUE,"VC",IF(ISNUMBER(SEARCH("crs",D19))=TRUE,"C",IF(ISNUMBER(SEARCH("med",D19))=TRUE,"M",IF(ISNUMBER(SEARCH("vf",D19))=TRUE,"VF",IF(ISNUMBER(SEARCH("f",D19))=TRUE,"F",""))))) -> F | F19: 100 | G19: dull | H19: 19 | K19: =IF(AND(C19<>"",C19<>Q19),TODAY(),IF(C19="","",K19)) | L19: =IF(AND(C19<>"",C19<>R19),NOW(),IF(C19="","",L19)) | O19: pl | P19: pale | Q19: =IF(C19="","",IF(OR(K19="",AND(ISNUMBER(Q19),C19=Q19)),Q19,C19)) | R19: =IF(C19="","",IF(OR(L19="",AND(ISNUMBER(R19),C19=R19)),R19,C19))
B20: 1935 | C20: 20 | D20: f | E20: =IF(ISNUMBER(SEARCH("v crs",D20))=TRUE,"VC",IF(ISNUMBER(SEARCH("crs",D20))=TRUE,"C",IF(ISNUMBER(SEARCH("med",D20))=TRUE,"M",IF(ISNUMBER(SEARCH("vf",D20))=TRUE,"VF",IF(ISNUMBER(SEARCH("f",D20))=TRUE,"F",""))))) -> F | F20: 100 | G20: dull | H20: 21.5 | K20: =IF(AND(C20<>"",C20<>Q20),TODAY(),IF(C20="","",K20)) | L20: =IF(AND(C20<>"",C20<>R20),NOW(),IF(C20="","",L20)) | Q20: =IF(C20="","",IF(OR(K20="",AND(ISNUMBER(Q20),C20=Q20)),Q20,C20)) | R20: =IF(C20="","",IF(OR(L20="",AND(ISNUMBER(R20),C20=R20)),R20,C20))
B21: 1940 | C21: 20 | D21: f | E21: =IF(ISNUMBER(SEARCH("v crs",D21))=TRUE,"VC",IF(ISNUMBER(SEARCH("crs",D21))=TRUE,"C",IF(ISNUMBER(SEARCH("med",D21))=TRUE,"M",IF(ISNUMBER(SEARCH("vf",D21))=TRUE,"VF",IF(ISNUMBER(SEARCH("f",D21))=TRUE,"F",""))))) -> F | F21: 100 | G21: dull | H21: 13.6 | I21: com | K21: =IF(AND(C21<>"",C21<>Q21),TODAY(),IF(C21="","",K21)) | L21: =IF(AND(C21<>"",C21<>R21),NOW(),IF(C21="","",L21)) | Q21: =IF(C21="","",IF(OR(K21="",AND(ISNUMBER(Q21),C21=Q21)),Q21,C21)) | R21: =IF(C21="","",IF(OR(L21="",AND(ISNUMBER(R21),C21=R21)),R21,C21))
B22: 1945 | C22: 20 | D22: f | E22: =IF(ISNUMBER(SEARCH("v crs",D22))=TRUE,"VC",IF(ISNUMBER(SEARCH("crs",D22))=TRUE,"C",IF(ISNUMBER(SEARCH("med",D22))=TRUE,"M",IF(ISNUMBER(SEARCH("vf",D22))=TRUE,"VF",IF(ISNUMBER(SEARCH("f",D22))=TRUE,"F",""))))) -> F | F22: 100 | G22: dull | H22: 15.1 | K22: =IF(AND(C22<>"",C22<>Q22),TODAY(),IF(C22="","",K22)) | L22: =IF(AND(C22<>"",C22<>R22),NOW(),IF(C22="","",L22)) | Q22: =IF(C22="","",IF(OR(K22="",AND(ISNUMBER(Q22),C22=Q22)),Q22,C22)) | R22: =IF(C22="","",IF(OR(L22="",AND(ISNUMBER(R22),C22=R22)),R22,C22))
B23: 1950 | C23: 20 | D23: f | E23: =IF(ISNUMBER(SEARCH("v crs",D23))=TRUE,"VC",IF(ISNUMBER(SEARCH("crs",D23))=TRUE,"C",IF(ISNUMBER(SEARCH("med",D23))=TRUE,"M",IF(ISNUMBER(SEARCH("vf",D23))=TRUE,"VF",IF(ISNUMBER(SEARCH("f",D23))=TRUE,"F",""))))) -> F | F23: 100 | G23: dull | H23: 23.2 | K23: =IF(AND(C23<>"",C23<>Q23),TODAY(),IF(C23="","",K23)) | L23: =IF(AND(C23<>"",C23<>R23),NOW(),IF(C23="","",L23)) | Q23: =IF(C23="","",IF(OR(K23="",AND(ISNUMBER(Q23),C23=Q23)),Q23,C23)) | R23: =IF(C23="","",IF(OR(L23="",AND(ISNUMBER(R23),C23=R23)),R23,C23))
B24: 1955 | C24: 25 | D24: f | E24: =IF(ISNUMBER(SEARCH("v crs",D24))=TRUE,"VC",IF(ISNUMBER(SEARCH("crs",D24))=TRUE,"C",IF(ISNUMBER(SEARCH("med",D24))=TRUE,"M",IF(ISNUMBER(SEARCH("vf",D24))=TRUE,"VF",IF(ISNUMBER(SEARCH("f",D24))=TRUE,"F",""))))) -> F | F24: 100 | G24: pale | H24: 23 | K24: =IF(AND(C24<>"",C24<>Q24),TODAY(),IF(C24="","",K24)) | L24: =IF(AND(C24<>"",C24<>R24),NOW(),IF(C24="","",L24)) | Q24: =IF(C24="","",IF(OR(K24="",AND(ISNUMBER(Q24),C24=Q24)),Q24,C24)) | R24: =IF(C24="","",IF(OR(L24="",AND(ISNUMBER(R24),C24=R24)),R24,C24))
B25: 1960 | C25: 25 | D25: f | E25: =IF(ISNUMBER(SEARCH("v crs",D25))=TRUE,"VC",IF(ISNUMBER(SEARCH("crs",D25))=TRUE,"C",IF(ISNUMBER(SEARCH("med",D25))=TRUE,"M",IF(ISNUMBER(SEARCH("vf",D25))=TRUE,"VF",IF(ISNUMBER(SEARCH("f",D25))=TRUE,"F",""))))) -> F | F25: 100 | G25: pale | H25: 19.7 | I25: tr | K25: =IF(AND(C25<>"",C25<>Q25),TODAY(),IF(C25="","",K25)) | L25: =IF(AND(C25<>"",C25<>R25),NOW(),IF(C25="","",L25)) | Q25: =IF(C25="","",IF(OR(K25="",AND(ISNUMBER(Q25),C25=Q25)),Q25,C25)) | R25: =IF(C25="","",IF(OR(L25="",AND(ISNUMBER(R25),C25=R25)),R25,C25))
B26: 1965 | C26: 30 | D26: f | E26: =IF(ISNUMBER(SEARCH("v crs",D26))=TRUE,"VC",IF(ISNUMBER(SEARCH("crs",D26))=TRUE,"C",IF(ISNUMBER(SEARCH("med",D26))=TRUE,"M",IF(ISNUMBER(SEARCH("vf",D26))=TRUE,"VF",IF(ISNUMBER(SEARCH("f",D26))=TRUE,"F",""))))) -> F | F26: 100 | G26: pale | H26: 19.8 | K26: =IF(AND(C26<>"",C26<>Q26),TODAY(),IF(C26="","",K26)) | L26: =IF(AND(C26<>"",C26<>R26),NOW(),IF(C26="","",L26)) | Q26: =IF(C26="","",IF(OR(K26="",AND(ISNUMBER(Q26),C26=Q26)),Q26,C26)) | R26: =IF(C26="","",IF(OR(L26="",AND(ISNUMBER(R26),C26=R26)),R26,C26))
B27: 1970 | C27: 30 | D27: f | E27: =IF(ISNUMBER(SEARCH("v crs",D27))=TRUE,"VC",IF(ISNUMBER(SEARCH("crs",D27))=TRUE,"C",IF(ISNUMBER(SEARCH("med",D27))=TRUE,"M",IF(ISNUMBER(SEARCH("vf",D27))=TRUE,"VF",IF(ISNUMBER(SEARCH("f",D27))=TRUE,"F",""))))) -> F | F27: 100 | G27: pale | H27: 23.7 | K27: =IF(AND(C27<>"",C27<>Q27),TODAY(),IF(C27="","",K27)) | L27: =IF(AND(C27<>"",C27<>R27),NOW(),IF(C27="","",L27)) | Q27: =IF(C27="","",IF(OR(K27="",AND(ISNUMBER(Q27),C27=Q27)),Q27,C27)) | R27: =IF(C27="","",IF(OR(L27="",AND(ISNUMBER(R27),C27=R27)),R27,C27))
B28: 1975 | C28: 30 | D28: f | E28: =IF(ISNUMBER(SEARCH("v crs",D28))=TRUE,"VC",IF(ISNUMBER(SEARCH("crs",D28))=TRUE,"C",IF(ISNUMBER(SEARCH("med",D28))=TRUE,"M",IF(ISNUMBER(SEARCH("vf",D28))=TRUE,"VF",IF(ISNUMBER(SEARCH("f",D28))=TRUE,"F",""))))) -> F | F28: 100 | G28: pale | H28: 25 | K28: =IF(AND(C28<>"",C28<>Q28),TODAY(),IF(C28="","",K28)) | L28: =IF(AND(C28<>"",C28<>R28),NOW(),IF(C28="","",L28)) | Q28: =IF(C28="","",IF(OR(K28="",AND(ISNUMBER(Q28),C28=Q28)),Q28,C28)) | R28: =IF(C28="","",IF(OR(L28="",AND(ISNUMBER(R28),C28=R28)),R28,C28))
B29: 1980 | C29: 30 | D29: f | E29: =IF(ISNUMBER(SEARCH("v crs",D29))=TRUE,"VC",IF(ISNUMBER(SEARCH("crs",D29))=TRUE,"C",IF(ISNUMBER(SEARCH("med",D29))=TRUE,"M",IF(ISNUMBER(SEARCH("vf",D29))=TRUE,"VF",IF(ISNUMBER(SEARCH("f",D29))=TRUE,"F",""))))) -> F | F29: 100 | G29: pale | H29: 19.1 | K29: =IF(AND(C29<>"",C29<>Q29),TODAY(),IF(C29="","",K29)) | L29: =IF(AND(C29<>"",C29<>R29),NOW(),IF(C29="","",L29)) | Q29: =IF(C29="","",IF(OR(K29="",AND(ISNUMBER(Q29),C29=Q29)),Q29,C29)) | R29: =IF(C29="","",IF(OR(L29="",AND(ISNUMBER(R29),C29=R29)),R29,C29))
B30: 1985 | C30: 30 | D30: f | E30: =IF(ISNUMBER(SEARCH("v crs",D30))=TRUE,"VC",IF(ISNUMBER(SEARCH("crs",D30))=TRUE,"C",IF(ISNUMBER(SEARCH("med",D30))=TRUE,"M",IF(ISNUMBER(SEARCH("vf",D30))=TRUE,"VF",IF(ISNUMBER(SEARCH("f",D30))=TRUE,"F",""))))) -> F | F30: 100 | G30: pl-mod bri | H30: 21.1 | K30: =IF(AND(C30<>"",C30<>Q30),TODAY(),IF(C30="","",K30)) | L30: =IF(AND(C30<>"",C30<>R30),NOW(),IF(C30="","",L30)) | Q30: =IF(C30="","",IF(OR(K30="",AND(ISNUMBER(Q30),C30=Q30)),Q30,C30)) | R30: =IF(C30="","",IF(OR(L30="",AND(ISNUMBER(R30),C30=R30)),R30,C30))
B31: 1990 | C31: 30 | D31: f | E31: =IF(ISNUMBER(SEARCH("v crs",D31))=TRUE,"VC",IF(ISNUMBER(SEARCH("crs",D31))=TRUE,"C",IF(ISNUMBER(SEARCH("med",D31))=TRUE,"M",IF(ISNUMBER(SEARCH("vf",D31))=TRUE,"VF",IF(ISNUMBER(SEARCH("f",D31))=TRUE,"F",""))))) -> F | F31: 100 | G31: pl-mod bri | H31: 25.1 | K31: =IF(AND(C31<>"",C31<>Q31),TODAY(),IF(C31="","",K31)) | L31: =IF(AND(C31<>"",C31<>R31),NOW(),IF(C31="","",L31)) | Q31: =IF(C31="","",IF(OR(K31="",AND(ISNUMBER(Q31),C31=Q31)),Q31,C31)) | R31: =IF(C31="","",IF(OR(L31="",AND(ISNUMBER(R31),C31=R31)),R31,C31))
B32: 1995 | C32: 40 | D32: f | E32: =IF(ISNUMBER(SEARCH("v crs",D32))=TRUE,"VC",IF(ISNUMBER(SEARCH("crs",D32))=TRUE,"C",IF(ISNUMBER(SEARCH("med",D32))=TRUE,"M",IF(ISNUMBER(SEARCH("vf",D32))=TRUE,"VF",IF(ISNUMBER(SEARCH("f",D32))=TRUE,"F",""))))) -> F | F32: 100 | G32: pl-mod bri | H32: 25.7 | K32: =IF(AND(C32<>"",C32<>Q32),TODAY(),IF(C32="","",K32)) | L32: =IF(AND(C32<>"",C32<>R32),NOW(),IF(C32="","",L32)) | Q32: =IF(C32="","",IF(OR(K32="",AND(ISNUMBER(Q32),C32=Q32)),Q32,C32)) | R32: =IF(C32="","",IF(OR(L32="",AND(ISNUMBER(R32),C32=R32)),R32,C32))
B33: 2000 | C33: 40 | D33: f | E33: =IF(ISNUMBER(SEARCH("v crs",D33))=TRUE,"VC",IF(ISNUMBER(SEARCH("crs",D33))=TRUE,"C",IF(ISNUMBER(SEARCH("med",D33))=TRUE,"M",IF(ISNUMBER(SEARCH("vf",D33))=TRUE,"VF",IF(ISNUMBER(SEARCH("f",D33))=TRUE,"F",""))))) -> F | F33: 100 | G33: pl-mod bri | H33: 22.4 | I33: com | K33: =IF(AND(C33<>"",C33<>Q33),TODAY(),IF(C33="","",K33)) | L33: =IF(AND(C33<>"",C33<>R33),NOW(),IF(C33="","",L33)) | Q33: =IF(C33="","",IF(OR(K33="",AND(ISNUMBER(Q33),C33=Q33)),Q33,C33)) | R33: =IF(C33="","",IF(OR(L33="",AND(ISNUMBER(R33),C33=R33)),R33,C33))
B34: 2005 | C34: 30 | D34: f | E34: =IF(ISNUMBER(SEARCH("v crs",D34))=TRUE,"VC",IF(ISNUMBER(SEARCH("crs",D34))=TRUE,"C",IF(ISNUMBER(SEARCH("med",D34))=TRUE,"M",IF(ISNUMBER(SEARCH("vf",D34))=TRUE,"VF",IF(ISNUMBER(SEARCH("f",D34))=TRUE,"F",""))))) -> F | F34: 100 | G34: pl-mod bri | H34: 17.4 | K34: =IF(AND(C34<>"",C34<>Q34),TODAY(),IF(C34="","",K34)) | L34: =IF(AND(C34<>"",C34<>R34),NOW(),IF(C34="","",L34)) | Q34: =IF(C34="","",IF(OR(K34="",AND(ISNUMBER(Q34),C34=Q34)),Q34,C34)) | R34: =IF(C34="","",IF(OR(L34="",AND(ISNUMBER(R34),C34=R34)),R34,C34))
B35: 2010 | C35: 30 | D35: f | E35: =IF(ISNUMBER(SEARCH("v crs",D35))=TRUE,"VC",IF(ISNUMBER(SEARCH("crs",D35))=TRUE,"C",IF(ISNUMBER(SEARCH("med",D35))=TRUE,"M",IF(ISNUMBER(SEARCH("vf",D35))=TRUE,"VF",IF(ISNUMBER(SEARCH("f",D35))=TRUE,"F",""))))) -> F | F35: 100 | G35: pl-mod bri | H35: 21.2 | I35: com | K35: =IF(AND(C35<>"",C35<>Q35),TODAY(),IF(C35="","",K35)) | L35: =IF(AND(C35<>"",C35<>R35),NOW(),IF(C35="","",L35)) | Q35: =IF(C35="","",IF(OR(K35="",AND(ISNUMBER(Q35),C35=Q35)),Q35,C35)) | R35: =IF(C35="","",IF(OR(L35="",AND(ISNUMBER(R35),C35=R35)),R35,C35))
B36: 2015 | C36: 30 | D36: f | E36: =IF(ISNUMBER(SEARCH("v crs",D36))=TRUE,"VC",IF(ISNUMBER(SEARCH("crs",D36))=TRUE,"C",IF(ISNUMBER(SEARCH("med",D36))=TRUE,"M",IF(ISNUMBER(SEARCH("vf",D36))=TRUE,"VF",IF(ISNUMBER(SEARCH("f",D36))=TRUE,"F",""))))) -> F | F36: 100 | G36: mod bri | H36: 16.6 | K36: =IF(AND(C36<>"",C36<>Q36),TODAY(),IF(C36="","",K36)) | L36: =IF(AND(C36<>"",C36<>R36),NOW(),IF(C36="","",L36)) | Q36: =IF(C36="","",IF(OR(K36="",AND(ISNUMBER(Q36),C36=Q36)),Q36,C36)) | R36: =IF(C36="","",IF(OR(L36="",AND(ISNUMBER(R36),C36=R36)),R36,C36))
B37: 2020 | C37: 30 | D37: f | E37: =IF(ISNUMBER(SEARCH("v crs",D37))=TRUE,"VC",IF(ISNUMBER(SEARCH("crs",D37))=TRUE,"C",IF(ISNUMBER(SEARCH("med",D37))=TRUE,"M",IF(ISNUMBER(SEARCH("vf",D37))=TRUE,"VF",IF(ISNUMBER(SEARCH("f",D37))=TRUE,"F",""))))) -> F | F37: 100 | G37: mod bri | H37: 23.6 | I37: com | K37: =IF(AND(C37<>"",C37<>Q37),TODAY(),IF(C37="","",K37)) | L37: =IF(AND(C37<>"",C37<>R37),NOW(),IF(C37="","",L37)) | Q37: =IF(C37="","",IF(OR(K37="",AND(ISNUMBER(Q37),C37=Q37)),Q37,C37)) | R37: =IF(C37="","",IF(OR(L37="",AND(ISNUMBER(R37),C37=R37)),R37,C37))
B38: 2025 | C38: 40 | D38: f | E38: =IF(ISNUMBER(SEARCH("v crs",D38))=TRUE,"VC",IF(ISNUMBER(SEARCH("crs",D38))=TRUE,"C",IF(ISNUMBER(SEARCH("med",D38))=TRUE,"M",IF(ISNUMBER(SEARCH("vf",D38))=TRUE,"VF",IF(ISNUMBER(SEARCH("f",D38))=TRUE,"F",""))))) -> F | F38: 100 | G38: mod bri | H38: 27.9 | K38: =IF(AND(C38<>"",C38<>Q38),TODAY(),IF(C38="","",K38)) | L38: =IF(AND(C38<>"",C38<>R38),NOW(),IF(C38="","",L38)) | Q38: =IF(C38="","",IF(OR(K38="",AND(ISNUMBER(Q38),C38=Q38)),Q38,C38)) | R38: =IF(C38="","",IF(OR(L38="",AND(ISNUMBER(R38),C38=R38)),R38,C38))
B39: 2030 | C39: 40 | D39: f | E39: =IF(ISNUMBER(SEARCH("v crs",D39))=TRUE,"VC",IF(ISNUMBER(SEARCH("crs",D39))=TRUE,"C",IF(ISNUMBER(SEARCH("med",D39))=TRUE,"M",IF(ISNUMBER(SEARCH("vf",D39))=TRUE,"VF",IF(ISNUMBER(SEARCH("f",D39))=TRUE,"F",""))))) -> F | F39: 100 | G39: mod bri | H39: 29.9 | I39: tr | K39: =IF(AND(C39<>"",C39<>Q39),TODAY(),IF(C39="","",K39)) | L39: =IF(AND(C39<>"",C39<>R39),NOW(),IF(C39="","",L39)) | Q39: =IF(C39="","",IF(OR(K39="",AND(ISNUMBER(Q39),C39=Q39)),Q39,C39)) | R39: =IF(C39="","",IF(OR(L39="",AND(ISNUMBER(R39),C39=R39)),R39,C39))
B40: 2035 | C40: 40 | D40: f | E40: =IF(ISNUMBER(SEARCH("v crs",D40))=TRUE,"VC",IF(ISNUMBER(SEARCH("crs",D40))=TRUE,"C",IF(ISNUMBER(SEARCH("med",D40))=TRUE,"M",IF(ISNUMBER(SEARCH("vf",D40))=TRUE,"VF",IF(ISNUMBER(SEARCH("f",D40))=TRUE,"F",""))))) -> F | F40: 100 | G40: mod bri | H40: 17.9 | K40: =IF(AND(C40<>"",C40<>Q40),TODAY(),IF(C40="","",K40)) | L40: =IF(AND(C40<>"",C40<>R40),NOW(),IF(C40="","",L40)) | Q40: =IF(C40="","",IF(OR(K40="",AND(ISNUMBER(Q40),C40=Q40)),Q40,C40)) | R40: =IF(C40="","",IF(OR(L40="",AND(ISNUMBER(R40),C40=R40)),R40,C40))
B41: 2040 | C41: 40 | D41: f | E41: =IF(ISNUMBER(SEARCH("v crs",D41))=TRUE,"VC",IF(ISNUMBER(SEARCH("crs",D41))=TRUE,"C",IF(ISNUMBER(SEARCH("med",D41))=TRUE,"M",IF(ISNUMBER(SEARCH("vf",D41))=TRUE,"VF",IF(ISNUMBER(SEARCH("f",D41))=TRUE,"F",""))))) -> F | F41: 100 | G41: mod bri | H41: 23.4 | K41: =IF(AND(C41<>"",C41<>Q41),TODAY(),IF(C41="","",K41)) | L41: =IF(AND(C41<>"",C41<>R41),NOW(),IF(C41="","",L41)) | Q41: =IF(C41="","",IF(OR(K41="",AND(ISNUMBER(Q41),C41=Q41)),Q41,C41)) | R41: =IF(C41="","",IF(OR(L41="",AND(ISNUMBER(R41),C41=R41)),R41,C41))
...

Sheet Long Sample Name
A1: Description
A2: =IF('Input Sheet'!C4="","",CONCATENATE("Sample ", 'Input Sheet'!B4, "m: ", L2, F2, "% ", "Siltstone, ", N2, 'Input Sheet'!C4, "% ", H2, " Sandstone, ", J2, I2, " FLUOR in SST. ", "TG ", 'Input Sheet'!H4, "U")) -> Sample 1715m: trace siderite in 65% Siltstone, 35% fine Sandstone, 5% dim FLUOR in SST. TG 22.6U | F2: =IF('Input Sheet'!C4="","",100-'Input Sheet'!C4) -> 65 | G2: =SUBSTITUTE(SUBSTITUTE(SUBSTITUTE(SUBSTITUTE(SUBSTITUTE(SUBSTITUTE(SUBSTITUTE(SUBSTITUTE(SUBSTITUTE(SUBSTITUTE(SUBSTITUTE(SUBSTITUTE(SUBSTITUTE(SUBSTITUTE(SUBSTITUTE(SUBSTITUTE(SUBSTITUTE(SUBSTITUTE(SUBSTITUTE(SUBSTITUTE(SUBSTITUTE(SUBSTITUTE(SUBSTITUTE(SUBSTITUTE(SUBSTITUTE(SUBSTITUTE(SUBSTITUTE(SUBSTITUTE(SUBSTITUTE(SUBSTITUTE(SUBSTITUTE('Input Sheet'!D4,$C$3,$D$3),$C$4,$D$4),$C$5,$D$5),$C$6,$D$6),$C$7,$D$7),$C$8,$D$8),$C$9,$D$9),$C$10,$D$10),$C$11,$D$11),$C$12,$D$12),$C$13,$D$13),$C$14,$D$14),$C$15,$D$15),$C$16,$D$16),$C$17,$D$17),$C$18,$D$18),$C$19,$D$19),$C$20,$D$20),$C$21,$D$21),$C$22,$D$22),$C$23,$D$23),$C$24,$D$24),$C$25,$D$25),$C$26,$D$26),$C$27,$D$27),$C$28,$D$28),$C$29,$D$29),$C$30,$D$30),$C$31,$D$31),$C$32,$D$32),$C$33,$D$33) -> fine | H2: =SUBSTITUTE(G2, "veryfine", "very fine") -> fine | I2: =SUBSTITUTE(SUBSTITUTE(SUBSTITUTE(SUBSTITUTE(SUBSTITUTE(SUBSTITUTE(SUBSTITUTE(SUBSTITUTE(SUBSTITUTE(SUBSTITUTE(SUBSTITUTE(SUBSTITUTE(SUBSTITUTE(SUBSTITUTE(SUBSTITUTE(SUBSTITUTE(SUBSTITUTE(SUBSTITUTE(SUBSTITUTE(SUBSTITUTE(SUBSTITUTE(SUBSTITUTE(SUBSTITUTE(SUBSTITUTE(SUBSTITUTE(SUBSTITUTE(SUBSTITUTE(SUBSTITUTE(SUBSTITUTE(SUBSTITUTE(SUBSTITUTE('Input Sheet'!G4,$C$3,$D$3),$C$4,$D$4),$C$5,$D$5),$C$6,$D$6),$C$7,$D$7),$C$8,$D$8),$C$9,$D$9),$C$10,$D$10),$C$11,$D$11),$C$12,$D$12),$C$13,$D$13),$C$14,$D$14),$C$15,$D$15),$C$16,$D$16),$C$17,$D$17),$C$18,$D$18),$C$19,$D$19),$C$20,$D$20),$C$21,$D$21),$C$22,$D$22),$C$23,$D$23),$C$24,$D$24),$C$25,$D$25),$C$26,$D$26),$C$27,$D$27),$C$28,$D$28),$C$29,$D$29),$C$30,$D$30),$C$31,$D$31),$C$32,$D$32),$C$33,$D$33) -> dim | J2: =IF('Input Sheet'!F4=0, "NO",CONCATENATE('Input Sheet'!F4, IF('Input Sheet'!F4>0,"% ",""))) -> 5% | K2: =SUBSTITUTE(SUBSTITUTE(SUBSTITUTE(SUBSTITUTE(SUBSTITUTE(SUBSTITUTE(SUBSTITUTE(SUBSTITUTE(SUBSTITUTE(SUBSTITUTE(SUBSTITUTE(SUBSTITUTE(SUBSTITUTE(SUBSTITUTE(SUBSTITUTE(SUBSTITUTE(SUBSTITUTE(SUBSTITUTE(SUBSTITUTE(SUBSTITUTE(SUBSTITUTE(SUBSTITUTE(SUBSTITUTE(SUBSTITUTE(SUBSTITUTE(SUBSTITUTE(SUBSTITUTE(SUBSTITUTE(SUBSTITUTE(SUBSTITUTE(SUBSTITUTE('Input Sheet'!I4,$C$3,$D$3),$C$4,$D$4),$C$5,$D$5),$C$6,$D$6),$C$7,$D$7),$C$8,$D$8),$C$9,$D$9),$C$10,$D$10),$C$11,$D$11),$C$12,$D$12),$C$13,$D$13),$C$14,$D$14),$C$15,$D$15),$C$16,$D$16),$C$17,$D$17),$C$18,$D$18),$C$19,$D$19),$C$20,$D$20),$C$21,$D$21),$C$22,$D$22),$C$23,$D$23),$C$24,$D$24),$C$25,$D$25),$C$26,$D$26),$C$27,$D$27),$C$28,$D$28),$C$29,$D$29),$C$30,$D$30),$C$31,$D$31),$C$32,$D$32),$C$33,$D$33) -> trace | L2: =CONCATENATE(K2, IF('Input Sheet'!I4="",""," siderite in ")) -> trace siderite in | M2: =SUBSTITUTE(SUBSTITUTE(SUBSTITUTE(SUBSTITUTE(SUBSTITUTE(SUBSTITUTE(SUBSTITUTE(SUBSTITUTE(SUBSTITUTE(SUBSTITUTE(SUBSTITUTE(SUBSTITUTE(SUBSTITUTE(SUBSTITUTE(SUBSTITUTE(SUBSTITUTE(SUBSTITUTE(SUBSTITUTE(SUBSTITUTE(SUBSTITUTE(SUBSTITUTE(SUBSTITUTE(SUBSTITUTE(SUBSTITUTE(SUBSTITUTE(SUBSTITUTE(SUBSTITUTE(SUBSTITUTE(SUBSTITUTE(SUBSTITUTE(SUBSTITUTE('Input Sheet'!J4,$C$3,$D$3),$C$4,$D$4),$C$5,$D$5),$C$6,$D$6),$C$7,$D$7),$C$8,$D$8),$C$9,$D$9),$C$10,$D$10),$C$11,$D$11),$C$12,$D$12),$C$13,$D$13),$C$14,$D$14),$C$15,$D$15),$C$16,$D$16),$C$17,$D$17),$C$18,$D$18),$C$19,$D$19),$C$20,$D$20),$C$21,$D$21),$C$22,$D$22),$C$23,$D$23),$C$24,$D$24),$C$25,$D$25),$C$26,$D$26),$C$27,$D$27),$C$28,$D$28),$C$29,$D$29),$C$30,$D$30),$C$31,$D$31),$C$32,$D$32),$C$33,$D$33) | N2: =CONCATENATE(M2, IF('Input Sheet'!J4="",""," siderite in "))
A3: =IF('Input Sheet'!C5="","",CONCATENATE("Sample ", 'Input Sheet'!B5, "m: ", L3, F3, "% ", "Siltstone, ", N3, 'Input Sheet'!C5, "% ", H3, " Sandstone, ", J3, I3, " FLUOR in SST. ", "TG ", 'Input Sheet'!H5, "U")) -> Sample 1720m: 65% Siltstone, 35% fine Sandstone, 5% dim FLUOR in SST. TG 22.6U | F3: =IF('Input Sheet'!C5="","",100-'Input Sheet'!C5) -> 65 | G3: =SUBSTITUTE(SUBSTITUTE(SUBSTITUTE(SUBSTITUTE(SUBSTITUTE(SUBSTITUTE(SUBSTITUTE(SUBSTITUTE(SUBSTITUTE(SUBSTITUTE(SUBSTITUTE(SUBSTITUTE(SUBSTITUTE(SUBSTITUTE(SUBSTITUTE(SUBSTITUTE(SUBSTITUTE(SUBSTITUTE(SUBSTITUTE(SUBSTITUTE(SUBSTITUTE(SUBSTITUTE(SUBSTITUTE(SUBSTITUTE(SUBSTITUTE(SUBSTITUTE(SUBSTITUTE(SUBSTITUTE(SUBSTITUTE(SUBSTITUTE(SUBSTITUTE('Input Sheet'!D5,$C$3,$D$3),$C$4,$D$4),$C$5,$D$5),$C$6,$D$6),$C$7,$D$7),$C$8,$D$8),$C$9,$D$9),$C$10,$D$10),$C$11,$D$11),$C$12,$D$12),$C$13,$D$13),$C$14,$D$14),$C$15,$D$15),$C$16,$D$16),$C$17,$D$17),$C$18,$D$18),$C$19,$D$19),$C$20,$D$20),$C$21,$D$21),$C$22,$D$22),$C$23,$D$23),$C$24,$D$24),$C$25,$D$25),$C$26,$D$26),$C$27,$D$27),$C$28,$D$28),$C$29,$D$29),$C$30,$D$30),$C$31,$D$31),$C$32,$D$32),$C$33,$D$33) -> fine | H3: =SUBSTITUTE(G3, "veryfine", "very fine") -> fine | I3: =SUBSTITUTE(SUBSTITUTE(SUBSTITUTE(SUBSTITUTE(SUBSTITUTE(SUBSTITUTE(SUBSTITUTE(SUBSTITUTE(SUBSTITUTE(SUBSTITUTE(SUBSTITUTE(SUBSTITUTE(SUBSTITUTE(SUBSTITUTE(SUBSTITUTE(SUBSTITUTE(SUBSTITUTE(SUBSTITUTE(SUBSTITUTE(SUBSTITUTE(SUBSTITUTE(SUBSTITUTE(SUBSTITUTE(SUBSTITUTE(SUBSTITUTE(SUBSTITUTE(SUBSTITUTE(SUBSTITUTE(SUBSTITUTE(SUBSTITUTE(SUBSTITUTE('Input Sheet'!G5,$C$3,$D$3),$C$4,$D$4),$C$5,$D$5),$C$6,$D$6),$C$7,$D$7),$C$8,$D$8),$C$9,$D$9),$C$10,$D$10),$C$11,$D$11),$C$12,$D$12),$C$13,$D$13),$C$14,$D$14),$C$15,$D$15),$C$16,$D$16),$C$17,$D$17),$C$18,$D$18),$C$19,$D$19),$C$20,$D$20),$C$21,$D$21),$C$22,$D$22),$C$23,$D$23),$C$24,$D$24),$C$25,$D$25),$C$26,$D$26),$C$27,$D$27),$C$28,$D$28),$C$29,$D$29),$C$30,$D$30),$C$31,$D$31),$C$32,$D$32),$C$33,$D$33) -> dim | J3: =IF('Input Sheet'!F5=0, "NO",CONCATENATE('Input Sheet'!F5, IF('Input Sheet'!F5>0,"% ",""))) -> 5% | K3: =SUBSTITUTE(SUBSTITUTE(SUBSTITUTE(SUBSTITUTE(SUBSTITUTE(SUBSTITUTE(SUBSTITUTE(SUBSTITUTE(SUBSTITUTE(SUBSTITUTE(SUBSTITUTE(SUBSTITUTE(SUBSTITUTE(SUBSTITUTE(SUBSTITUTE(SUBSTITUTE(SUBSTITUTE(SUBSTITUTE(SUBSTITUTE(SUBSTITUTE(SUBSTITUTE(SUBSTITUTE(SUBSTITUTE(SUBSTITUTE(SUBSTITUTE(SUBSTITUTE(SUBSTITUTE(SUBSTITUTE(SUBSTITUTE(SUBSTITUTE(SUBSTITUTE('Input Sheet'!I5,$C$3,$D$3),$C$4,$D$4),$C$5,$D$5),$C$6,$D$6),$C$7,$D$7),$C$8,$D$8),$C$9,$D$9),$C$10,$D$10),$C$11,$D$11),$C$12,$D$12),$C$13,$D$13),$C$14,$D$14),$C$15,$D$15),$C$16,$D$16),$C$17,$D$17),$C$18,$D$18),$C$19,$D$19),$C$20,$D$20),$C$21,$D$21),$C$22,$D$22),$C$23,$D$23),$C$24,$D$24),$C$25,$D$25),$C$26,$D$26),$C$27,$D$27),$C$28,$D$28),$C$29,$D$29),$C$30,$D$30),$C$31,$D$31),$C$32,$D$32),$C$33,$D$33) | L3: =CONCATENATE(K3, IF('Input Sheet'!I5="",""," siderite in ")) | M3: =SUBSTITUTE(SUBSTITUTE(SUBSTITUTE(SUBSTITUTE(SUBSTITUTE(SUBSTITUTE(SUBSTITUTE(SUBSTITUTE(SUBSTITUTE(SUBSTITUTE(SUBSTITUTE(SUBSTITUTE(SUBSTITUTE(SUBSTITUTE(SUBSTITUTE(SUBSTITUTE(SUBSTITUTE(SUBSTITUTE(SUBSTITUTE(SUBSTITUTE(SUBSTITUTE(SUBSTITUTE(SUBSTITUTE(SUBSTITUTE(SUBSTITUTE(SUBSTITUTE(SUBSTITUTE(SUBSTITUTE(SUBSTITUTE(SUBSTITUTE(SUBSTITUTE('Input Sheet'!J5,$C$3,$D$3),$C$4,$D$4),$C$5,$D$5),$C$6,$D$6),$C$7,$D$7),$C$8,$D$8),$C$9,$D$9),$C$10,$D$10),$C$11,$D$11),$C$12,$D$12),$C$13,$D$13),$C$14,$D$14),$C$15,$D$15),$C$16,$D$16),$C$17,$D$17),$C$18,$D$18),$C$19,$D$19),$C$20,$D$20),$C$21,$D$21),$C$22,$D$22),$C$23,$D$23),$C$24,$D$24),$C$25,$D$25),$C$26,$D$26),$C$27,$D$27),$C$28,$D$28),$C$29,$D$29),$C$30,$D$30),$C$31,$D$31),$C$32,$D$32),$C$33,$D$33) | N3: =CONCATENATE(M3, IF('Input Sheet'!J5="",""," siderite in "))
A4: =IF('Input Sheet'!C6="","",CONCATENATE("Sample ", 'Input Sheet'!B6, "m: ", L4, F4, "% ", "Siltstone, ", N4, 'Input Sheet'!C6, "% ", H4, " Sandstone, ", J4, I4, " FLUOR in SST. ", "TG ", 'Input Sheet'!H6, "U")) -> Sample 1785m: 60% Siltstone, 40% fine Sandstone, 100% dim FLUOR in SST. TG 39.4U | C4: f | D4: fine | F4: =IF('Input Sheet'!C6="","",100-'Input Sheet'!C6) -> 60 | G4: =SUBSTITUTE(SUBSTITUTE(SUBSTITUTE(SUBSTITUTE(SUBSTITUTE(SUBSTITUTE(SUBSTITUTE(SUBSTITUTE(SUBSTITUTE(SUBSTITUTE(SUBSTITUTE(SUBSTITUTE(SUBSTITUTE(SUBSTITUTE(SUBSTITUTE(SUBSTITUTE(SUBSTITUTE(SUBSTITUTE(SUBSTITUTE(SUBSTITUTE(SUBSTITUTE(SUBSTITUTE(SUBSTITUTE(SUBSTITUTE(SUBSTITUTE(SUBSTITUTE(SUBSTITUTE(SUBSTITUTE(SUBSTITUTE(SUBSTITUTE(SUBSTITUTE('Input Sheet'!D6,$C$3,$D$3),$C$4,$D$4),$C$5,$D$5),$C$6,$D$6),$C$7,$D$7),$C$8,$D$8),$C$9,$D$9),$C$10,$D$10),$C$11,$D$11),$C$12,$D$12),$C$13,$D$13),$C$14,$D$14),$C$15,$D$15),$C$16,$D$16),$C$17,$D$17),$C$18,$D$18),$C$19,$D$19),$C$20,$D$20),$C$21,$D$21),$C$22,$D$22),$C$23,$D$23),$C$24,$D$24),$C$25,$D$25),$C$26,$D$26),$C$27,$D$27),$C$28,$D$28),$C$29,$D$29),$C$30,$D$30),$C$31,$D$31),$C$32,$D$32),$C$33,$D$33) -> fine | H4: =SUBSTITUTE(G4, "veryfine", "very fine") -> fine | I4: =SUBSTITUTE(SUBSTITUTE(SUBSTITUTE(SUBSTITUTE(SUBSTITUTE(SUBSTITUTE(SUBSTITUTE(SUBSTITUTE(SUBSTITUTE(SUBSTITUTE(SUBSTITUTE(SUBSTITUTE(SUBSTITUTE(SUBSTITUTE(SUBSTITUTE(SUBSTITUTE(SUBSTITUTE(SUBSTITUTE(SUBSTITUTE(SUBSTITUTE(SUBSTITUTE(SUBSTITUTE(SUBSTITUTE(SUBSTITUTE(SUBSTITUTE(SUBSTITUTE(SUBSTITUTE(SUBSTITUTE(SUBSTITUTE(SUBSTITUTE(SUBSTITUTE('Input Sheet'!G6,$C$3,$D$3),$C$4,$D$4),$C$5,$D$5),$C$6,$D$6),$C$7,$D$7),$C$8,$D$8),$C$9,$D$9),$C$10,$D$10),$C$11,$D$11),$C$12,$D$12),$C$13,$D$13),$C$14,$D$14),$C$15,$D$15),$C$16,$D$16),$C$17,$D$17),$C$18,$D$18),$C$19,$D$19),$C$20,$D$20),$C$21,$D$21),$C$22,$D$22),$C$23,$D$23),$C$24,$D$24),$C$25,$D$25),$C$26,$D$26),$C$27,$D$27),$C$28,$D$28),$C$29,$D$29),$C$30,$D$30),$C$31,$D$31),$C$32,$D$32),$C$33,$D$33) -> dim | J4: =IF('Input Sheet'!F6=0, "NO",CONCATENATE('Input Sheet'!F6, IF('Input Sheet'!F6>0,"% ",""))) -> 100% | K4: =SUBSTITUTE(SUBSTITUTE(SUBSTITUTE(SUBSTITUTE(SUBSTITUTE(SUBSTITUTE(SUBSTITUTE(SUBSTITUTE(SUBSTITUTE(SUBSTITUTE(SUBSTITUTE(SUBSTITUTE(SUBSTITUTE(SUBSTITUTE(SUBSTITUTE(SUBSTITUTE(SUBSTITUTE(SUBSTITUTE(SUBSTITUTE(SUBSTITUTE(SUBSTITUTE(SUBSTITUTE(SUBSTITUTE(SUBSTITUTE(SUBSTITUTE(SUBSTITUTE(SUBSTITUTE(SUBSTITUTE(SUBSTITUTE(SUBSTITUTE(SUBSTITUTE('Input Sheet'!I6,$C$3,$D$3),$C$4,$D$4),$C$5,$D$5),$C$6,$D$6),$C$7,$D$7),$C$8,$D$8),$C$9,$D$9),$C$10,$D$10),$C$11,$D$11),$C$12,$D$12),$C$13,$D$13),$C$14,$D$14),$C$15,$D$15),$C$16,$D$16),$C$17,$D$17),$C$18,$D$18),$C$19,$D$19),$C$20,$D$20),$C$21,$D$21),$C$22,$D$22),$C$23,$D$23),$C$24,$D$24),$C$25,$D$25),$C$26,$D$26),$C$27,$D$27),$C$28,$D$28),$C$29,$D$29),$C$30,$D$30),$C$31,$D$31),$C$32,$D$32),$C$33,$D$33) | L4: =CONCATENATE(K4, IF('Input Sheet'!I6="",""," siderite in ")) | M4: =SUBSTITUTE(SUBSTITUTE(SUBSTITUTE(SUBSTITUTE(SUBSTITUTE(SUBSTITUTE(SUBSTITUTE(SUBSTITUTE(SUBSTITUTE(SUBSTITUTE(SUBSTITUTE(SUBSTITUTE(SUBSTITUTE(SUBSTITUTE(SUBSTITUTE(SUBSTITUTE(SUBSTITUTE(SUBSTITUTE(SUBSTITUTE(SUBSTITUTE(SUBSTITUTE(SUBSTITUTE(SUBSTITUTE(SUBSTITUTE(SUBSTITUTE(SUBSTITUTE(SUBSTITUTE(SUBSTITUTE(SUBSTITUTE(SUBSTITUTE(SUBSTITUTE('Input Sheet'!J6,$C$3,$D$3),$C$4,$D$4),$C$5,$D$5),$C$6,$D$6),$C$7,$D$7),$C$8,$D$8),$C$9,$D$9),$C$10,$D$10),$C$11,$D$11),$C$12,$D$12),$C$13,$D$13),$C$14,$D$14),$C$15,$D$15),$C$16,$D$16),$C$17,$D$17),$C$18,$D$18),$C$19,$D$19),$C$20,$D$20),$C$21,$D$21),$C$22,$D$22),$C$23,$D$23),$C$24,$D$24),$C$25,$D$25),$C$26,$D$26),$C$27,$D$27),$C$28,$D$28),$C$29,$D$29),$C$30,$D$30),$C$31,$D$31),$C$32,$D$32),$C$33,$D$33) | N4: =CONCATENATE(M4, IF('Input Sheet'!J6="",""," siderite in "))
A5: =IF('Input Sheet'!C7="","",CONCATENATE("Sample ", 'Input Sheet'!B7, "m: ", L5, F5, "% ", "Siltstone, ", N5, 'Input Sheet'!C7, "% ", H5, " Sandstone, ", J5, I5, " FLUOR in SST. ", "TG ", 'Input Sheet'!H7, "U")) -> Sample 1790m: 60% Siltstone, 40% fine Sandstone, 100% dim FLUOR in SST. TG 24U | C5: med | D5: medium | F5: =IF('Input Sheet'!C7="","",100-'Input Sheet'!C7) -> 60 | G5: =SUBSTITUTE(SUBSTITUTE(SUBSTITUTE(SUBSTITUTE(SUBSTITUTE(SUBSTITUTE(SUBSTITUTE(SUBSTITUTE(SUBSTITUTE(SUBSTITUTE(SUBSTITUTE(SUBSTITUTE(SUBSTITUTE(SUBSTITUTE(SUBSTITUTE(SUBSTITUTE(SUBSTITUTE(SUBSTITUTE(SUBSTITUTE(SUBSTITUTE(SUBSTITUTE(SUBSTITUTE(SUBSTITUTE(SUBSTITUTE(SUBSTITUTE(SUBSTITUTE(SUBSTITUTE(SUBSTITUTE(SUBSTITUTE(SUBSTITUTE(SUBSTITUTE('Input Sheet'!D7,$C$3,$D$3),$C$4,$D$4),$C$5,$D$5),$C$6,$D$6),$C$7,$D$7),$C$8,$D$8),$C$9,$D$9),$C$10,$D$10),$C$11,$D$11),$C$12,$D$12),$C$13,$D$13),$C$14,$D$14),$C$15,$D$15),$C$16,$D$16),$C$17,$D$17),$C$18,$D$18),$C$19,$D$19),$C$20,$D$20),$C$21,$D$21),$C$22,$D$22),$C$23,$D$23),$C$24,$D$24),$C$25,$D$25),$C$26,$D$26),$C$27,$D$27),$C$28,$D$28),$C$29,$D$29),$C$30,$D$30),$C$31,$D$31),$C$32,$D$32),$C$33,$D$33) -> fine | H5: =SUBSTITUTE(G5, "veryfine", "very fine") -> fine | I5: =SUBSTITUTE(SUBSTITUTE(SUBSTITUTE(SUBSTITUTE(SUBSTITUTE(SUBSTITUTE(SUBSTITUTE(SUBSTITUTE(SUBSTITUTE(SUBSTITUTE(SUBSTITUTE(SUBSTITUTE(SUBSTITUTE(SUBSTITUTE(SUBSTITUTE(SUBSTITUTE(SUBSTITUTE(SUBSTITUTE(SUBSTITUTE(SUBSTITUTE(SUBSTITUTE(SUBSTITUTE(SUBSTITUTE(SUBSTITUTE(SUBSTITUTE(SUBSTITUTE(SUBSTITUTE(SUBSTITUTE(SUBSTITUTE(SUBSTITUTE(SUBSTITUTE('Input Sheet'!G7,$C$3,$D$3),$C$4,$D$4),$C$5,$D$5),$C$6,$D$6),$C$7,$D$7),$C$8,$D$8),$C$9,$D$9),$C$10,$D$10),$C$11,$D$11),$C$12,$D$12),$C$13,$D$13),$C$14,$D$14),$C$15,$D$15),$C$16,$D$16),$C$17,$D$17),$C$18,$D$18),$C$19,$D$19),$C$20,$D$20),$C$21,$D$21),$C$22,$D$22),$C$23,$D$23),$C$24,$D$24),$C$25,$D$25),$C$26,$D$26),$C$27,$D$27),$C$28,$D$28),$C$29,$D$29),$C$30,$D$30),$C$31,$D$31),$C$32,$D$32),$C$33,$D$33) -> dim | J5: =IF('Input Sheet'!F7=0, "NO",CONCATENATE('Input Sheet'!F7, IF('Input Sheet'!F7>0,"% ",""))) -> 100% | K5: =SUBSTITUTE(SUBSTITUTE(SUBSTITUTE(SUBSTITUTE(SUBSTITUTE(SUBSTITUTE(SUBSTITUTE(SUBSTITUTE(SUBSTITUTE(SUBSTITUTE(SUBSTITUTE(SUBSTITUTE(SUBSTITUTE(SUBSTITUTE(SUBSTITUTE(SUBSTITUTE(SUBSTITUTE(SUBSTITUTE(SUBSTITUTE(SUBSTITUTE(SUBSTITUTE(SUBSTITUTE(SUBSTITUTE(SUBSTITUTE(SUBSTITUTE(SUBSTITUTE(SUBSTITUTE(SUBSTITUTE(SUBSTITUTE(SUBSTITUTE(SUBSTITUTE('Input Sheet'!I7,$C$3,$D$3),$C$4,$D$4),$C$5,$D$5),$C$6,$D$6),$C$7,$D$7),$C$8,$D$8),$C$9,$D$9),$C$10,$D$10),$C$11,$D$11),$C$12,$D$12),$C$13,$D$13),$C$14,$D$14),$C$15,$D$15),$C$16,$D$16),$C$17,$D$17),$C$18,$D$18),$C$19,$D$19),$C$20,$D$20),$C$21,$D$21),$C$22,$D$22),$C$23,$D$23),$C$24,$D$24),$C$25,$D$25),$C$26,$D$26),$C$27,$D$27),$C$28,$D$28),$C$29,$D$29),$C$30,$D$30),$C$31,$D$31),$C$32,$D$32),$C$33,$D$33) | L5: =CONCATENATE(K5, IF('Input Sheet'!I7="",""," siderite in ")) | M5: =SUBSTITUTE(SUBSTITUTE(SUBSTITUTE(SUBSTITUTE(SUBSTITUTE(SUBSTITUTE(SUBSTITUTE(SUBSTITUTE(SUBSTITUTE(SUBSTITUTE(SUBSTITUTE(SUBSTITUTE(SUBSTITUTE(SUBSTITUTE(SUBSTITUTE(SUBSTITUTE(SUBSTITUTE(SUBSTITUTE(SUBSTITUTE(SUBSTITUTE(SUBSTITUTE(SUBSTITUTE(SUBSTITUTE(SUBSTITUTE(SUBSTITUTE(SUBSTITUTE(SUBSTITUTE(SUBSTITUTE(SUBSTITUTE(SUBSTITUTE(SUBSTITUTE('Input Sheet'!J7,$C$3,$D$3),$C$4,$D$4),$C$5,$D$5),$C$6,$D$6),$C$7,$D$7),$C$8,$D$8),$C$9,$D$9),$C$10,$D$10),$C$11,$D$11),$C$12,$D$12),$C$13,$D$13),$C$14,$D$14),$C$15,$D$15),$C$16,$D$16),$C$17,$D$17),$C$18,$D$18),$C$19,$D$19),$C$20,$D$20),$C$21,$D$21),$C$22,$D$22),$C$23,$D$23),$C$24,$D$24),$C$25,$D$25),$C$26,$D$26),$C$27,$D$27),$C$28,$D$28),$C$29,$D$29),$C$30,$D$30),$C$31,$D$31),$C$32,$D$32),$C$33,$D$33) | N5: =CONCATENATE(M5, IF('Input Sheet'!J7="",""," siderite in "))
A6: =IF('Input Sheet'!C8="","",CONCATENATE("Sample ", 'Input Sheet'!B8, "m: ", L6, F6, "% ", "Siltstone, ", N6, 'Input Sheet'!C8, "% ", H6, " Sandstone, ", J6, I6, " FLUOR in SST. ", "TG ", 'Input Sheet'!H8, "U")) -> Sample 1795m: 20% Siltstone, 80% fine Sandstone, 100% dim FLUOR in SST. TG 26.4U | C6: crs | D6: coarse | F6: =IF('Input Sheet'!C8="","",100-'Input Sheet'!C8) -> 20 | G6: =SUBSTITUTE(SUBSTITUTE(SUBSTITUTE(SUBSTITUTE(SUBSTITUTE(SUBSTITUTE(SUBSTITUTE(SUBSTITUTE(SUBSTITUTE(SUBSTITUTE(SUBSTITUTE(SUBSTITUTE(SUBSTITUTE(SUBSTITUTE(SUBSTITUTE(SUBSTITUTE(SUBSTITUTE(SUBSTITUTE(SUBSTITUTE(SUBSTITUTE(SUBSTITUTE(SUBSTITUTE(SUBSTITUTE(SUBSTITUTE(SUBSTITUTE(SUBSTITUTE(SUBSTITUTE(SUBSTITUTE(SUBSTITUTE(SUBSTITUTE(SUBSTITUTE('Input Sheet'!D8,$C$3,$D$3),$C$4,$D$4),$C$5,$D$5),$C$6,$D$6),$C$7,$D$7),$C$8,$D$8),$C$9,$D$9),$C$10,$D$10),$C$11,$D$11),$C$12,$D$12),$C$13,$D$13),$C$14,$D$14),$C$15,$D$15),$C$16,$D$16),$C$17,$D$17),$C$18,$D$18),$C$19,$D$19),$C$20,$D$20),$C$21,$D$21),$C$22,$D$22),$C$23,$D$23),$C$24,$D$24),$C$25,$D$25),$C$26,$D$26),$C$27,$D$27),$C$28,$D$28),$C$29,$D$29),$C$30,$D$30),$C$31,$D$31),$C$32,$D$32),$C$33,$D$33) -> fine | H6: =SUBSTITUTE(G6, "veryfine", "very fine") -> fine | I6: =SUBSTITUTE(SUBSTITUTE(SUBSTITUTE(SUBSTITUTE(SUBSTITUTE(SUBSTITUTE(SUBSTITUTE(SUBSTITUTE(SUBSTITUTE(SUBSTITUTE(SUBSTITUTE(SUBSTITUTE(SUBSTITUTE(SUBSTITUTE(SUBSTITUTE(SUBSTITUTE(SUBSTITUTE(SUBSTITUTE(SUBSTITUTE(SUBSTITUTE(SUBSTITUTE(SUBSTITUTE(SUBSTITUTE(SUBSTITUTE(SUBSTITUTE(SUBSTITUTE(SUBSTITUTE(SUBSTITUTE(SUBSTITUTE(SUBSTITUTE(SUBSTITUTE('Input Sheet'!G8,$C$3,$D$3),$C$4,$D$4),$C$5,$D$5),$C$6,$D$6),$C$7,$D$7),$C$8,$D$8),$C$9,$D$9),$C$10,$D$10),$C$11,$D$11),$C$12,$D$12),$C$13,$D$13),$C$14,$D$14),$C$15,$D$15),$C$16,$D$16),$C$17,$D$17),$C$18,$D$18),$C$19,$D$19),$C$20,$D$20),$C$21,$D$21),$C$22,$D$22),$C$23,$D$23),$C$24,$D$24),$C$25,$D$25),$C$26,$D$26),$C$27,$D$27),$C$28,$D$28),$C$29,$D$29),$C$30,$D$30),$C$31,$D$31),$C$32,$D$32),$C$33,$D$33) -> dim | J6: =IF('Input Sheet'!F8=0, "NO",CONCATENATE('Input Sheet'!F8, IF('Input Sheet'!F8>0,"% ",""))) -> 100% | K6: =SUBSTITUTE(SUBSTITUTE(SUBSTITUTE(SUBSTITUTE(SUBSTITUTE(SUBSTITUTE(SUBSTITUTE(SUBSTITUTE(SUBSTITUTE(SUBSTITUTE(SUBSTITUTE(SUBSTITUTE(SUBSTITUTE(SUBSTITUTE(SUBSTITUTE(SUBSTITUTE(SUBSTITUTE(SUBSTITUTE(SUBSTITUTE(SUBSTITUTE(SUBSTITUTE(SUBSTITUTE(SUBSTITUTE(SUBSTITUTE(SUBSTITUTE(SUBSTITUTE(SUBSTITUTE(SUBSTITUTE(SUBSTITUTE(SUBSTITUTE(SUBSTITUTE('Input Sheet'!I8,$C$3,$D$3),$C$4,$D$4),$C$5,$D$5),$C$6,$D$6),$C$7,$D$7),$C$8,$D$8),$C$9,$D$9),$C$10,$D$10),$C$11,$D$11),$C$12,$D$12),$C$13,$D$13),$C$14,$D$14),$C$15,$D$15),$C$16,$D$16),$C$17,$D$17),$C$18,$D$18),$C$19,$D$19),$C$20,$D$20),$C$21,$D$21),$C$22,$D$22),$C$23,$D$23),$C$24,$D$24),$C$25,$D$25),$C$26,$D$26),$C$27,$D$27),$C$28,$D$28),$C$29,$D$29),$C$30,$D$30),$C$31,$D$31),$C$32,$D$32),$C$33,$D$33) | L6: =CONCATENATE(K6, IF('Input Sheet'!I8="",""," siderite in ")) | M6: =SUBSTITUTE(SUBSTITUTE(SUBSTITUTE(SUBSTITUTE(SUBSTITUTE(SUBSTITUTE(SUBSTITUTE(SUBSTITUTE(SUBSTITUTE(SUBSTITUTE(SUBSTITUTE(SUBSTITUTE(SUBSTITUTE(SUBSTITUTE(SUBSTITUTE(SUBSTITUTE(SUBSTITUTE(SUBSTITUTE(SUBSTITUTE(SUBSTITUTE(SUBSTITUTE(SUBSTITUTE(SUBSTITUTE(SUBSTITUTE(SUBSTITUTE(SUBSTITUTE(SUBSTITUTE(SUBSTITUTE(SUBSTITUTE(SUBSTITUTE(SUBSTITUTE('Input Sheet'!J8,$C$3,$D$3),$C$4,$D$4),$C$5,$D$5),$C$6,$D$6),$C$7,$D$7),$C$8,$D$8),$C$9,$D$9),$C$10,$D$10),$C$11,$D$11),$C$12,$D$12),$C$13,$D$13),$C$14,$D$14),$C$15,$D$15),$C$16,$D$16),$C$17,$D$17),$C$18,$D$18),$C$19,$D$19),$C$20,$D$20),$C$21,$D$21),$C$22,$D$22),$C$23,$D$23),$C$24,$D$24),$C$25,$D$25),$C$26,$D$26),$C$27,$D$27),$C$28,$D$28),$C$29,$D$29),$C$30,$D$30),$C$31,$D$31),$C$32,$D$32),$C$33,$D$33) | N6: =CONCATENATE(M6, IF('Input Sheet'!J8="",""," siderite in "))
A7: =IF('Input Sheet'!C9="","",CONCATENATE("Sample ", 'Input Sheet'!B9, "m: ", L7, F7, "% ", "Siltstone, ", N7, 'Input Sheet'!C9, "% ", H7, " Sandstone, ", J7, I7, " FLUOR in SST. ", "TG ", 'Input Sheet'!H9, "U")) -> Sample 1800m: 40% Siltstone, 60% fine Sandstone, 100% dim FLUOR in SST. TG 20.4U | C7: v | D7: very | F7: =IF('Input Sheet'!C9="","",100-'Input Sheet'!C9) -> 40 | G7: =SUBSTITUTE(SUBSTITUTE(SUBSTITUTE(SUBSTITUTE(SUBSTITUTE(SUBSTITUTE(SUBSTITUTE(SUBSTITUTE(SUBSTITUTE(SUBSTITUTE(SUBSTITUTE(SUBSTITUTE(SUBSTITUTE(SUBSTITUTE(SUBSTITUTE(SUBSTITUTE(SUBSTITUTE(SUBSTITUTE(SUBSTITUTE(SUBSTITUTE(SUBSTITUTE(SUBSTITUTE(SUBSTITUTE(SUBSTITUTE(SUBSTITUTE(SUBSTITUTE(SUBSTITUTE(SUBSTITUTE(SUBSTITUTE(SUBSTITUTE(SUBSTITUTE('Input Sheet'!D9,$C$3,$D$3),$C$4,$D$4),$C$5,$D$5),$C$6,$D$6),$C$7,$D$7),$C$8,$D$8),$C$9,$D$9),$C$10,$D$10),$C$11,$D$11),$C$12,$D$12),$C$13,$D$13),$C$14,$D$14),$C$15,$D$15),$C$16,$D$16),$C$17,$D$17),$C$18,$D$18),$C$19,$D$19),$C$20,$D$20),$C$21,$D$21),$C$22,$D$22),$C$23,$D$23),$C$24,$D$24),$C$25,$D$25),$C$26,$D$26),$C$27,$D$27),$C$28,$D$28),$C$29,$D$29),$C$30,$D$30),$C$31,$D$31),$C$32,$D$32),$C$33,$D$33) -> fine | H7: =SUBSTITUTE(G7, "veryfine", "very fine") -> fine | I7: =SUBSTITUTE(SUBSTITUTE(SUBSTITUTE(SUBSTITUTE(SUBSTITUTE(SUBSTITUTE(SUBSTITUTE(SUBSTITUTE(SUBSTITUTE(SUBSTITUTE(SUBSTITUTE(SUBSTITUTE(SUBSTITUTE(SUBSTITUTE(SUBSTITUTE(SUBSTITUTE(SUBSTITUTE(SUBSTITUTE(SUBSTITUTE(SUBSTITUTE(SUBSTITUTE(SUBSTITUTE(SUBSTITUTE(SUBSTITUTE(SUBSTITUTE(SUBSTITUTE(SUBSTITUTE(SUBSTITUTE(SUBSTITUTE(SUBSTITUTE(SUBSTITUTE('Input Sheet'!G9,$C$3,$D$3),$C$4,$D$4),$C$5,$D$5),$C$6,$D$6),$C$7,$D$7),$C$8,$D$8),$C$9,$D$9),$C$10,$D$10),$C$11,$D$11),$C$12,$D$12),$C$13,$D$13),$C$14,$D$14),$C$15,$D$15),$C$16,$D$16),$C$17,$D$17),$C$18,$D$18),$C$19,$D$19),$C$20,$D$20),$C$21,$D$21),$C$22,$D$22),$C$23,$D$23),$C$24,$D$24),$C$25,$D$25),$C$26,$D$26),$C$27,$D$27),$C$28,$D$28),$C$29,$D$29),$C$30,$D$30),$C$31,$D$31),$C$32,$D$32),$C$33,$D$33) -> dim | J7: =IF('Input Sheet'!F9=0, "NO",CONCATENATE('Input Sheet'!F9, IF('Input Sheet'!F9>0,"% ",""))) -> 100% | K7: =SUBSTITUTE(SUBSTITUTE(SUBSTITUTE(SUBSTITUTE(SUBSTITUTE(SUBSTITUTE(SUBSTITUTE(SUBSTITUTE(SUBSTITUTE(SUBSTITUTE(SUBSTITUTE(SUBSTITUTE(SUBSTITUTE(SUBSTITUTE(SUBSTITUTE(SUBSTITUTE(SUBSTITUTE(SUBSTITUTE(SUBSTITUTE(SUBSTITUTE(SUBSTITUTE(SUBSTITUTE(SUBSTITUTE(SUBSTITUTE(SUBSTITUTE(SUBSTITUTE(SUBSTITUTE(SUBSTITUTE(SUBSTITUTE(SUBSTITUTE(SUBSTITUTE('Input Sheet'!I9,$C$3,$D$3),$C$4,$D$4),$C$5,$D$5),$C$6,$D$6),$C$7,$D$7),$C$8,$D$8),$C$9,$D$9),$C$10,$D$10),$C$11,$D$11),$C$12,$D$12),$C$13,$D$13),$C$14,$D$14),$C$15,$D$15),$C$16,$D$16),$C$17,$D$17),$C$18,$D$18),$C$19,$D$19),$C$20,$D$20),$C$21,$D$21),$C$22,$D$22),$C$23,$D$23),$C$24,$D$24),$C$25,$D$25),$C$26,$D$26),$C$27,$D$27),$C$28,$D$28),$C$29,$D$29),$C$30,$D$30),$C$31,$D$31),$C$32,$D$32),$C$33,$D$33) | L7: =CONCATENATE(K7, IF('Input Sheet'!I9="",""," siderite in ")) | M7: =SUBSTITUTE(SUBSTITUTE(SUBSTITUTE(SUBSTITUTE(SUBSTITUTE(SUBSTITUTE(SUBSTITUTE(SUBSTITUTE(SUBSTITUTE(SUBSTITUTE(SUBSTITUTE(SUBSTITUTE(SUBSTITUTE(SUBSTITUTE(SUBSTITUTE(SUBSTITUTE(SUBSTITUTE(SUBSTITUTE(SUBSTITUTE(SUBSTITUTE(SUBSTITUTE(SUBSTITUTE(SUBSTITUTE(SUBSTITUTE(SUBSTITUTE(SUBSTITUTE(SUBSTITUTE(SUBSTITUTE(SUBSTITUTE(SUBSTITUTE(SUBSTITUTE('Input Sheet'!J9,$C$3,$D$3),$C$4,$D$4),$C$5,$D$5),$C$6,$D$6),$C$7,$D$7),$C$8,$D$8),$C$9,$D$9),$C$10,$D$10),$C$11,$D$11),$C$12,$D$12),$C$13,$D$13),$C$14,$D$14),$C$15,$D$15),$C$16,$D$16),$C$17,$D$17),$C$18,$D$18),$C$19,$D$19),$C$20,$D$20),$C$21,$D$21),$C$22,$D$22),$C$23,$D$23),$C$24,$D$24),$C$25,$D$25),$C$26,$D$26),$C$27,$D$27),$C$28,$D$28),$C$29,$D$29),$C$30,$D$30),$C$31,$D$31),$C$32,$D$32),$C$33,$D$33) | N7: =CONCATENATE(M7, IF('Input Sheet'!J9="",""," siderite in "))
A8: =IF('Input Sheet'!C10="","",CONCATENATE("Sample ", 'Input Sheet'!B10, "m: ", L8, F8, "% ", "Siltstone, ", N8, 'Input Sheet'!C10, "% ", H8, " Sandstone, ", J8, I8, " FLUOR in SST. ", "TG ", 'Input Sheet'!H10, "U")) -> Sample 1805m: 40% Siltstone, 60% fine Sandstone, 10% dim FLUOR in SST. TG 14.5U | C8: - | D8: to | F8: =IF('Input Sheet'!C10="","",100-'Input Sheet'!C10) -> 40 | G8: =SUBSTITUTE(SUBSTITUTE(SUBSTITUTE(SUBSTITUTE(SUBSTITUTE(SUBSTITUTE(SUBSTITUTE(SUBSTITUTE(SUBSTITUTE(SUBSTITUTE(SUBSTITUTE(SUBSTITUTE(SUBSTITUTE(SUBSTITUTE(SUBSTITUTE(SUBSTITUTE(SUBSTITUTE(SUBSTITUTE(SUBSTITUTE(SUBSTITUTE(SUBSTITUTE(SUBSTITUTE(SUBSTITUTE(SUBSTITUTE(SUBSTITUTE(SUBSTITUTE(SUBSTITUTE(SUBSTITUTE(SUBSTITUTE(SUBSTITUTE(SUBSTITUTE('Input Sheet'!D10,$C$3,$D$3),$C$4,$D$4),$C$5,$D$5),$C$6,$D$6),$C$7,$D$7),$C$8,$D$8),$C$9,$D$9),$C$10,$D$10),$C$11,$D$11),$C$12,$D$12),$C$13,$D$13),$C$14,$D$14),$C$15,$D$15),$C$16,$D$16),$C$17,$D$17),$C$18,$D$18),$C$19,$D$19),$C$20,$D$20),$C$21,$D$21),$C$22,$D$22),$C$23,$D$23),$C$24,$D$24),$C$25,$D$25),$C$26,$D$26),$C$27,$D$27),$C$28,$D$28),$C$29,$D$29),$C$30,$D$30),$C$31,$D$31),$C$32,$D$32),$C$33,$D$33) -> fine | H8: =SUBSTITUTE(G8, "veryfine", "very fine") -> fine | I8: =SUBSTITUTE(SUBSTITUTE(SUBSTITUTE(SUBSTITUTE(SUBSTITUTE(SUBSTITUTE(SUBSTITUTE(SUBSTITUTE(SUBSTITUTE(SUBSTITUTE(SUBSTITUTE(SUBSTITUTE(SUBSTITUTE(SUBSTITUTE(SUBSTITUTE(SUBSTITUTE(SUBSTITUTE(SUBSTITUTE(SUBSTITUTE(SUBSTITUTE(SUBSTITUTE(SUBSTITUTE(SUBSTITUTE(SUBSTITUTE(SUBSTITUTE(SUBSTITUTE(SUBSTITUTE(SUBSTITUTE(SUBSTITUTE(SUBSTITUTE(SUBSTITUTE('Input Sheet'!G10,$C$3,$D$3),$C$4,$D$4),$C$5,$D$5),$C$6,$D$6),$C$7,$D$7),$C$8,$D$8),$C$9,$D$9),$C$10,$D$10),$C$11,$D$11),$C$12,$D$12),$C$13,$D$13),$C$14,$D$14),$C$15,$D$15),$C$16,$D$16),$C$17,$D$17),$C$18,$D$18),$C$19,$D$19),$C$20,$D$20),$C$21,$D$21),$C$22,$D$22),$C$23,$D$23),$C$24,$D$24),$C$25,$D$25),$C$26,$D$26),$C$27,$D$27),$C$28,$D$28),$C$29,$D$29),$C$30,$D$30),$C$31,$D$31),$C$32,$D$32),$C$33,$D$33) -> dim | J8: =IF('Input Sheet'!F10=0, "NO",CONCATENATE('Input Sheet'!F10, IF('Input Sheet'!F10>0,"% ",""))) -> 10% | K8: =SUBSTITUTE(SUBSTITUTE(SUBSTITUTE(SUBSTITUTE(SUBSTITUTE(SUBSTITUTE(SUBSTITUTE(SUBSTITUTE(SUBSTITUTE(SUBSTITUTE(SUBSTITUTE(SUBSTITUTE(SUBSTITUTE(SUBSTITUTE(SUBSTITUTE(SUBSTITUTE(SUBSTITUTE(SUBSTITUTE(SUBSTITUTE(SUBSTITUTE(SUBSTITUTE(SUBSTITUTE(SUBSTITUTE(SUBSTITUTE(SUBSTITUTE(SUBSTITUTE(SUBSTITUTE(SUBSTITUTE(SUBSTITUTE(SUBSTITUTE(SUBSTITUTE('Input Sheet'!I10,$C$3,$D$3),$C$4,$D$4),$C$5,$D$5),$C$6,$D$6),$C$7,$D$7),$C$8,$D$8),$C$9,$D$9),$C$10,$D$10),$C$11,$D$11),$C$12,$D$12),$C$13,$D$13),$C$14,$D$14),$C$15,$D$15),$C$16,$D$16),$C$17,$D$17),$C$18,$D$18),$C$19,$D$19),$C$20,$D$20),$C$21,$D$21),$C$22,$D$22),$C$23,$D$23),$C$24,$D$24),$C$25,$D$25),$C$26,$D$26),$C$27,$D$27),$C$28,$D$28),$C$29,$D$29),$C$30,$D$30),$C$31,$D$31),$C$32,$D$32),$C$33,$D$33) | L8: =CONCATENATE(K8, IF('Input Sheet'!I10="",""," siderite in ")) | M8: =SUBSTITUTE(SUBSTITUTE(SUBSTITUTE(SUBSTITUTE(SUBSTITUTE(SUBSTITUTE(SUBSTITUTE(SUBSTITUTE(SUBSTITUTE(SUBSTITUTE(SUBSTITUTE(SUBSTITUTE(SUBSTITUTE(SUBSTITUTE(SUBSTITUTE(SUBSTITUTE(SUBSTITUTE(SUBSTITUTE(SUBSTITUTE(SUBSTITUTE(SUBSTITUTE(SUBSTITUTE(SUBSTITUTE(SUBSTITUTE(SUBSTITUTE(SUBSTITUTE(SUBSTITUTE(SUBSTITUTE(SUBSTITUTE(SUBSTITUTE(SUBSTITUTE('Input Sheet'!J10,$C$3,$D$3),$C$4,$D$4),$C$5,$D$5),$C$6,$D$6),$C$7,$D$7),$C$8,$D$8),$C$9,$D$9),$C$10,$D$10),$C$11,$D$11),$C$12,$D$12),$C$13,$D$13),$C$14,$D$14),$C$15,$D$15),$C$16,$D$16),$C$17,$D$17),$C$18,$D$18),$C$19,$D$19),$C$20,$D$20),$C$21,$D$21),$C$22,$D$22),$C$23,$D$23),$C$24,$D$24),$C$25,$D$25),$C$26,$D$26),$C$27,$D$27),$C$28,$D$28),$C$29,$D$29),$C$30,$D$30),$C$31,$D$31),$C$32,$D$32),$C$33,$D$33) | N8: =CONCATENATE(M8, IF('Input Sheet'!J10="",""," siderite in "))
A9: =IF('Input Sheet'!C11="","",CONCATENATE("Sample ", 'Input Sheet'!B11, "m: ", L9, F9, "% ", "Siltstone, ", N9, 'Input Sheet'!C11, "% ", H9, " Sandstone, ", J9, I9, " FLUOR in SST. ", "TG ", 'Input Sheet'!H11, "U")) -> Sample 1810m: 50% Siltstone, 50% fine Sandstone, 10% dim FLUOR in SST. TG 16.2U | C9: occ | D9: occasional | F9: =IF('Input Sheet'!C11="","",100-'Input Sheet'!C11) -> 50 | G9: =SUBSTITUTE(SUBSTITUTE(SUBSTITUTE(SUBSTITUTE(SUBSTITUTE(SUBSTITUTE(SUBSTITUTE(SUBSTITUTE(SUBSTITUTE(SUBSTITUTE(SUBSTITUTE(SUBSTITUTE(SUBSTITUTE(SUBSTITUTE(SUBSTITUTE(SUBSTITUTE(SUBSTITUTE(SUBSTITUTE(SUBSTITUTE(SUBSTITUTE(SUBSTITUTE(SUBSTITUTE(SUBSTITUTE(SUBSTITUTE(SUBSTITUTE(SUBSTITUTE(SUBSTITUTE(SUBSTITUTE(SUBSTITUTE(SUBSTITUTE(SUBSTITUTE('Input Sheet'!D11,$C$3,$D$3),$C$4,$D$4),$C$5,$D$5),$C$6,$D$6),$C$7,$D$7),$C$8,$D$8),$C$9,$D$9),$C$10,$D$10),$C$11,$D$11),$C$12,$D$12),$C$13,$D$13),$C$14,$D$14),$C$15,$D$15),$C$16,$D$16),$C$17,$D$17),$C$18,$D$18),$C$19,$D$19),$C$20,$D$20),$C$21,$D$21),$C$22,$D$22),$C$23,$D$23),$C$24,$D$24),$C$25,$D$25),$C$26,$D$26),$C$27,$D$27),$C$28,$D$28),$C$29,$D$29),$C$30,$D$30),$C$31,$D$31),$C$32,$D$32),$C$33,$D$33) -> fine | H9: =SUBSTITUTE(G9, "veryfine", "very fine") -> fine | I9: =SUBSTITUTE(SUBSTITUTE(SUBSTITUTE(SUBSTITUTE(SUBSTITUTE(SUBSTITUTE(SUBSTITUTE(SUBSTITUTE(SUBSTITUTE(SUBSTITUTE(SUBSTITUTE(SUBSTITUTE(SUBSTITUTE(SUBSTITUTE(SUBSTITUTE(SUBSTITUTE(SUBSTITUTE(SUBSTITUTE(SUBSTITUTE(SUBSTITUTE(SUBSTITUTE(SUBSTITUTE(SUBSTITUTE(SUBSTITUTE(SUBSTITUTE(SUBSTITUTE(SUBSTITUTE(SUBSTITUTE(SUBSTITUTE(SUBSTITUTE(SUBSTITUTE('Input Sheet'!G11,$C$3,$D$3),$C$4,$D$4),$C$5,$D$5),$C$6,$D$6),$C$7,$D$7),$C$8,$D$8),$C$9,$D$9),$C$10,$D$10),$C$11,$D$11),$C$12,$D$12),$C$13,$D$13),$C$14,$D$14),$C$15,$D$15),$C$16,$D$16),$C$17,$D$17),$C$18,$D$18),$C$19,$D$19),$C$20,$D$20),$C$21,$D$21),$C$22,$D$22),$C$23,$D$23),$C$24,$D$24),$C$25,$D$25),$C$26,$D$26),$C$27,$D$27),$C$28,$D$28),$C$29,$D$29),$C$30,$D$30),$C$31,$D$31),$C$32,$D$32),$C$33,$D$33) -> dim | J9: =IF('Input Sheet'!F11=0, "NO",CONCATENATE('Input Sheet'!F11, IF('Input Sheet'!F11>0,"% ",""))) -> 10% | K9: =SUBSTITUTE(SUBSTITUTE(SUBSTITUTE(SUBSTITUTE(SUBSTITUTE(SUBSTITUTE(SUBSTITUTE(SUBSTITUTE(SUBSTITUTE(SUBSTITUTE(SUBSTITUTE(SUBSTITUTE(SUBSTITUTE(SUBSTITUTE(SUBSTITUTE(SUBSTITUTE(SUBSTITUTE(SUBSTITUTE(SUBSTITUTE(SUBSTITUTE(SUBSTITUTE(SUBSTITUTE(SUBSTITUTE(SUBSTITUTE(SUBSTITUTE(SUBSTITUTE(SUBSTITUTE(SUBSTITUTE(SUBSTITUTE(SUBSTITUTE(SUBSTITUTE('Input Sheet'!I11,$C$3,$D$3),$C$4,$D$4),$C$5,$D$5),$C$6,$D$6),$C$7,$D$7),$C$8,$D$8),$C$9,$D$9),$C$10,$D$10),$C$11,$D$11),$C$12,$D$12),$C$13,$D$13),$C$14,$D$14),$C$15,$D$15),$C$16,$D$16),$C$17,$D$17),$C$18,$D$18),$C$19,$D$19),$C$20,$D$20),$C$21,$D$21),$C$22,$D$22),$C$23,$D$23),$C$24,$D$24),$C$25,$D$25),$C$26,$D$26),$C$27,$D$27),$C$28,$D$28),$C$29,$D$29),$C$30,$D$30),$C$31,$D$31),$C$32,$D$32),$C$33,$D$33) | L9: =CONCATENATE(K9, IF('Input Sheet'!I11="",""," siderite in ")) | M9: =SUBSTITUTE(SUBSTITUTE(SUBSTITUTE(SUBSTITUTE(SUBSTITUTE(SUBSTITUTE(SUBSTITUTE(SUBSTITUTE(SUBSTITUTE(SUBSTITUTE(SUBSTITUTE(SUBSTITUTE(SUBSTITUTE(SUBSTITUTE(SUBSTITUTE(SUBSTITUTE(SUBSTITUTE(SUBSTITUTE(SUBSTITUTE(SUBSTITUTE(SUBSTITUTE(SUBSTITUTE(SUBSTITUTE(SUBSTITUTE(SUBSTITUTE(SUBSTITUTE(SUBSTITUTE(SUBSTITUTE(SUBSTITUTE(SUBSTITUTE(SUBSTITUTE('Input Sheet'!J11,$C$3,$D$3),$C$4,$D$4),$C$5,$D$5),$C$6,$D$6),$C$7,$D$7),$C$8,$D$8),$C$9,$D$9),$C$10,$D$10),$C$11,$D$11),$C$12,$D$12),$C$13,$D$13),$C$14,$D$14),$C$15,$D$15),$C$16,$D$16),$C$17,$D$17),$C$18,$D$18),$C$19,$D$19),$C$20,$D$20),$C$21,$D$21),$C$22,$D$22),$C$23,$D$23),$C$24,$D$24),$C$25,$D$25),$C$26,$D$26),$C$27,$D$27),$C$28,$D$28),$C$29,$D$29),$C$30,$D$30),$C$31,$D$31),$C$32,$D$32),$C$33,$D$33) | N9: =CONCATENATE(M9, IF('Input Sheet'!J11="",""," siderite in "))
A10: =IF('Input Sheet'!C12="","",CONCATENATE("Sample ", 'Input Sheet'!B12, "m: ", L10, F10, "% ", "Siltstone, ", N10, 'Input Sheet'!C12, "% ", H10, " Sandstone, ", J10, I10, " FLUOR in SST. ", "TG ", 'Input Sheet'!H12, "U")) -> Sample 1895m: trace siderite in 85% Siltstone, 15% fine Sandstone, 20% dim FLUOR in SST. TG 7.8U | C10: mnr | D10: minor | F10: =IF('Input Sheet'!C12="","",100-'Input Sheet'!C12) -> 85 | G10: =SUBSTITUTE(SUBSTITUTE(SUBSTITUTE(SUBSTITUTE(SUBSTITUTE(SUBSTITUTE(SUBSTITUTE(SUBSTITUTE(SUBSTITUTE(SUBSTITUTE(SUBSTITUTE(SUBSTITUTE(SUBSTITUTE(SUBSTITUTE(SUBSTITUTE(SUBSTITUTE(SUBSTITUTE(SUBSTITUTE(SUBSTITUTE(SUBSTITUTE(SUBSTITUTE(SUBSTITUTE(SUBSTITUTE(SUBSTITUTE(SUBSTITUTE(SUBSTITUTE(SUBSTITUTE(SUBSTITUTE(SUBSTITUTE(SUBSTITUTE(SUBSTITUTE('Input Sheet'!D12,$C$3,$D$3),$C$4,$D$4),$C$5,$D$5),$C$6,$D$6),$C$7,$D$7),$C$8,$D$8),$C$9,$D$9),$C$10,$D$10),$C$11,$D$11),$C$12,$D$12),$C$13,$D$13),$C$14,$D$14),$C$15,$D$15),$C$16,$D$16),$C$17,$D$17),$C$18,$D$18),$C$19,$D$19),$C$20,$D$20),$C$21,$D$21),$C$22,$D$22),$C$23,$D$23),$C$24,$D$24),$C$25,$D$25),$C$26,$D$26),$C$27,$D$27),$C$28,$D$28),$C$29,$D$29),$C$30,$D$30),$C$31,$D$31),$C$32,$D$32),$C$33,$D$33) -> fine | H10: =SUBSTITUTE(G10, "veryfine", "very fine") -> fine | I10: =SUBSTITUTE(SUBSTITUTE(SUBSTITUTE(SUBSTITUTE(SUBSTITUTE(SUBSTITUTE(SUBSTITUTE(SUBSTITUTE(SUBSTITUTE(SUBSTITUTE(SUBSTITUTE(SUBSTITUTE(SUBSTITUTE(SUBSTITUTE(SUBSTITUTE(SUBSTITUTE(SUBSTITUTE(SUBSTITUTE(SUBSTITUTE(SUBSTITUTE(SUBSTITUTE(SUBSTITUTE(SUBSTITUTE(SUBSTITUTE(SUBSTITUTE(SUBSTITUTE(SUBSTITUTE(SUBSTITUTE(SUBSTITUTE(SUBSTITUTE(SUBSTITUTE('Input Sheet'!G12,$C$3,$D$3),$C$4,$D$4),$C$5,$D$5),$C$6,$D$6),$C$7,$D$7),$C$8,$D$8),$C$9,$D$9),$C$10,$D$10),$C$11,$D$11),$C$12,$D$12),$C$13,$D$13),$C$14,$D$14),$C$15,$D$15),$C$16,$D$16),$C$17,$D$17),$C$18,$D$18),$C$19,$D$19),$C$20,$D$20),$C$21,$D$21),$C$22,$D$22),$C$23,$D$23),$C$24,$D$24),$C$25,$D$25),$C$26,$D$26),$C$27,$D$27),$C$28,$D$28),$C$29,$D$29),$C$30,$D$30),$C$31,$D$31),$C$32,$D$32),$C$33,$D$33) -> dim | J10: =IF('Input Sheet'!F12=0, "NO",CONCATENATE('Input Sheet'!F12, IF('Input Sheet'!F12>0,"% ",""))) -> 20% | K10: =SUBSTITUTE(SUBSTITUTE(SUBSTITUTE(SUBSTITUTE(SUBSTITUTE(SUBSTITUTE(SUBSTITUTE(SUBSTITUTE(SUBSTITUTE(SUBSTITUTE(SUBSTITUTE(SUBSTITUTE(SUBSTITUTE(SUBSTITUTE(SUBSTITUTE(SUBSTITUTE(SUBSTITUTE(SUBSTITUTE(SUBSTITUTE(SUBSTITUTE(SUBSTITUTE(SUBSTITUTE(SUBSTITUTE(SUBSTITUTE(SUBSTITUTE(SUBSTITUTE(SUBSTITUTE(SUBSTITUTE(SUBSTITUTE(SUBSTITUTE(SUBSTITUTE('Input Sheet'!I12,$C$3,$D$3),$C$4,$D$4),$C$5,$D$5),$C$6,$D$6),$C$7,$D$7),$C$8,$D$8),$C$9,$D$9),$C$10,$D$10),$C$11,$D$11),$C$12,$D$12),$C$13,$D$13),$C$14,$D$14),$C$15,$D$15),$C$16,$D$16),$C$17,$D$17),$C$18,$D$18),$C$19,$D$19),$C$20,$D$20),$C$21,$D$21),$C$22,$D$22),$C$23,$D$23),$C$24,$D$24),$C$25,$D$25),$C$26,$D$26),$C$27,$D$27),$C$28,$D$28),$C$29,$D$29),$C$30,$D$30),$C$31,$D$31),$C$32,$D$32),$C$33,$D$33) -> trace | L10: =CONCATENATE(K10, IF('Input Sheet'!I12="",""," siderite in ")) -> trace siderite in | M10: =SUBSTITUTE(SUBSTITUTE(SUBSTITUTE(SUBSTITUTE(SUBSTITUTE(SUBSTITUTE(SUBSTITUTE(SUBSTITUTE(SUBSTITUTE(SUBSTITUTE(SUBSTITUTE(SUBSTITUTE(SUBSTITUTE(SUBSTITUTE(SUBSTITUTE(SUBSTITUTE(SUBSTITUTE(SUBSTITUTE(SUBSTITUTE(SUBSTITUTE(SUBSTITUTE(SUBSTITUTE(SUBSTITUTE(SUBSTITUTE(SUBSTITUTE(SUBSTITUTE(SUBSTITUTE(SUBSTITUTE(SUBSTITUTE(SUBSTITUTE(SUBSTITUTE('Input Sheet'!J12,$C$3,$D$3),$C$4,$D$4),$C$5,$D$5),$C$6,$D$6),$C$7,$D$7),$C$8,$D$8),$C$9,$D$9),$C$10,$D$10),$C$11,$D$11),$C$12,$D$12),$C$13,$D$13),$C$14,$D$14),$C$15,$D$15),$C$16,$D$16),$C$17,$D$17),$C$18,$D$18),$C$19,$D$19),$C$20,$D$20),$C$21,$D$21),$C$22,$D$22),$C$23,$D$23),$C$24,$D$24),$C$25,$D$25),$C$26,$D$26),$C$27,$D$27),$C$28,$D$28),$C$29,$D$29),$C$30,$D$30),$C$31,$D$31),$C$32,$D$32),$C$33,$D$33) | N10: =CONCATENATE(M10, IF('Input Sheet'!J12="",""," siderite in "))
A11: =IF('Input Sheet'!C13="","",CONCATENATE("Sample ", 'Input Sheet'!B13, "m: ", L11, F11, "% ", "Siltstone, ", N11, 'Input Sheet'!C13, "% ", H11, " Sandstone, ", J11, I11, " FLUOR in SST. ", "TG ", 'Input Sheet'!H13, "U")) -> Sample 1900m: 85% Siltstone, 15% fine Sandstone, 50% dim FLUOR in SST. TG 7.4U | C11: rr | D11: rare | F11: =IF('Input Sheet'!C13="","",100-'Input Sheet'!C13) -> 85 | G11: =SUBSTITUTE(SUBSTITUTE(SUBSTITUTE(SUBSTITUTE(SUBSTITUTE(SUBSTITUTE(SUBSTITUTE(SUBSTITUTE(SUBSTITUTE(SUBSTITUTE(SUBSTITUTE(SUBSTITUTE(SUBSTITUTE(SUBSTITUTE(SUBSTITUTE(SUBSTITUTE(SUBSTITUTE(SUBSTITUTE(SUBSTITUTE(SUBSTITUTE(SUBSTITUTE(SUBSTITUTE(SUBSTITUTE(SUBSTITUTE(SUBSTITUTE(SUBSTITUTE(SUBSTITUTE(SUBSTITUTE(SUBSTITUTE(SUBSTITUTE(SUBSTITUTE('Input Sheet'!D13,$C$3,$D$3),$C$4,$D$4),$C$5,$D$5),$C$6,$D$6),$C$7,$D$7),$C$8,$D$8),$C$9,$D$9),$C$10,$D$10),$C$11,$D$11),$C$12,$D$12),$C$13,$D$13),$C$14,$D$14),$C$15,$D$15),$C$16,$D$16),$C$17,$D$17),$C$18,$D$18),$C$19,$D$19),$C$20,$D$20),$C$21,$D$21),$C$22,$D$22),$C$23,$D$23),$C$24,$D$24),$C$25,$D$25),$C$26,$D$26),$C$27,$D$27),$C$28,$D$28),$C$29,$D$29),$C$30,$D$30),$C$31,$D$31),$C$32,$D$32),$C$33,$D$33) -> fine | H11: =SUBSTITUTE(G11, "veryfine", "very fine") -> fine | I11: =SUBSTITUTE(SUBSTITUTE(SUBSTITUTE(SUBSTITUTE(SUBSTITUTE(SUBSTITUTE(SUBSTITUTE(SUBSTITUTE(SUBSTITUTE(SUBSTITUTE(SUBSTITUTE(SUBSTITUTE(SUBSTITUTE(SUBSTITUTE(SUBSTITUTE(SUBSTITUTE(SUBSTITUTE(SUBSTITUTE(SUBSTITUTE(SUBSTITUTE(SUBSTITUTE(SUBSTITUTE(SUBSTITUTE(SUBSTITUTE(SUBSTITUTE(SUBSTITUTE(SUBSTITUTE(SUBSTITUTE(SUBSTITUTE(SUBSTITUTE(SUBSTITUTE('Input Sheet'!G13,$C$3,$D$3),$C$4,$D$4),$C$5,$D$5),$C$6,$D$6),$C$7,$D$7),$C$8,$D$8),$C$9,$D$9),$C$10,$D$10),$C$11,$D$11),$C$12,$D$12),$C$13,$D$13),$C$14,$D$14),$C$15,$D$15),$C$16,$D$16),$C$17,$D$17),$C$18,$D$18),$C$19,$D$19),$C$20,$D$20),$C$21,$D$21),$C$22,$D$22),$C$23,$D$23),$C$24,$D$24),$C$25,$D$25),$C$26,$D$26),$C$27,$D$27),$C$28,$D$28),$C$29,$D$29),$C$30,$D$30),$C$31,$D$31),$C$32,$D$32),$C$33,$D$33) -> dim | J11: =IF('Input Sheet'!F13=0, "NO",CONCATENATE('Input Sheet'!F13, IF('Input Sheet'!F13>0,"% ",""))) -> 50% | K11: =SUBSTITUTE(SUBSTITUTE(SUBSTITUTE(SUBSTITUTE(SUBSTITUTE(SUBSTITUTE(SUBSTITUTE(SUBSTITUTE(SUBSTITUTE(SUBSTITUTE(SUBSTITUTE(SUBSTITUTE(SUBSTITUTE(SUBSTITUTE(SUBSTITUTE(SUBSTITUTE(SUBSTITUTE(SUBSTITUTE(SUBSTITUTE(SUBSTITUTE(SUBSTITUTE(SUBSTITUTE(SUBSTITUTE(SUBSTITUTE(SUBSTITUTE(SUBSTITUTE(SUBSTITUTE(SUBSTITUTE(SUBSTITUTE(SUBSTITUTE(SUBSTITUTE('Input Sheet'!I13,$C$3,$D$3),$C$4,$D$4),$C$5,$D$5),$C$6,$D$6),$C$7,$D$7),$C$8,$D$8),$C$9,$D$9),$C$10,$D$10),$C$11,$D$11),$C$12,$D$12),$C$13,$D$13),$C$14,$D$14),$C$15,$D$15),$C$16,$D$16),$C$17,$D$17),$C$18,$D$18),$C$19,$D$19),$C$20,$D$20),$C$21,$D$21),$C$22,$D$22),$C$23,$D$23),$C$24,$D$24),$C$25,$D$25),$C$26,$D$26),$C$27,$D$27),$C$28,$D$28),$C$29,$D$29),$C$30,$D$30),$C$31,$D$31),$C$32,$D$32),$C$33,$D$33) | L11: =CONCATENATE(K11, IF('Input Sheet'!I13="",""," siderite in ")) | M11: =SUBSTITUTE(SUBSTITUTE(SUBSTITUTE(SUBSTITUTE(SUBSTITUTE(SUBSTITUTE(SUBSTITUTE(SUBSTITUTE(SUBSTITUTE(SUBSTITUTE(SUBSTITUTE(SUBSTITUTE(SUBSTITUTE(SUBSTITUTE(SUBSTITUTE(SUBSTITUTE(SUBSTITUTE(SUBSTITUTE(SUBSTITUTE(SUBSTITUTE(SUBSTITUTE(SUBSTITUTE(SUBSTITUTE(SUBSTITUTE(SUBSTITUTE(SUBSTITUTE(SUBSTITUTE(SUBSTITUTE(SUBSTITUTE(SUBSTITUTE(SUBSTITUTE('Input Sheet'!J13,$C$3,$D$3),$C$4,$D$4),$C$5,$D$5),$C$6,$D$6),$C$7,$D$7),$C$8,$D$8),$C$9,$D$9),$C$10,$D$10),$C$11,$D$11),$C$12,$D$12),$C$13,$D$13),$C$14,$D$14),$C$15,$D$15),$C$16,$D$16),$C$17,$D$17),$C$18,$D$18),$C$19,$D$19),$C$20,$D$20),$C$21,$D$21),$C$22,$D$22),$C$23,$D$23),$C$24,$D$24),$C$25,$D$25),$C$26,$D$26),$C$27,$D$27),$C$28,$D$28),$C$29,$D$29),$C$30,$D$30),$C$31,$D$31),$C$32,$D$32),$C$33,$D$33) | N11: =CONCATENATE(M11, IF('Input Sheet'!J13="",""," siderite in "))
