Workbook

Sheet Example Sheet
B1: Sample Descriptions
B3: Depth (mMD) | C3: % Sandstone | D3: Grain Size | E3: Max Grain Size | F3: % Fluor | G3: Brightness | H3: Gas (U) | I3: FeCO3 in SLTST | J3: FeCO3 in SST | K3: Date | L3: Time | O3: Short Hand
B4: 1596 | C4: 50 | D4: vf-f | E4: F | H4: 5 | I4: mnr | K4: 45161 | L4: 0.54166667 | O4: f | P4: fine
B5: 1599 | C5: 60 | D5: vf-f, tr med | E5: M | H5: 5 | I5: mnr | K5: 45161 | L5: 0.54861111 | O5: med | P5: medium
B6: 1602 | C6: 65 | D6: vf-f | E6: F | H6: 5 | I6: mnr | K6: 45161 | L6: 0.55208333 | O6: crs | P6: coarse
B7: 1605 | C7: 50 | D7: vf, occ f | E7: F | H7: 6 | I7: tr | K7: 45161 | L7: 0.5625 | O7: v | P7: very
B8: 1608 | C8: 30 | D8: vf-f | E8: F | H8: 7 | I8: tr | J8: tr | K8: 45161 | L8: 0.58333333 | O8: - | P8: to
B9: 1611 | C9: 40 | D9: vf-f | E9: F | F9: Tr | H9: 7 | I9: tr | J9: tr | K9: 45161 | L9: 0.60416667 | O9: occ | P9: occasional
B10: 1614 | C10: 60 | D10: vf-f | E10: F | F10: 10 | G10: pl-mod bri | H10: 8 | I10: tr | K10: 45161 | L10: 0.625 | O10: mnr | P10: minor
B11: 1617 | C11: 40 | D11: vf-f | E11: F | F11: Tr | G11: pl-mod bri | H11: 7 | I11: tr | J11: mnr | K11: 45161 | L11: 0.64583333 | O11: rr | P11: rare
B12: 1620 | C12: 30 | D12: vf-f | E12: F | F12: 10 | G12: pl-mod bri | H12: 7 | I12: mnr | J12: mnr | K12: 45161 | L12: 0.66666667 | O12: tr | P12: trace
B13: 1623 | C13: 30 | D13: vff-f | E13: F | F13: 10 | G13: pl-mod bri | H13: 5 | I13: mnr | J13: tr | K13: 45161 | L13: 0.6875 | O13: mod | P13: moderately
B14: 1626 | C14: 80 | D14: vf-med, tr crs-v crs | E14: C | F14: 80 | G14: mod bri | H14: 77 | I14: tr | K14: 45161 | L14: 0.70833333 | O14: bri | P14: bright
B15: 1629 | C15: 90 | D15: f-med, tr crs-v crs | E15: C | F15: 100 | G15: mod bri-bri | H15: 100 | K15: 45161 | L15: 0.72916667 | O15: dll | P15: dull
B16: 1632 | C16: 95 | D16: f-med, tr crs-v crs | E16: C | F16: 100 | G16: mod bri-bri | H16: 94 | K16: 45161 | L16: 0.75 | O16: com | P16: common
B17: 1635 | C17: 100 | D17: f-med,tr crs | E17: C | F17: 100 | G17: mod bri-bri | H17: 102 | K17: 45161 | L17: 0.77083333 | O17: i/p | P17: in part
O18: dom | P18: dominantly
O19: pl | P19: pale

Sheet Input Sheet
B1: Sample Descriptions
B3: Depth (mMD) | C3: % Sandstone | D3: Grain Size | E3: Max Grain Size | F3: % Fluor | G3: Brightness | H3: Brightness Code | I3: Gas (U) | J3: FeCO3 in SLTST | K3: FeCO3 in SST | L3: Date | M3: Time | P3: Short Hand | S3: Brightness
A4: Stimpee 7 _OP | B4: 1565 | C4: 15 | D4: vf | E4: VF | F4: 0 | I4: 5 | L4: 45206 | M4: 0.52777778 | P4: f | Q4: fine | R4: =IF(C4="","",IF(OR(L4="",AND(ISNUMBER(R4),C4=R4)),R4,C4)) | S4: bri | T4: 3
A5: Stimpee 7 _OP | B5: 1570 | C5: 20 | D5: vf | E5: VF | F5: 0 | I5: 7 | L5: 45206 | M5: 0.55208333 | P5: med | Q5: medium | R5: =IF(C5="","",IF(OR(L5="",AND(ISNUMBER(R5),C5=R5)),R5,C5)) | S5: mod bri - bri | T5: 2.5
A6: Stimpee 7 _OP | B6: 1575 | C6: 25 | D6: vf | E6: VF | F6: 0 | I6: 8 | L6: 45206 | M6: 0.56597222 | P6: crs | Q6: coarse | R6: =IF(C6="","",IF(OR(L6="",AND(ISNUMBER(R6),C6=R6)),R6,C6)) | S6: mod bri | T6: 2
A7: Stimpee 7 _OP | B7: 1580 | C7: 20 | D7: vf | E7: VF | F7: 0 | I7: 5 | L7: 45206 | M7: 0.58333333 | P7: v | Q7: very | R7: =IF(C7="","",IF(OR(L7="",AND(ISNUMBER(R7),C7=R7)),R7,C7)) | S7: dll - bri | T7: 1.5
A8: Stimpee 7 _OP | B8: 1585 | C8: 15 | D8: vf | E8: VF | F8: 0 | I8: 5 | L8: 45206 | M8: 0.59375 | P8: - | Q8: to | R8: =IF(C8="","",IF(OR(L8="",AND(ISNUMBER(R8),C8=R8)),R8,C8)) | S8: dll - mod bri | T8: 1
A9: Stimpee 7 _OP | B9: 1590 | C9: 15 | D9: vf | E9: VF | F9: 0 | I9: 8 | L9: 45206 | M9: 0.60416667 | P9: occ | Q9: occasional | R9: =IF(C9="","",IF(OR(L9="",AND(ISNUMBER(R9),C9=R9)),R9,C9)) | S9: dll | T9: 0.5
A10: Stimpee 7 _OP | B10: 1595 | C10: 30 | D10: vf-f | E10: F | F10: 0 | I10: 9 | L10: 45206 | M10: 0.62847222 | P10: mnr | Q10: minor | R10: =IF(C10="","",IF(OR(L10="",AND(ISNUMBER(R10),C10=R10)),R10,C10)) | S10: =IF(C10="","",IF(OR(M10="",AND(ISNUMBER(S10),C10=S10)),S10,C10))
A11: Stimpee 7 _OP | B11: 1600 | C11: 50 | D11: vf-f | E11: M | F11: 0 | I11: 11 | L11: 45206 | M11: 0.64236111 | P11: rr | Q11: rare | R11: =IF(C11="","",IF(OR(L11="",AND(ISNUMBER(R11),C11=R11)),R11,C11)) | S11: =IF(C11="","",IF(OR(M11="",AND(ISNUMBER(S11),C11=S11)),S11,C11))
A12: Stimpee 7 _OP | B12: 1605 | C12: 45 | D12: vf-f | E12: M | F12: 0 | I12: 13 | L12: 45206 | M12: 0.64930556 | P12: tr | Q12: trace | R12: =IF(C12="","",IF(OR(L12="",AND(ISNUMBER(R12),C12=R12)),R12,C12)) | S12: =IF(C12="","",IF(OR(M12="",AND(ISNUMBER(S12),C12=S12)),S12,C12))
A13: Stimpee 7 _OP | B13: 1610 | C13: 45 | D13: vf-f | E13: F | F13: 0 | I13: 9 | L13: 45206 | M13: 0.66319444 | P13: mod | Q13: moderately | R13: =IF(C13="","",IF(OR(L13="",AND(ISNUMBER(R13),C13=R13)),R13,C13)) | S13: =IF(C13="","",IF(OR(M13="",AND(ISNUMBER(S13),C13=S13)),S13,C13))
A14: Stimpee 7 _OP | B14: 1615 | C14: 65 | D14: vf-f | E14: C | F14: 15 | G14: mod bri | H14: =_xlfn.XLOOKUP(G14,$S$4:$S$9,$T$4:$T$9,"",0,1) -> 2 | I14: 10 | L14: 45206 | M14: 0.69444444 | P14: bri | Q14: bright | R14: =IF(C14="","",IF(OR(L14="",AND(ISNUMBER(R14),C14=R14)),R14,C14)) | S14: =IF(C14="","",IF(OR(M14="",AND(ISNUMBER(S14),C14=S14)),S14,C14))
A15: Stimpee 7 _OP | B15: 1620 | C15: 70 | D15: vf-f | E15: C | F15: 50 | G15: mod bri | H15: =_xlfn.XLOOKUP(G15,$S$4:$S$9,$T$4:$T$9,"",0,1) -> 2 | I15: 21 | L15: 45206 | M15: 0.72569444 | P15: dll | Q15: dull | R15: =IF(C15="","",IF(OR(L15="",AND(ISNUMBER(R15),C15=R15)),R15,C15)) | S15: =IF(C15="","",IF(OR(M15="",AND(ISNUMBER(S15),C15=S15)),S15,C15))
A16: Stimpee 7 _OP | B16: 1625 | C16: 70 | D16: vf-f | E16: C | F16: 70 | G16: mod bri | H16: =_xlfn.XLOOKUP(G16,$S$4:$S$9,$T$4:$T$9,"",0,1) -> 2 | I16: 25 | L16: 45206 | M16: 0.73958333 | P16: com | Q16: common | R16: =IF(C16="","",IF(OR(L16="",AND(ISNUMBER(R16),C16=R16)),R16,C16)) | S16: =IF(C16="","",IF(OR(M16="",AND(ISNUMBER(S16),C16=S16)),S16,C16))
A17: Stimpee 7 _OP | B17: 1630 | C17: 70 | D17: vf-f | E17: C | F17: 100 | G17: mod bri | H17: =_xlfn.XLOOKUP(G17,$S$4:$S$9,$T$4:$T$9,"",0,1) -> 2 | I17: 22 | L17: 45206 | M17: 0.75347222 | P17: i/p | Q17: in part | R17: =IF(C17="","",IF(OR(L17="",AND(ISNUMBER(R17),C17=R17)),R17,C17)) | S17: =IF(C17="","",IF(OR(M17="",AND(ISNUMBER(S17),C17=S17)),S17,C17))
A18: Stimpee 7 _OP | B18: 1637 | C18: 70 | D18: vf-f | E18: C | F18: 100 | G18: mod bri | H18: =_xlfn.XLOOKUP(G18,$S$4:$S$9,$T$4:$T$9,"",0,1) -> 2 | I18: 17 | L18: 45206 | M18: 0.78125 | P18: dom | Q18: dominantly | R18: =IF(C18="","",IF(OR(L18="",AND(ISNUMBER(R18),C18=R18)),R18,C18)) | S18: =IF(C18="","",IF(OR(M18="",AND(ISNUMBER(S18),C18=S18)),S18,C18))
A19: Stimpee 7 _OP | B19: 1640 | C19: 60 | D19: vf-f | E19: F | F19: 50 | G19: mod bri | H19: =_xlfn.XLOOKUP(G19,$S$4:$S$9,$T$4:$T$9,"",0,1) -> 2 | I19: 13 | L19: 45207 | M19: 0.46527778 | P19: pl | Q19: pale | R19: =IF(C19="","",IF(OR(L19="",AND(ISNUMBER(R19),C19=R19)),R19,C19)) | S19: =IF(C19="","",IF(OR(M19="",AND(ISNUMBER(S19),C19=S19)),S19,C19))
A20: Stimpee 7 _OP | B20: 1645 | C20: 40 | D20: vf-f | E20: F | F20: 50 | G20: mod bri | H20: =_xlfn.XLOOKUP(G20,$S$4:$S$9,$T$4:$T$9,"",0,1) -> 2 | I20: 7 | L20: 45207 | M20: 0.47569444 | R20: =IF(C20="","",IF(OR(L20="",AND(ISNUMBER(R20),C20=R20)),R20,C20)) | S20: =IF(C20="","",IF(OR(M20="",AND(ISNUMBER(S20),C20=S20)),S20,C20))
A21: Stimpee 7 _OP | B21: 1650 | C21: 30 | D21: vf-f | E21: C | F21: 30 | G21: mod bri | H21: =_xlfn.XLOOKUP(G21,$S$4:$S$9,$T$4:$T$9,"",0,1) -> 2 | I21: 18 | L21: 45207 | M21: 0.49652778 | R21: =IF(C21="","",IF(OR(L21="",AND(ISNUMBER(R21),C21=R21)),R21,C21)) | S21: =IF(C21="","",IF(OR(M21="",AND(ISNUMBER(S21),C21=S21)),S21,C21))
A22: Stimpee 7 _OP | B22: 1655 | C22: 30 | D22: vf-f | E22: C | F22: 60 | G22: mod bri | H22: =_xlfn.XLOOKUP(G22,$S$4:$S$9,$T$4:$T$9,"",0,1) -> 2 | I22: 24 | L22: 45207 | M22: 0.51388889 | R22: =IF(C22="","",IF(OR(L22="",AND(ISNUMBER(R22),C22=R22)),R22,C22)) | S22: =IF(C22="","",IF(OR(M22="",AND(ISNUMBER(S22),C22=S22)),S22,C22))
A23: Stimpee 7 _OP | B23: 1660 | C23: 40 | D23: vf-f | E23: C | F23: 60 | G23: mod bri | H23: =_xlfn.XLOOKUP(G23,$S$4:$S$9,$T$4:$T$9,"",0,1) -> 2 | I23: 28 | L23: 45207 | M23: 0.52430556 | R23: =IF(C23="","",IF(OR(L23="",AND(ISNUMBER(R23),C23=R23)),R23,C23)) | S23: =IF(C23="","",IF(OR(M23="",AND(ISNUMBER(S23),C23=S23)),S23,C23))
A24: Stimpee 7 _OP | B24: 1665 | C24: 40 | D24: f-med | E24: C | F24: 60 | G24: mod bri | H24: =_xlfn.XLOOKUP(G24,$S$4:$S$9,$T$4:$T$9,"",0,1) -> 2 | I24: 24 | L24: 45207 | M24: 0.53125 | R24: =IF(C24="","",IF(OR(L24="",AND(ISNUMBER(R24),C24=R24)),R24,C24)) | S24: =IF(C24="","",IF(OR(M24="",AND(ISNUMBER(S24),C24=S24)),S24,C24))
A25: Stimpee 7 _OP | B25: 1670 | C25: 50 | D25: f-med | E25: M | F25: 40 | G25: mod bri | H25: =_xlfn.XLOOKUP(G25,$S$4:$S$9,$T$4:$T$9,"",0,1) -> 2 | I25: 18 | L25: 45207 | M25: 0.54513889 | R25: =IF(C25="","",IF(OR(L25="",AND(ISNUMBER(R25),C25=R25)),R25,C25)) | S25: =IF(C25="","",IF(OR(M25="",AND(ISNUMBER(S25),C25=S25)),S25,C25))
A26: Stimpee 7 _OP | B26: 1675 | C26: 35 | D26: f-med | E26: C | F26: 45 | G26: mod bri | H26: =_xlfn.XLOOKUP(G26,$S$4:$S$9,$T$4:$T$9,"",0,1) -> 2 | I26: 16 | L26: 45207 | M26: 0.56597222 | R26: =IF(C26="","",IF(OR(L26="",AND(ISNUMBER(R26),C26=R26)),R26,C26)) | S26: =IF(C26="","",IF(OR(M26="",AND(ISNUMBER(S26),C26=S26)),S26,C26))
A27: Stimpee 7 _OP | B27: 1680 | C27: 35 | D27: f-med | E27: C | F27: 50 | G27: mod bri | H27: =_xlfn.XLOOKUP(G27,$S$4:$S$9,$T$4:$T$9,"",0,1) -> 2 | I27: 23 | L27: 45207 | M27: 0.57638889 | R27: =IF(C27="","",IF(OR(L27="",AND(ISNUMBER(R27),C27=R27)),R27,C27)) | S27: =IF(C27="","",IF(OR(M27="",AND(ISNUMBER(S27),C27=S27)),S27,C27))
A28: Stimpee 7 _OP | B28: 1685 | C28: 30 | D28: f-med | E28: C | F28: 60 | G28: mod bri | H28: =_xlfn.XLOOKUP(G28,$S$4:$S$9,$T$4:$T$9,"",0,1) -> 2 | I28: 20 | L28: 45207 | M28: 0.59027778 | R28: =IF(C28="","",IF(OR(L28="",AND(ISNUMBER(R28),C28=R28)),R28,C28)) | S28: =IF(C28="","",IF(OR(M28="",AND(ISNUMBER(S28),C28=S28)),S28,C28))
A29: Stimpee 7 _OP | B29: 1690 | C29: 30 | D29: f-med | E29: C | F29: 50 | G29: mod bri | H29: =_xlfn.XLOOKUP(G29,$S$4:$S$9,$T$4:$T$9,"",0,1) -> 2 | I29: 25 | L29: 45207 | M29: 0.60069444 | R29: =IF(C29="","",IF(OR(L29="",AND(ISNUMBER(R29),C29=R29)),R29,C29)) | S29: =IF(C29="","",IF(OR(M29="",AND(ISNUMBER(S29),C29=S29)),S29,C29))
A30: Stimpee 7 _OP | B30: 1695 | C30: 60 | D30: f-med | E30: C | F30: 50 | G30: mod bri | H30: =_xlfn.XLOOKUP(G30,$S$4:$S$9,$T$4:$T$9,"",0,1) -> 2 | I30: 47 | L30: 45207 | M30: 0.61805556 | R30: =IF(C30="","",IF(OR(L30="",AND(ISNUMBER(R30),C30=R30)),R30,C30)) | S30: =IF(C30="","",IF(OR(M30="",AND(ISNUMBER(S30),C30=S30)),S30,C30))
A31: Stimpee 7 _OP | B31: 1700 | C31: 75 | D31: vf-f | E31: M | F31: 60 | G31: mod bri | H31: =_xlfn.XLOOKUP(G31,$S$4:$S$9,$T$4:$T$9,"",0,1) -> 2 | I31: 65 | L31: 45207 | M31: 0.62847222 | R31: =IF(C31="","",IF(OR(L31="",AND(ISNUMBER(R31),C31=R31)),R31,C31)) | S31: =IF(C31="","",IF(OR(M31="",AND(ISNUMBER(S31),C31=S31)),S31,C31))
... A121: Stimpee 7 _OP | B121: 2540 | C121: 95 | D121: vf-f | E121: F | F121: 50 | G121: dll - mod bri | H121: =_xlfn.XLOOKUP(G121,$S$4:$S$9,$T$4:$T$9,"",0,1) -> 1 | I121: 158 | L121: 45209 | M121: 0.46527778 | R121: =IF(C121="","",IF(OR(L121="",AND(ISNUMBER(R121),C121=R121)),R121,C121)) | S121: =IF(C121="","",IF(OR(M121="",AND(ISNUMBER(S121),C121=S121)),S121,C121))
A122: Stimpee 7 _OP | B122: 2550 | C122: 60 | D122: vf-f | E122: C | F122: 10 | G122: dll - mod bri | H122: =_xlfn.XLOOKUP(G122,$S$4:$S$9,$T$4:$T$9,"",0,1) -> 1 | I122: 128 | J122: Y | L122: 45209 | M122: 0.48263889 | R122: =IF(C122="","",IF(OR(L122="",AND(ISNUMBER(R122),C122=R122)),R122,C122)) | S122: =IF(C122="","",IF(OR(M122="",AND(ISNUMBER(S122),C122=S122)),S122,C122))
A123: Stimpee 7 _OP | B123: 2560 | C123: 20 | D123: vf-f | E123: C | F123: 25 | G123: dll - mod bri | H123: =_xlfn.XLOOKUP(G123,$S$4:$S$9,$T$4:$T$9,"",0,1) -> 1 | I123: 119 | J123: Y | L123: 45209 | M123: 0.50347222 | R123: =IF(C123="","",IF(OR(L123="",AND(ISNUMBER(R123),C123=R123)),R123,C123)) | S123: =IF(C123="","",IF(OR(M123="",AND(ISNUMBER(S123),C123=S123)),S123,C123))
A124: Stimpee 7 _OP | B124: 2570 | C124: 20 | D124: vf-f | E124: C | F124: 25 | G124: dll - mod bri | H124: =_xlfn.XLOOKUP(G124,$S$4:$S$9,$T$4:$T$9,"",0,1) -> 1 | I124: 123 | J124: Y | L124: 45209 | M124: 0.52430556 | R124: =IF(C124="","",IF(OR(L124="",AND(ISNUMBER(R124),C124=R124)),R124,C124)) | S124: =IF(C124="","",IF(OR(M124="",AND(ISNUMBER(S124),C124=S124)),S124,C124))
A125: Stimpee 7 _OP | B125: 2580 | C125: 30 | D125: vf-f | E125: M | F125: 25 | G125: dll - mod bri | H125: =_xlfn.XLOOKUP(G125,$S$4:$S$9,$T$4:$T$9,"",0,1) -> 1 | I125: 101 | J125: Y | L125: 45209 | M125: 0.54513889 | R125: =IF(C125="","",IF(OR(L125="",AND(ISNUMBER(R125),C125=R125)),R125,C125)) | S125: =IF(C125="","",IF(OR(M125="",AND(ISNUMBER(S125),C125=S125)),S125,C125))
A126: Stimpee 7 _OP | B126: 2590 | C126: 30 | D126: vf-f | E126: M | F126: 25 | G126: dll - mod bri | H126: =_xlfn.XLOOKUP(G126,$S$4:$S$9,$T$4:$T$9,"",0,1) -> 1 | I126: 89 | J126: Y | L126: 45209 | M126: 0.58333333 | R126: =IF(C126="","",IF(OR(L126="",AND(ISNUMBER(R126),C126=R126)),R126,C126)) | S126: =IF(C126="","",IF(OR(M126="",AND(ISNUMBER(S126),C126=S126)),S126,C126))
A127: Stimpee 7 _OP | B127: 2600 | C127: 40 | D127: vf-f | E127: M | F127: 25 | G127: dll - mod bri | H127: =_xlfn.XLOOKUP(G127,$S$4:$S$9,$T$4:$T$9,"",0,1) -> 1 | I127: 94 | J127: Y | L127: 45209 | M127: 0.59722222 | R127: =IF(C127="","",IF(OR(L127="",AND(ISNUMBER(R127),C127=R127)),R127,C127)) | S127: =IF(C127="","",IF(OR(M127="",AND(ISNUMBER(S127),C127=S127)),S127,C127))
A128: Stimpee 7 _OP | B128: 2610 | C128: 25 | D128: vf-f | E128: M | F128: 20 | G128: dll - mod bri | H128: =_xlfn.XLOOKUP(G128,$S$4:$S$9,$T$4:$T$9,"",0,1) -> 1 | I128: 82 | J128: Y | L128: 45209 | M128: 0.61805556 | R128: =IF(C128="","",IF(OR(L128="",AND(ISNUMBER(R128),C128=R128)),R128,C128)) | S128: =IF(C128="","",IF(OR(M128="",AND(ISNUMBER(S128),C128=S128)),S128,C128))
A129: Stimpee 7 _OP | B129: 2620 | C129: 20 | D129: vf-f | E129: M | F129: 20 | G129: dll - mod bri | H129: =_xlfn.XLOOKUP(G129,$S$4:$S$9,$T$4:$T$9,"",0,1) -> 1 | I129: 89 | J129: Y | L129: 45209 | M129: 0.63194444 | R129: =IF(C129="","",IF(OR(L129="",AND(ISNUMBER(R129),C129=R129)),R129,C129)) | S129: =IF(C129="","",IF(OR(M129="",AND(ISNUMBER(S129),C129=S129)),S129,C129))
A130: Stimpee 7 _OP | B130: 2630 | C130: 40 | D130: vf-f | E130: M | F130: 5 | G130: dll - mod bri | H130: =_xlfn.XLOOKUP(G130,$S$4:$S$9,$T$4:$T$9,"",0,1) -> 1 | I130: 84 | J130: y | L130: 45209 | M130: 0.65625 | R130: =IF(C130="","",IF(OR(L130="",AND(ISNUMBER(R130),C130=R130)),R130,C130)) | S130: =IF(C130="","",IF(OR(M130="",AND(ISNUMBER(S130),C130=S130)),S130,C130))
...

Sheet Long Sample Name
A1: Description | B1: Reservoir Description | C1: Show Description
A2: =IF('Input Sheet'!C4="","",CONCATENATE("Sample ", 'Input Sheet'!B4, "m: ", M2, G2, "% ", "Siltstone, ", O2, 'Input Sheet'!C4, "% ", I2, " Sandstone, ", K2, J2, " FLUOR in SST. ", "TG ", 'Input Sheet'!I4, "U")) -> Sample 1565m: 85% Siltstone, 15% very fine Sandstone, NO FLUOR in SST. TG 5U | B2: =IF('Input Sheet'!C4="","",CONCATENATE("Sample ", 'Input Sheet'!B4, "m: ", N2, H2, "% ", "Siltstone, ", P2, 'Input Sheet'!C4, "% ", J2, " Sandstone ")) -> Sample 1565m: veryfine% Siltstone, 15% Sandstone | C2: =IF('Input Sheet'!C4="","",CONCATENATE("Sample ", 'Input Sheet'!B4, "m: ", M2,, K2, J2, " FLUOR in SST. ", "TG ", 'Input Sheet'!I4, "U")) -> Sample 1565m: NO FLUOR in SST. TG 5U | G2: =IF('Input Sheet'!C4="","",100-'Input Sheet'!C4) -> 85 | H2: =SUBSTITUTE(SUBSTITUTE(SUBSTITUTE(SUBSTITUTE(SUBSTITUTE(SUBSTITUTE(SUBSTITUTE(SUBSTITUTE(SUBSTITUTE(SUBSTITUTE(SUBSTITUTE(SUBSTITUTE(SUBSTITUTE(SUBSTITUTE(SUBSTITUTE(SUBSTITUTE(SUBSTITUTE(SUBSTITUTE(SUBSTITUTE(SUBSTITUTE(SUBSTITUTE(SUBSTITUTE(SUBSTITUTE(SUBSTITUTE(SUBSTITUTE(SUBSTITUTE(SUBSTITUTE(SUBSTITUTE(SUBSTITUTE(SUBSTITUTE(SUBSTITUTE('Input Sheet'!D4,$D$3,$E$3),$D$4,$E$4),$D$5,$E$5),$D$6,$E$6),$D$7,$E$7),$D$8,$E$8),$D$9,$E$9),$D$10,$E$10),$D$11,$E$11),$D$12,$E$12),$D$13,$E$13),$D$14,$E$14),$D$15,$E$15),$D$16,$E$16),$D$17,$E$17),$D$18,$E$18),$D$19,$E$19),$D$20,$E$20),$D$21,$E$21),$D$22,$E$22),$D$23,$E$23),$D$24,$E$24),$D$25,$E$25),$D$26,$E$26),$D$27,$E$27),$D$28,$E$28),$D$29,$E$29),$D$30,$E$30),$D$31,$E$31),$D$32,$E$32),$D$33,$E$33) -> veryfine | I2: =SUBSTITUTE(H2, "veryfine", "very fine") -> very fine | J2: =SUBSTITUTE(SUBSTITUTE(SUBSTITUTE(SUBSTITUTE(SUBSTITUTE(SUBSTITUTE(SUBSTITUTE(SUBSTITUTE(SUBSTITUTE(SUBSTITUTE(SUBSTITUTE(SUBSTITUTE(SUBSTITUTE(SUBSTITUTE(SUBSTITUTE(SUBSTITUTE(SUBSTITUTE(SUBSTITUTE(SUBSTITUTE(SUBSTITUTE(SUBSTITUTE(SUBSTITUTE(SUBSTITUTE(SUBSTITUTE(SUBSTITUTE(SUBSTITUTE(SUBSTITUTE(SUBSTITUTE(SUBSTITUTE(SUBSTITUTE(SUBSTITUTE('Input Sheet'!G4,$D$3,$E$3),$D$4,$E$4),$D$5,$E$5),$D$6,$E$6),$D$7,$E$7),$D$8,$E$8),$D$9,$E$9),$D$10,$E$10),$D$11,$E$11),$D$12,$E$12),$D$13,$E$13),$D$14,$E$14),$D$15,$E$15),$D$16,$E$16),$D$17,$E$17),$D$18,$E$18),$D$19,$E$19),$D$20,$E$20),$D$21,$E$21),$D$22,$E$22),$D$23,$E$23),$D$24,$E$24),$D$25,$E$25),$D$26,$E$26),$D$27,$E$27),$D$28,$E$28),$D$29,$E$29),$D$30,$E$30),$D$31,$E$31),$D$32,$E$32),$D$33,$E$33) | K2: =IF('Input Sheet'!F4=0, "NO",CONCATENATE('Input Sheet'!F4, IF('Input Sheet'!F4>0,"% ",""))) -> NO | L2: =SUBSTITUTE(SUBSTITUTE(SUBSTITUTE(SUBSTITUTE(SUBSTITUTE(SUBSTITUTE(SUBSTITUTE(SUBSTITUTE(SUBSTITUTE(SUBSTITUTE(SUBSTITUTE(SUBSTITUTE(SUBSTITUTE(SUBSTITUTE(SUBSTITUTE(SUBSTITUTE(SUBSTITUTE(SUBSTITUTE(SUBSTITUTE(SUBSTITUTE(SUBSTITUTE(SUBSTITUTE(SUBSTITUTE(SUBSTITUTE(SUBSTITUTE(SUBSTITUTE(SUBSTITUTE(SUBSTITUTE(SUBSTITUTE(SUBSTITUTE(SUBSTITUTE('Input Sheet'!J4,$D$3,$E$3),$D$4,$E$4),$D$5,$E$5),$D$6,$E$6),$D$7,$E$7),$D$8,$E$8),$D$9,$E$9),$D$10,$E$10),$D$11,$E$11),$D$12,$E$12),$D$13,$E$13),$D$14,$E$14),$D$15,$E$15),$D$16,$E$16),$D$17,$E$17),$D$18,$E$18),$D$19,$E$19),$D$20,$E$20),$D$21,$E$21),$D$22,$E$22),$D$23,$E$23),$D$24,$E$24),$D$25,$E$25),$D$26,$E$26),$D$27,$E$27),$D$28,$E$28),$D$29,$E$29),$D$30,$E$30),$D$31,$E$31),$D$32,$E$32),$D$33,$E$33) | M2: =CONCATENATE(L2, IF('Input Sheet'!J4="",""," siderite in ")) | N2: =SUBSTITUTE(SUBSTITUTE(SUBSTITUTE(SUBSTITUTE(SUBSTITUTE(SUBSTITUTE(SUBSTITUTE(SUBSTITUTE(SUBSTITUTE(SUBSTITUTE(SUBSTITUTE(SUBSTITUTE(SUBSTITUTE(SUBSTITUTE(SUBSTITUTE(SUBSTITUTE(SUBSTITUTE(SUBSTITUTE(SUBSTITUTE(SUBSTITUTE(SUBSTITUTE(SUBSTITUTE(SUBSTITUTE(SUBSTITUTE(SUBSTITUTE(SUBSTITUTE(SUBSTITUTE(SUBSTITUTE(SUBSTITUTE(SUBSTITUTE(SUBSTITUTE('Input Sheet'!K4,$D$3,$E$3),$D$4,$E$4),$D$5,$E$5),$D$6,$E$6),$D$7,$E$7),$D$8,$E$8),$D$9,$E$9),$D$10,$E$10),$D$11,$E$11),$D$12,$E$12),$D$13,$E$13),$D$14,$E$14),$D$15,$E$15),$D$16,$E$16),$D$17,$E$17),$D$18,$E$18),$D$19,$E$19),$D$20,$E$20),$D$21,$E$21),$D$22,$E$22),$D$23,$E$23),$D$24,$E$24),$D$25,$E$25),$D$26,$E$26),$D$27,$E$27),$D$28,$E$28),$D$29,$E$29),$D$30,$E$30),$D$31,$E$31),$D$32,$E$32),$D$33,$E$33) | O2: =CONCATENATE(N2, IF('Input Sheet'!K4="",""," siderite in "))
A3: =IF('Input Sheet'!C5="","",CONCATENATE("Sample ", 'Input Sheet'!B5, "m: ", M3, G3, "% ", "Siltstone, ", O3, 'Input Sheet'!C5, "% ", I3, " Sandstone, ", K3, J3, " FLUOR in SST. ", "TG ", 'Input Sheet'!I5, "U")) -> Sample 1570m: 80% Siltstone, 20% very fine Sandstone, NO FLUOR in SST. TG 7U | B3: =IF('Input Sheet'!C5="","",CONCATENATE("Sample ", 'Input Sheet'!B5, "m: ", N3, H3, "% ", "Siltstone, ", P3, 'Input Sheet'!C5, "% ", J3, " Sandstone ")) -> Sample 1570m: veryfine% Siltstone, 20% Sandstone | C3: =IF('Input Sheet'!C5="","",CONCATENATE("Sample ", 'Input Sheet'!B5, "m: ", M3,, K3, J3, " FLUOR in SST. ", "TG ", 'Input Sheet'!I5, "U")) -> Sample 1570m: NO FLUOR in SST. TG 7U | G3: =IF('Input Sheet'!C5="","",100-'Input Sheet'!C5) -> 80 | H3: =SUBSTITUTE(SUBSTITUTE(SUBSTITUTE(SUBSTITUTE(SUBSTITUTE(SUBSTITUTE(SUBSTITUTE(SUBSTITUTE(SUBSTITUTE(SUBSTITUTE(SUBSTITUTE(SUBSTITUTE(SUBSTITUTE(SUBSTITUTE(SUBSTITUTE(SUBSTITUTE(SUBSTITUTE(SUBSTITUTE(SUBSTITUTE(SUBSTITUTE(SUBSTITUTE(SUBSTITUTE(SUBSTITUTE(SUBSTITUTE(SUBSTITUTE(SUBSTITUTE(SUBSTITUTE(SUBSTITUTE(SUBSTITUTE(SUBSTITUTE(SUBSTITUTE('Input Sheet'!D5,$D$3,$E$3),$D$4,$E$4),$D$5,$E$5),$D$6,$E$6),$D$7,$E$7),$D$8,$E$8),$D$9,$E$9),$D$10,$E$10),$D$11,$E$11),$D$12,$E$12),$D$13,$E$13),$D$14,$E$14),$D$15,$E$15),$D$16,$E$16),$D$17,$E$17),$D$18,$E$18),$D$19,$E$19),$D$20,$E$20),$D$21,$E$21),$D$22,$E$22),$D$23,$E$23),$D$24,$E$24),$D$25,$E$25),$D$26,$E$26),$D$27,$E$27),$D$28,$E$28),$D$29,$E$29),$D$30,$E$30),$D$31,$E$31),$D$32,$E$32),$D$33,$E$33) -> veryfine | I3: =SUBSTITUTE(H3, "veryfine", "very fine") -> very fine | J3: =SUBSTITUTE(SUBSTITUTE(SUBSTITUTE(SUBSTITUTE(SUBSTITUTE(SUBSTITUTE(SUBSTITUTE(SUBSTITUTE(SUBSTITUTE(SUBSTITUTE(SUBSTITUTE(SUBSTITUTE(SUBSTITUTE(SUBSTITUTE(SUBSTITUTE(SUBSTITUTE(SUBSTITUTE(SUBSTITUTE(SUBSTITUTE(SUBSTITUTE(SUBSTITUTE(SUBSTITUTE(SUBSTITUTE(SUBSTITUTE(SUBSTITUTE(SUBSTITUTE(SUBSTITUTE(SUBSTITUTE(SUBSTITUTE(SUBSTITUTE(SUBSTITUTE('Input Sheet'!G5,$D$3,$E$3),$D$4,$E$4),$D$5,$E$5),$D$6,$E$6),$D$7,$E$7),$D$8,$E$8),$D$9,$E$9),$D$10,$E$10),$D$11,$E$11),$D$12,$E$12),$D$13,$E$13),$D$14,$E$14),$D$15,$E$15),$D$16,$E$16),$D$17,$E$17),$D$18,$E$18),$D$19,$E$19),$D$20,$E$20),$D$21,$E$21),$D$22,$E$22),$D$23,$E$23),$D$24,$E$24),$D$25,$E$25),$D$26,$E$26),$D$27,$E$27),$D$28,$E$28),$D$29,$E$29),$D$30,$E$30),$D$31,$E$31),$D$32,$E$32),$D$33,$E$33) | K3: =IF('Input Sheet'!F5=0, "NO",CONCATENATE('Input Sheet'!F5, IF('Input Sheet'!F5>0,"% ",""))) -> NO | L3: =SUBSTITUTE(SUBSTITUTE(SUBSTITUTE(SUBSTITUTE(SUBSTITUTE(SUBSTITUTE(SUBSTITUTE(SUBSTITUTE(SUBSTITUTE(SUBSTITUTE(SUBSTITUTE(SUBSTITUTE(SUBSTITUTE(SUBSTITUTE(SUBSTITUTE(SUBSTITUTE(SUBSTITUTE(SUBSTITUTE(SUBSTITUTE(SUBSTITUTE(SUBSTITUTE(SUBSTITUTE(SUBSTITUTE(SUBSTITUTE(SUBSTITUTE(SUBSTITUTE(SUBSTITUTE(SUBSTITUTE(SUBSTITUTE(SUBSTITUTE(SUBSTITUTE('Input Sheet'!J5,$D$3,$E$3),$D$4,$E$4),$D$5,$E$5),$D$6,$E$6),$D$7,$E$7),$D$8,$E$8),$D$9,$E$9),$D$10,$E$10),$D$11,$E$11),$D$12,$E$12),$D$13,$E$13),$D$14,$E$14),$D$15,$E$15),$D$16,$E$16),$D$17,$E$17),$D$18,$E$18),$D$19,$E$19),$D$20,$E$20),$D$21,$E$21),$D$22,$E$22),$D$23,$E$23),$D$24,$E$24),$D$25,$E$25),$D$26,$E$26),$D$27,$E$27),$D$28,$E$28),$D$29,$E$29),$D$30,$E$30),$D$31,$E$31),$D$32,$E$32),$D$33,$E$33) | M3: =CONCATENATE(L3, IF('Input Sheet'!J5="",""," siderite in ")) | N3: =SUBSTITUTE(SUBSTITUTE(SUBSTITUTE(SUBSTITUTE(SUBSTITUTE(SUBSTITUTE(SUBSTITUTE(SUBSTITUTE(SUBSTITUTE(SUBSTITUTE(SUBSTITUTE(SUBSTITUTE(SUBSTITUTE(SUBSTITUTE(SUBSTITUTE(SUBSTITUTE(SUBSTITUTE(SUBSTITUTE(SUBSTITUTE(SUBSTITUTE(SUBSTITUTE(SUBSTITUTE(SUBSTITUTE(SUBSTITUTE(SUBSTITUTE(SUBSTITUTE(SUBSTITUTE(SUBSTITUTE(SUBSTITUTE(SUBSTITUTE(SUBSTITUTE('Input Sheet'!K5,$D$3,$E$3),$D$4,$E$4),$D$5,$E$5),$D$6,$E$6),$D$7,$E$7),$D$8,$E$8),$D$9,$E$9),$D$10,$E$10),$D$11,$E$11),$D$12,$E$12),$D$13,$E$13),$D$14,$E$14),$D$15,$E$15),$D$16,$E$16),$D$17,$E$17),$D$18,$E$18),$D$19,$E$19),$D$20,$E$20),$D$21,$E$21),$D$22,$E$22),$D$23,$E$23),$D$24,$E$24),$D$25,$E$25),$D$26,$E$26),$D$27,$E$27),$D$28,$E$28),$D$29,$E$29),$D$30,$E$30),$D$31,$E$31),$D$32,$E$32),$D$33,$E$33) | O3: =CONCATENATE(N3, IF('Input Sheet'!K5="",""," siderite in "))
A4: =IF('Input Sheet'!C6="","",CONCATENATE("Sample ", 'Input Sheet'!B6, "m: ", M4, G4, "% ", "Siltstone, ", O4, 'Input Sheet'!C6, "% ", I4, " Sandstone, ", K4, J4, " FLUOR in SST. ", "TG ", 'Input Sheet'!I6, "U")) -> Sample 1575m: 75% Siltstone, 25% very fine Sandstone, NO FLUOR in SST. TG 8U | B4: =IF('Input Sheet'!C6="","",CONCATENATE("Sample ", 'Input Sheet'!B6, "m: ", N4, H4, "% ", "Siltstone, ", P4, 'Input Sheet'!C6, "% ", J4, " Sandstone ")) -> Sample 1575m: veryfine% Siltstone, 25% Sandstone | C4: =IF('Input Sheet'!C6="","",CONCATENATE("Sample ", 'Input Sheet'!B6, "m: ", M4,, K4, J4, " FLUOR in SST. ", "TG ", 'Input Sheet'!I6, "U")) -> Sample 1575m: NO FLUOR in SST. TG 8U | D4: f | E4: fine | G4: =IF('Input Sheet'!C6="","",100-'Input Sheet'!C6) -> 75 | H4: =SUBSTITUTE(SUBSTITUTE(SUBSTITUTE(SUBSTITUTE(SUBSTITUTE(SUBSTITUTE(SUBSTITUTE(SUBSTITUTE(SUBSTITUTE(SUBSTITUTE(SUBSTITUTE(SUBSTITUTE(SUBSTITUTE(SUBSTITUTE(SUBSTITUTE(SUBSTITUTE(SUBSTITUTE(SUBSTITUTE(SUBSTITUTE(SUBSTITUTE(SUBSTITUTE(SUBSTITUTE(SUBSTITUTE(SUBSTITUTE(SUBSTITUTE(SUBSTITUTE(SUBSTITUTE(SUBSTITUTE(SUBSTITUTE(SUBSTITUTE(SUBSTITUTE('Input Sheet'!D6,$D$3,$E$3),$D$4,$E$4),$D$5,$E$5),$D$6,$E$6),$D$7,$E$7),$D$8,$E$8),$D$9,$E$9),$D$10,$E$10),$D$11,$E$11),$D$12,$E$12),$D$13,$E$13),$D$14,$E$14),$D$15,$E$15),$D$16,$E$16),$D$17,$E$17),$D$18,$E$18),$D$19,$E$19),$D$20,$E$20),$D$21,$E$21),$D$22,$E$22),$D$23,$E$23),$D$24,$E$24),$D$25,$E$25),$D$26,$E$26),$D$27,$E$27),$D$28,$E$28),$D$29,$E$29),$D$30,$E$30),$D$31,$E$31),$D$32,$E$32),$D$33,$E$33) -> veryfine | I4: =SUBSTITUTE(H4, "veryfine", "very fine") -> very fine | J4: =SUBSTITUTE(SUBSTITUTE(SUBSTITUTE(SUBSTITUTE(SUBSTITUTE(SUBSTITUTE(SUBSTITUTE(SUBSTITUTE(SUBSTITUTE(SUBSTITUTE(SUBSTITUTE(SUBSTITUTE(SUBSTITUTE(SUBSTITUTE(SUBSTITUTE(SUBSTITUTE(SUBSTITUTE(SUBSTITUTE(SUBSTITUTE(SUBSTITUTE(SUBSTITUTE(SUBSTITUTE(SUBSTITUTE(SUBSTITUTE(SUBSTITUTE(SUBSTITUTE(SUBSTITUTE(SUBSTITUTE(SUBSTITUTE(SUBSTITUTE(SUBSTITUTE('Input Sheet'!G6,$D$3,$E$3),$D$4,$E$4),$D$5,$E$5),$D$6,$E$6),$D$7,$E$7),$D$8,$E$8),$D$9,$E$9),$D$10,$E$10),$D$11,$E$11),$D$12,$E$12),$D$13,$E$13),$D$14,$E$14),$D$15,$E$15),$D$16,$E$16),$D$17,$E$17),$D$18,$E$18),$D$19,$E$19),$D$20,$E$20),$D$21,$E$21),$D$22,$E$22),$D$23,$E$23),$D$24,$E$24),$D$25,$E$25),$D$26,$E$26),$D$27,$E$27),$D$28,$E$28),$D$29,$E$29),$D$30,$E$30),$D$31,$E$31),$D$32,$E$32),$D$33,$E$33) | K4: =IF('Input Sheet'!F6=0, "NO",CONCATENATE('Input Sheet'!F6, IF('Input Sheet'!F6>0,"% ",""))) -> NO | L4: =SUBSTITUTE(SUBSTITUTE(SUBSTITUTE(SUBSTITUTE(SUBSTITUTE(SUBSTITUTE(SUBSTITUTE(SUBSTITUTE(SUBSTITUTE(SUBSTITUTE(SUBSTITUTE(SUBSTITUTE(SUBSTITUTE(SUBSTITUTE(SUBSTITUTE(SUBSTITUTE(SUBSTITUTE(SUBSTITUTE(SUBSTITUTE(SUBSTITUTE(SUBSTITUTE(SUBSTITUTE(SUBSTITUTE(SUBSTITUTE(SUBSTITUTE(SUBSTITUTE(SUBSTITUTE(SUBSTITUTE(SUBSTITUTE(SUBSTITUTE(SUBSTITUTE('Input Sheet'!J6,$D$3,$E$3),$D$4,$E$4),$D$5,$E$5),$D$6,$E$6),$D$7,$E$7),$D$8,$E$8),$D$9,$E$9),$D$10,$E$10),$D$11,$E$11),$D$12,$E$12),$D$13,$E$13),$D$14,$E$14),$D$15,$E$15),$D$16,$E$16),$D$17,$E$17),$D$18,$E$18),$D$19,$E$19),$D$20,$E$20),$D$21,$E$21),$D$22,$E$22),$D$23,$E$23),$D$24,$E$24),$D$25,$E$25),$D$26,$E$26),$D$27,$E$27),$D$28,$E$28),$D$29,$E$29),$D$30,$E$30),$D$31,$E$31),$D$32,$E$32),$D$33,$E$33) | M4: =CONCATENATE(L4, IF('Input Sheet'!J6="",""," siderite in ")) | N4: =SUBSTITUTE(SUBSTITUTE(SUBSTITUTE(SUBSTITUTE(SUBSTITUTE(SUBSTITUTE(SUBSTITUTE(SUBSTITUTE(SUBSTITUTE(SUBSTITUTE(SUBSTITUTE(SUBSTITUTE(SUBSTITUTE(SUBSTITUTE(SUBSTITUTE(SUBSTITUTE(SUBSTITUTE(SUBSTITUTE(SUBSTITUTE(SUBSTITUTE(SUBSTITUTE(SUBSTITUTE(SUBSTITUTE(SUBSTITUTE(SUBSTITUTE(SUBSTITUTE(SUBSTITUTE(SUBSTITUTE(SUBSTITUTE(SUBSTITUTE(SUBSTITUTE('Input Sheet'!K6,$D$3,$E$3),$D$4,$E$4),$D$5,$E$5),$D$6,$E$6),$D$7,$E$7),$D$8,$E$8),$D$9,$E$9),$D$10,$E$10),$D$11,$E$11),$D$12,$E$12),$D$13,$E$13),$D$14,$E$14),$D$15,$E$15),$D$16,$E$16),$D$17,$E$17),$D$18,$E$18),$D$19,$E$19),$D$20,$E$20),$D$21,$E$21),$D$22,$E$22),$D$23,$E$23),$D$24,$E$24),$D$25,$E$25),$D$26,$E$26),$D$27,$E$27),$D$28,$E$28),$D$29,$E$29),$D$30,$E$30),$D$31,$E$31),$D$32,$E$32),$D$33,$E$33) | O4: =CONCATENATE(N4, IF('Input Sheet'!K6="",""," siderite in "))
A5: =IF('Input Sheet'!C7="","",CONCATENATE("Sample ", 'Input Sheet'!B7, "m: ", M5, G5, "% ", "Siltstone, ", O5, 'Input Sheet'!C7, "% ", I5, " Sandstone, ", K5, J5, " FLUOR in SST. ", "TG ", 'Input Sheet'!I7, "U")) -> Sample 1580m: 80% Siltstone, 20% very fine Sandstone, NO FLUOR in SST. TG 5U | B5: =IF('Input Sheet'!C7="","",CONCATENATE("Sample ", 'Input Sheet'!B7, "m: ", N5, H5, "% ", "Siltstone, ", P5, 'Input Sheet'!C7, "% ", J5, " Sandstone ")) -> Sample 1580m: veryfine% Siltstone, 20% Sandstone | C5: =IF('Input Sheet'!C7="","",CONCATENATE("Sample ", 'Input Sheet'!B7, "m: ", M5,, K5, J5, " FLUOR in SST. ", "TG ", 'Input Sheet'!I7, "U")) -> Sample 1580m: NO FLUOR in SST. TG 5U | D5: med | E5: medium | G5: =IF('Input Sheet'!C7="","",100-'Input Sheet'!C7) -> 80 | H5: =SUBSTITUTE(SUBSTITUTE(SUBSTITUTE(SUBSTITUTE(SUBSTITUTE(SUBSTITUTE(SUBSTITUTE(SUBSTITUTE(SUBSTITUTE(SUBSTITUTE(SUBSTITUTE(SUBSTITUTE(SUBSTITUTE(SUBSTITUTE(SUBSTITUTE(SUBSTITUTE(SUBSTITUTE(SUBSTITUTE(SUBSTITUTE(SUBSTITUTE(SUBSTITUTE(SUBSTITUTE(SUBSTITUTE(SUBSTITUTE(SUBSTITUTE(SUBSTITUTE(SUBSTITUTE(SUBSTITUTE(SUBSTITUTE(SUBSTITUTE(SUBSTITUTE('Input Sheet'!D7,$D$3,$E$3),$D$4,$E$4),$D$5,$E$5),$D$6,$E$6),$D$7,$E$7),$D$8,$E$8),$D$9,$E$9),$D$10,$E$10),$D$11,$E$11),$D$12,$E$12),$D$13,$E$13),$D$14,$E$14),$D$15,$E$15),$D$16,$E$16),$D$17,$E$17),$D$18,$E$18),$D$19,$E$19),$D$20,$E$20),$D$21,$E$21),$D$22,$E$22),$D$23,$E$23),$D$24,$E$24),$D$25,$E$25),$D$26,$E$26),$D$27,$E$27),$D$28,$E$28),$D$29,$E$29),$D$30,$E$30),$D$31,$E$31),$D$32,$E$32),$D$33,$E$33) -> veryfine | I5: =SUBSTITUTE(H5, "veryfine", "very fine") -> very fine | J5: =SUBSTITUTE(SUBSTITUTE(SUBSTITUTE(SUBSTITUTE(SUBSTITUTE(SUBSTITUTE(SUBSTITUTE(SUBSTITUTE(SUBSTITUTE(SUBSTITUTE(SUBSTITUTE(SUBSTITUTE(SUBSTITUTE(SUBSTITUTE(SUBSTITUTE(SUBSTITUTE(SUBSTITUTE(SUBSTITUTE(SUBSTITUTE(SUBSTITUTE(SUBSTITUTE(SUBSTITUTE(SUBSTITUTE(SUBSTITUTE(SUBSTITUTE(SUBSTITUTE(SUBSTITUTE(SUBSTITUTE(SUBSTITUTE(SUBSTITUTE(SUBSTITUTE('Input Sheet'!G7,$D$3,$E$3),$D$4,$E$4),$D$5,$E$5),$D$6,$E$6),$D$7,$E$7),$D$8,$E$8),$D$9,$E$9),$D$10,$E$10),$D$11,$E$11),$D$12,$E$12),$D$13,$E$13),$D$14,$E$14),$D$15,$E$15),$D$16,$E$16),$D$17,$E$17),$D$18,$E$18),$D$19,$E$19),$D$20,$E$20),$D$21,$E$21),$D$22,$E$22),$D$23,$E$23),$D$24,$E$24),$D$25,$E$25),$D$26,$E$26),$D$27,$E$27),$D$28,$E$28),$D$29,$E$29),$D$30,$E$30),$D$31,$E$31),$D$32,$E$32),$D$33,$E$33) | K5: =IF('Input Sheet'!F7=0, "NO",CONCATENATE('Input Sheet'!F7, IF('Input Sheet'!F7>0,"% ",""))) -> NO | L5: =SUBSTITUTE(SUBSTITUTE(SUBSTITUTE(SUBSTITUTE(SUBSTITUTE(SUBSTITUTE(SUBSTITUTE(SUBSTITUTE(SUBSTITUTE(SUBSTITUTE(SUBSTITUTE(SUBSTITUTE(SUBSTITUTE(SUBSTITUTE(SUBSTITUTE(SUBSTITUTE(SUBSTITUTE(SUBSTITUTE(SUBSTITUTE(SUBSTITUTE(SUBSTITUTE(SUBSTITUTE(SUBSTITUTE(SUBSTITUTE(SUBSTITUTE(SUBSTITUTE(SUBSTITUTE(SUBSTITUTE(SUBSTITUTE(SUBSTITUTE(SUBSTITUTE('Input Sheet'!J7,$D$3,$E$3),$D$4,$E$4),$D$5,$E$5),$D$6,$E$6),$D$7,$E$7),$D$8,$E$8),$D$9,$E$9),$D$10,$E$10),$D$11,$E$11),$D$12,$E$12),$D$13,$E$13),$D$14,$E$14),$D$15,$E$15),$D$16,$E$16),$D$17,$E$17),$D$18,$E$18),$D$19,$E$19),$D$20,$E$20),$D$21,$E$21),$D$22,$E$22),$D$23,$E$23),$D$24,$E$24),$D$25,$E$25),$D$26,$E$26),$D$27,$E$27),$D$28,$E$28),$D$29,$E$29),$D$30,$E$30),$D$31,$E$31),$D$32,$E$32),$D$33,$E$33) | M5: =CONCATENATE(L5, IF('Input Sheet'!J7="",""," siderite in ")) | N5: =SUBSTITUTE(SUBSTITUTE(SUBSTITUTE(SUBSTITUTE(SUBSTITUTE(SUBSTITUTE(SUBSTITUTE(SUBSTITUTE(SUBSTITUTE(SUBSTITUTE(SUBSTITUTE(SUBSTITUTE(SUBSTITUTE(SUBSTITUTE(SUBSTITUTE(SUBSTITUTE(SUBSTITUTE(SUBSTITUTE(SUBSTITUTE(SUBSTITUTE(SUBSTITUTE(SUBSTITUTE(SUBSTITUTE(SUBSTITUTE(SUBSTITUTE(SUBSTITUTE(SUBSTITUTE(SUBSTITUTE(SUBSTITUTE(SUBSTITUTE(SUBSTITUTE('Input Sheet'!K7,$D$3,$E$3),$D$4,$E$4),$D$5,$E$5),$D$6,$E$6),$D$7,$E$7),$D$8,$E$8),$D$9,$E$9),$D$10,$E$10),$D$11,$E$11),$D$12,$E$12),$D$13,$E$13),$D$14,$E$14),$D$15,$E$15),$D$16,$E$16),$D$17,$E$17),$D$18,$E$18),$D$19,$E$19),$D$20,$E$20),$D$21,$E$21),$D$22,$E$22),$D$23,$E$23),$D$24,$E$24),$D$25,$E$25),$D$26,$E$26),$D$27,$E$27),$D$28,$E$28),$D$29,$E$29),$D$30,$E$30),$D$31,$E$31),$D$32,$E$32),$D$33,$E$33) | O5: =CONCATENATE(N5, IF('Input Sheet'!K7="",""," siderite in "))
A6: =IF('Input Sheet'!C8="","",CONCATENATE("Sample ", 'Input Sheet'!B8, "m: ", M6, G6, "% ", "Siltstone, ", O6, 'Input Sheet'!C8, "% ", I6, " Sandstone, ", K6, J6, " FLUOR in SST. ", "TG ", 'Input Sheet'!I8, "U")) -> Sample 1585m: 85% Siltstone, 15% very fine Sandstone, NO FLUOR in SST. TG 5U | B6: =IF('Input Sheet'!C8="","",CONCATENATE("Sample ", 'Input Sheet'!B8, "m: ", N6, H6, "% ", "Siltstone, ", P6, 'Input Sheet'!C8, "% ", J6, " Sandstone ")) -> Sample 1585m: veryfine% Siltstone, 15% Sandstone | C6: =IF('Input Sheet'!C8="","",CONCATENATE("Sample ", 'Input Sheet'!B8, "m: ", M6,, K6, J6, " FLUOR in SST. ", "TG ", 'Input Sheet'!I8, "U")) -> Sample 1585m: NO FLUOR in SST. TG 5U | D6: crs | E6: coarse | G6: =IF('Input Sheet'!C8="","",100-'Input Sheet'!C8) -> 85 | H6: =SUBSTITUTE(SUBSTITUTE(SUBSTITUTE(SUBSTITUTE(SUBSTITUTE(SUBSTITUTE(SUBSTITUTE(SUBSTITUTE(SUBSTITUTE(SUBSTITUTE(SUBSTITUTE(SUBSTITUTE(SUBSTITUTE(SUBSTITUTE(SUBSTITUTE(SUBSTITUTE(SUBSTITUTE(SUBSTITUTE(SUBSTITUTE(SUBSTITUTE(SUBSTITUTE(SUBSTITUTE(SUBSTITUTE(SUBSTITUTE(SUBSTITUTE(SUBSTITUTE(SUBSTITUTE(SUBSTITUTE(SUBSTITUTE(SUBSTITUTE(SUBSTITUTE('Input Sheet'!D8,$D$3,$E$3),$D$4,$E$4),$D$5,$E$5),$D$6,$E$6),$D$7,$E$7),$D$8,$E$8),$D$9,$E$9),$D$10,$E$10),$D$11,$E$11),$D$12,$E$12),$D$13,$E$13),$D$14,$E$14),$D$15,$E$15),$D$16,$E$16),$D$17,$E$17),$D$18,$E$18),$D$19,$E$19),$D$20,$E$20),$D$21,$E$21),$D$22,$E$22),$D$23,$E$23),$D$24,$E$24),$D$25,$E$25),$D$26,$E$26),$D$27,$E$27),$D$28,$E$28),$D$29,$E$29),$D$30,$E$30),$D$31,$E$31),$D$32,$E$32),$D$33,$E$33) -> veryfine | I6: =SUBSTITUTE(H6, "veryfine", "very fine") -> very fine | J6: =SUBSTITUTE(SUBSTITUTE(SUBSTITUTE(SUBSTITUTE(SUBSTITUTE(SUBSTITUTE(SUBSTITUTE(SUBSTITUTE(SUBSTITUTE(SUBSTITUTE(SUBSTITUTE(SUBSTITUTE(SUBSTITUTE(SUBSTITUTE(SUBSTITUTE(SUBSTITUTE(SUBSTITUTE(SUBSTITUTE(SUBSTITUTE(SUBSTITUTE(SUBSTITUTE(SUBSTITUTE(SUBSTITUTE(SUBSTITUTE(SUBSTITUTE(SUBSTITUTE(SUBSTITUTE(SUBSTITUTE(SUBSTITUTE(SUBSTITUTE(SUBSTITUTE('Input Sheet'!G8,$D$3,$E$3),$D$4,$E$4),$D$5,$E$5),$D$6,$E$6),$D$7,$E$7),$D$8,$E$8),$D$9,$E$9),$D$10,$E$10),$D$11,$E$11),$D$12,$E$12),$D$13,$E$13),$D$14,$E$14),$D$15,$E$15),$D$16,$E$16),$D$17,$E$17),$D$18,$E$18),$D$19,$E$19),$D$20,$E$20),$D$21,$E$21),$D$22,$E$22),$D$23,$E$23),$D$24,$E$24),$D$25,$E$25),$D$26,$E$26),$D$27,$E$27),$D$28,$E$28),$D$29,$E$29),$D$30,$E$30),$D$31,$E$31),$D$32,$E$32),$D$33,$E$33) | K6: =IF('Input Sheet'!F8=0, "NO",CONCATENATE('Input Sheet'!F8, IF('Input Sheet'!F8>0,"% ",""))) -> NO | L6: =SUBSTITUTE(SUBSTITUTE(SUBSTITUTE(SUBSTITUTE(SUBSTITUTE(SUBSTITUTE(SUBSTITUTE(SUBSTITUTE(SUBSTITUTE(SUBSTITUTE(SUBSTITUTE(SUBSTITUTE(SUBSTITUTE(SUBSTITUTE(SUBSTITUTE(SUBSTITUTE(SUBSTITUTE(SUBSTITUTE(SUBSTITUTE(SUBSTITUTE(SUBSTITUTE(SUBSTITUTE(SUBSTITUTE(SUBSTITUTE(SUBSTITUTE(SUBSTITUTE(SUBSTITUTE(SUBSTITUTE(SUBSTITUTE(SUBSTITUTE(SUBSTITUTE('Input Sheet'!J8,$D$3,$E$3),$D$4,$E$4),$D$5,$E$5),$D$6,$E$6),$D$7,$E$7),$D$8,$E$8),$D$9,$E$9),$D$10,$E$10),$D$11,$E$11),$D$12,$E$12),$D$13,$E$13),$D$14,$E$14),$D$15,$E$15),$D$16,$E$16),$D$17,$E$17),$D$18,$E$18),$D$19,$E$19),$D$20,$E$20),$D$21,$E$21),$D$22,$E$22),$D$23,$E$23),$D$24,$E$24),$D$25,$E$25),$D$26,$E$26),$D$27,$E$27),$D$28,$E$28),$D$29,$E$29),$D$30,$E$30),$D$31,$E$31),$D$32,$E$32),$D$33,$E$33) | M6: =CONCATENATE(L6, IF('Input Sheet'!J8="",""," siderite in ")) | N6: =SUBSTITUTE(SUBSTITUTE(SUBSTITUTE(SUBSTITUTE(SUBSTITUTE(SUBSTITUTE(SUBSTITUTE(SUBSTITUTE(SUBSTITUTE(SUBSTITUTE(SUBSTITUTE(SUBSTITUTE(SUBSTITUTE(SUBSTITUTE(SUBSTITUTE(SUBSTITUTE(SUBSTITUTE(SUBSTITUTE(SUBSTITUTE(SUBSTITUTE(SUBSTITUTE(SUBSTITUTE(SUBSTITUTE(SUBSTITUTE(SUBSTITUTE(SUBSTITUTE(SUBSTITUTE(SUBSTITUTE(SUBSTITUTE(SUBSTITUTE(SUBSTITUTE('Input Sheet'!K8,$D$3,$E$3),$D$4,$E$4),$D$5,$E$5),$D$6,$E$6),$D$7,$E$7),$D$8,$E$8),$D$9,$E$9),$D$10,$E$10),$D$11,$E$11),$D$12,$E$12),$D$13,$E$13),$D$14,$E$14),$D$15,$E$15),$D$16,$E$16),$D$17,$E$17),$D$18,$E$18),$D$19,$E$19),$D$20,$E$20),$D$21,$E$21),$D$22,$E$22),$D$23,$E$23),$D$24,$E$24),$D$25,$E$25),$D$26,$E$26),$D$27,$E$27),$D$28,$E$28),$D$29,$E$29),$D$30,$E$30),$D$31,$E$31),$D$32,$E$32),$D$33,$E$33) | O6: =CONCATENATE(N6, IF('Input Sheet'!K8="",""," siderite in "))
A7: =IF('Input Sheet'!C9="","",CONCATENATE("Sample ", 'Input Sheet'!B9, "m: ", M7, G7, "% ", "Siltstone, ", O7, 'Input Sheet'!C9, "% ", I7, " Sandstone, ", K7, J7, " FLUOR in SST. ", "TG ", 'Input Sheet'!I9, "U")) -> Sample 1590m: 85% Siltstone, 15% very fine Sandstone, NO FLUOR in SST. TG 8U | B7: =IF('Input Sheet'!C9="","",CONCATENATE("Sample ", 'Input Sheet'!B9, "m: ", N7, H7, "% ", "Siltstone, ", P7, 'Input Sheet'!C9, "% ", J7, " Sandstone ")) -> Sample 1590m: veryfine% Siltstone, 15% Sandstone | C7: =IF('Input Sheet'!C9="","",CONCATENATE("Sample ", 'Input Sheet'!B9, "m: ", M7,, K7, J7, " FLUOR in SST. ", "TG ", 'Input Sheet'!I9, "U")) -> Sample 1590m: NO FLUOR in SST. TG 8U | D7: v | E7: very | G7: =IF('Input Sheet'!C9="","",100-'Input Sheet'!C9) -> 85 | H7: =SUBSTITUTE(SUBSTITUTE(SUBSTITUTE(SUBSTITUTE(SUBSTITUTE(SUBSTITUTE(SUBSTITUTE(SUBSTITUTE(SUBSTITUTE(SUBSTITUTE(SUBSTITUTE(SUBSTITUTE(SUBSTITUTE(SUBSTITUTE(SUBSTITUTE(SUBSTITUTE(SUBSTITUTE(SUBSTITUTE(SUBSTITUTE(SUBSTITUTE(SUBSTITUTE(SUBSTITUTE(SUBSTITUTE(SUBSTITUTE(SUBSTITUTE(SUBSTITUTE(SUBSTITUTE(SUBSTITUTE(SUBSTITUTE(SUBSTITUTE(SUBSTITUTE('Input Sheet'!D9,$D$3,$E$3),$D$4,$E$4),$D$5,$E$5),$D$6,$E$6),$D$7,$E$7),$D$8,$E$8),$D$9,$E$9),$D$10,$E$10),$D$11,$E$11),$D$12,$E$12),$D$13,$E$13),$D$14,$E$14),$D$15,$E$15),$D$16,$E$16),$D$17,$E$17),$D$18,$E$18),$D$19,$E$19),$D$20,$E$20),$D$21,$E$21),$D$22,$E$22),$D$23,$E$23),$D$24,$E$24),$D$25,$E$25),$D$26,$E$26),$D$27,$E$27),$D$28,$E$28),$D$29,$E$29),$D$30,$E$30),$D$31,$E$31),$D$32,$E$32),$D$33,$E$33) -> veryfine | I7: =SUBSTITUTE(H7, "veryfine", "very fine") -> very fine | J7: =SUBSTITUTE(SUBSTITUTE(SUBSTITUTE(SUBSTITUTE(SUBSTITUTE(SUBSTITUTE(SUBSTITUTE(SUBSTITUTE(SUBSTITUTE(SUBSTITUTE(SUBSTITUTE(SUBSTITUTE(SUBSTITUTE(SUBSTITUTE(SUBSTITUTE(SUBSTITUTE(SUBSTITUTE(SUBSTITUTE(SUBSTITUTE(SUBSTITUTE(SUBSTITUTE(SUBSTITUTE(SUBSTITUTE(SUBSTITUTE(SUBSTITUTE(SUBSTITUTE(SUBSTITUTE(SUBSTITUTE(SUBSTITUTE(SUBSTITUTE(SUBSTITUTE('Input Sheet'!G9,$D$3,$E$3),$D$4,$E$4),$D$5,$E$5),$D$6,$E$6),$D$7,$E$7),$D$8,$E$8),$D$9,$E$9),$D$10,$E$10),$D$11,$E$11),$D$12,$E$12),$D$13,$E$13),$D$14,$E$14),$D$15,$E$15),$D$16,$E$16),$D$17,$E$17),$D$18,$E$18),$D$19,$E$19),$D$20,$E$20),$D$21,$E$21),$D$22,$E$22),$D$23,$E$23),$D$24,$E$24),$D$25,$E$25),$D$26,$E$26),$D$27,$E$27),$D$28,$E$28),$D$29,$E$29),$D$30,$E$30),$D$31,$E$31),$D$32,$E$32),$D$33,$E$33) | K7: =IF('Input Sheet'!F9=0, "NO",CONCATENATE('Input Sheet'!F9, IF('Input Sheet'!F9>0,"% ",""))) -> NO | L7: =SUBSTITUTE(SUBSTITUTE(SUBSTITUTE(SUBSTITUTE(SUBSTITUTE(SUBSTITUTE(SUBSTITUTE(SUBSTITUTE(SUBSTITUTE(SUBSTITUTE(SUBSTITUTE(SUBSTITUTE(SUBSTITUTE(SUBSTITUTE(SUBSTITUTE(SUBSTITUTE(SUBSTITUTE(SUBSTITUTE(SUBSTITUTE(SUBSTITUTE(SUBSTITUTE(SUBSTITUTE(SUBSTITUTE(SUBSTITUTE(SUBSTITUTE(SUBSTITUTE(SUBSTITUTE(SUBSTITUTE(SUBSTITUTE(SUBSTITUTE(SUBSTITUTE('Input Sheet'!J9,$D$3,$E$3),$D$4,$E$4),$D$5,$E$5),$D$6,$E$6),$D$7,$E$7),$D$8,$E$8),$D$9,$E$9),$D$10,$E$10),$D$11,$E$11),$D$12,$E$12),$D$13,$E$13),$D$14,$E$14),$D$15,$E$15),$D$16,$E$16),$D$17,$E$17),$D$18,$E$18),$D$19,$E$19),$D$20,$E$20),$D$21,$E$21),$D$22,$E$22),$D$23,$E$23),$D$24,$E$24),$D$25,$E$25),$D$26,$E$26),$D$27,$E$27),$D$28,$E$28),$D$29,$E$29),$D$30,$E$30),$D$31,$E$31),$D$32,$E$32),$D$33,$E$33) | M7: =CONCATENATE(L7, IF('Input Sheet'!J9="",""," siderite in ")) | N7: =SUBSTITUTE(SUBSTITUTE(SUBSTITUTE(SUBSTITUTE(SUBSTITUTE(SUBSTITUTE(SUBSTITUTE(SUBSTITUTE(SUBSTITUTE(SUBSTITUTE(SUBSTITUTE(SUBSTITUTE(SUBSTITUTE(SUBSTITUTE(SUBSTITUTE(SUBSTITUTE(SUBSTITUTE(SUBSTITUTE(SUBSTITUTE(SUBSTITUTE(SUBSTITUTE(SUBSTITUTE(SUBSTITUTE(SUBSTITUTE(SUBSTITUTE(SUBSTITUTE(SUBSTITUTE(SUBSTITUTE(SUBSTITUTE(SUBSTITUTE(SUBSTITUTE('Input Sheet'!K9,$D$3,$E$3),$D$4,$E$4),$D$5,$E$5),$D$6,$E$6),$D$7,$E$7),$D$8,$E$8),$D$9,$E$9),$D$10,$E$10),$D$11,$E$11),$D$12,$E$12),$D$13,$E$13),$D$14,$E$14),$D$15,$E$15),$D$16,$E$16),$D$17,$E$17),$D$18,$E$18),$D$19,$E$19),$D$20,$E$20),$D$21,$E$21),$D$22,$E$22),$D$23,$E$23),$D$24,$E$24),$D$25,$E$25),$D$26,$E$26),$D$27,$E$27),$D$28,$E$28),$D$29,$E$29),$D$30,$E$30),$D$31,$E$31),$D$32,$E$32),$D$33,$E$33) | O7: =CONCATENATE(N7, IF('Input Sheet'!K9="",""," siderite in "))
A8: =IF('Input Sheet'!C10="","",CONCATENATE("Sample ", 'Input Sheet'!B10, "m: ", M8, G8, "% ", "Siltstone, ", O8, 'Input Sheet'!C10, "% ", I8, " Sandstone, ", K8, J8, " FLUOR in SST. ", "TG ", 'Input Sheet'!I10, "U")) -> Sample 1595m: 70% Siltstone, 30% very fine to fine Sandstone, NO FLUOR in SST. TG 9U | B8: =IF('Input Sheet'!C10="","",CONCATENATE("Sample ", 'Input Sheet'!B10, "m: ", N8, H8, "% ", "Siltstone, ", P8, 'Input Sheet'!C10, "% ", J8, " Sandstone ")) -> Sample 1595m: veryfine to fine% Siltstone, 30% Sandstone | C8: =IF('Input Sheet'!C10="","",CONCATENATE("Sample ", 'Input Sheet'!B10, "m: ", M8,, K8, J8, " FLUOR in SST. ", "TG ", 'Input Sheet'!I10, "U")) -> Sample 1595m: NO FLUOR in SST. TG 9U | D8: - | E8: to | G8: =IF('Input Sheet'!C10="","",100-'Input Sheet'!C10) -> 70 | H8: =SUBSTITUTE(SUBSTITUTE(SUBSTITUTE(SUBSTITUTE(SUBSTITUTE(SUBSTITUTE(SUBSTITUTE(SUBSTITUTE(SUBSTITUTE(SUBSTITUTE(SUBSTITUTE(SUBSTITUTE(SUBSTITUTE(SUBSTITUTE(SUBSTITUTE(SUBSTITUTE(SUBSTITUTE(SUBSTITUTE(SUBSTITUTE(SUBSTITUTE(SUBSTITUTE(SUBSTITUTE(SUBSTITUTE(SUBSTITUTE(SUBSTITUTE(SUBSTITUTE(SUBSTITUTE(SUBSTITUTE(SUBSTITUTE(SUBSTITUTE(SUBSTITUTE('Input Sheet'!D10,$D$3,$E$3),$D$4,$E$4),$D$5,$E$5),$D$6,$E$6),$D$7,$E$7),$D$8,$E$8),$D$9,$E$9),$D$10,$E$10),$D$11,$E$11),$D$12,$E$12),$D$13,$E$13),$D$14,$E$14),$D$15,$E$15),$D$16,$E$16),$D$17,$E$17),$D$18,$E$18),$D$19,$E$19),$D$20,$E$20),$D$21,$E$21),$D$22,$E$22),$D$23,$E$23),$D$24,$E$24),$D$25,$E$25),$D$26,$E$26),$D$27,$E$27),$D$28,$E$28),$D$29,$E$29),$D$30,$E$30),$D$31,$E$31),$D$32,$E$32),$D$33,$E$33) -> veryfine to fine | I8: =SUBSTITUTE(H8, "veryfine", "very fine") -> very fine to fine | J8: =SUBSTITUTE(SUBSTITUTE(SUBSTITUTE(SUBSTITUTE(SUBSTITUTE(SUBSTITUTE(SUBSTITUTE(SUBSTITUTE(SUBSTITUTE(SUBSTITUTE(SUBSTITUTE(SUBSTITUTE(SUBSTITUTE(SUBSTITUTE(SUBSTITUTE(SUBSTITUTE(SUBSTITUTE(SUBSTITUTE(SUBSTITUTE(SUBSTITUTE(SUBSTITUTE(SUBSTITUTE(SUBSTITUTE(SUBSTITUTE(SUBSTITUTE(SUBSTITUTE(SUBSTITUTE(SUBSTITUTE(SUBSTITUTE(SUBSTITUTE(SUBSTITUTE('Input Sheet'!G10,$D$3,$E$3),$D$4,$E$4),$D$5,$E$5),$D$6,$E$6),$D$7,$E$7),$D$8,$E$8),$D$9,$E$9),$D$10,$E$10),$D$11,$E$11),$D$12,$E$12),$D$13,$E$13),$D$14,$E$14),$D$15,$E$15),$D$16,$E$16),$D$17,$E$17),$D$18,$E$18),$D$19,$E$19),$D$20,$E$20),$D$21,$E$21),$D$22,$E$22),$D$23,$E$23),$D$24,$E$24),$D$25,$E$25),$D$26,$E$26),$D$27,$E$27),$D$28,$E$28),$D$29,$E$29),$D$30,$E$30),$D$31,$E$31),$D$32,$E$32),$D$33,$E$33) | K8: =IF('Input Sheet'!F10=0, "NO",CONCATENATE('Input Sheet'!F10, IF('Input Sheet'!F10>0,"% ",""))) -> NO | L8: =SUBSTITUTE(SUBSTITUTE(SUBSTITUTE(SUBSTITUTE(SUBSTITUTE(SUBSTITUTE(SUBSTITUTE(SUBSTITUTE(SUBSTITUTE(SUBSTITUTE(SUBSTITUTE(SUBSTITUTE(SUBSTITUTE(SUBSTITUTE(SUBSTITUTE(SUBSTITUTE(SUBSTITUTE(SUBSTITUTE(SUBSTITUTE(SUBSTITUTE(SUBSTITUTE(SUBSTITUTE(SUBSTITUTE(SUBSTITUTE(SUBSTITUTE(SUBSTITUTE(SUBSTITUTE(SUBSTITUTE(SUBSTITUTE(SUBSTITUTE(SUBSTITUTE('Input Sheet'!J10,$D$3,$E$3),$D$4,$E$4),$D$5,$E$5),$D$6,$E$6),$D$7,$E$7),$D$8,$E$8),$D$9,$E$9),$D$10,$E$10),$D$11,$E$11),$D$12,$E$12),$D$13,$E$13),$D$14,$E$14),$D$15,$E$15),$D$16,$E$16),$D$17,$E$17),$D$18,$E$18),$D$19,$E$19),$D$20,$E$20),$D$21,$E$21),$D$22,$E$22),$D$23,$E$23),$D$24,$E$24),$D$25,$E$25),$D$26,$E$26),$D$27,$E$27),$D$28,$E$28),$D$29,$E$29),$D$30,$E$30),$D$31,$E$31),$D$32,$E$32),$D$33,$E$33) | M8: =CONCATENATE(L8, IF('Input Sheet'!J10="",""," siderite in ")) | N8: =SUBSTITUTE(SUBSTITUTE(SUBSTITUTE(SUBSTITUTE(SUBSTITUTE(SUBSTITUTE(SUBSTITUTE(SUBSTITUTE(SUBSTITUTE(SUBSTITUTE(SUBSTITUTE(SUBSTITUTE(SUBSTITUTE(SUBSTITUTE(SUBSTITUTE(SUBSTITUTE(SUBSTITUTE(SUBSTITUTE(SUBSTITUTE(SUBSTITUTE(SUBSTITUTE(SUBSTITUTE(SUBSTITUTE(SUBSTITUTE(SUBSTITUTE(SUBSTITUTE(SUBSTITUTE(SUBSTITUTE(SUBSTITUTE(SUBSTITUTE(SUBSTITUTE('Input Sheet'!K10,$D$3,$E$3),$D$4,$E$4),$D$5,$E$5),$D$6,$E$6),$D$7,$E$7),$D$8,$E$8),$D$9,$E$9),$D$10,$E$10),$D$11,$E$11),$D$12,$E$12),$D$13,$E$13),$D$14,$E$14),$D$15,$E$15),$D$16,$E$16),$D$17,$E$17),$D$18,$E$18),$D$19,$E$19),$D$20,$E$20),$D$21,$E$21),$D$22,$E$22),$D$23,$E$23),$D$24,$E$24),$D$25,$E$25),$D$26,$E$26),$D$27,$E$27),$D$28,$E$28),$D$29,$E$29),$D$30,$E$30),$D$31,$E$31),$D$32,$E$32),$D$33,$E$33) | O8: =CONCATENATE(N8, IF('Input Sheet'!K10="",""," siderite in "))
A9: =IF('Input Sheet'!C11="","",CONCATENATE("Sample ", 'Input Sheet'!B11, "m: ", M9, G9, "% ", "Siltstone, ", O9, 'Input Sheet'!C11, "% ", I9, " Sandstone, ", K9, J9, " FLUOR in SST. ", "TG ", 'Input Sheet'!I11, "U")) -> Sample 1600m: 50% Siltstone, 50% very fine to fine Sandstone, NO FLUOR in SST. TG 11U | B9: =IF('Input Sheet'!C11="","",CONCATENATE("Sample ", 'Input Sheet'!B11, "m: ", N9, H9, "% ", "Siltstone, ", P9, 'Input Sheet'!C11, "% ", J9, " Sandstone ")) -> Sample 1600m: veryfine to fine% Siltstone, 50% Sandstone | C9: =IF('Input Sheet'!C11="","",CONCATENATE("Sample ", 'Input Sheet'!B11, "m: ", M9,, K9, J9, " FLUOR in SST. ", "TG ", 'Input Sheet'!I11, "U")) -> Sample 1600m: NO FLUOR in SST. TG 11U | D9: occ | E9: occasional | G9: =IF('Input Sheet'!C11="","",100-'Input Sheet'!C11) -> 50 | H9: =SUBSTITUTE(SUBSTITUTE(SUBSTITUTE(SUBSTITUTE(SUBSTITUTE(SUBSTITUTE(SUBSTITUTE(SUBSTITUTE(SUBSTITUTE(SUBSTITUTE(SUBSTITUTE(SUBSTITUTE(SUBSTITUTE(SUBSTITUTE(SUBSTITUTE(SUBSTITUTE(SUBSTITUTE(SUBSTITUTE(SUBSTITUTE(SUBSTITUTE(SUBSTITUTE(SUBSTITUTE(SUBSTITUTE(SUBSTITUTE(SUBSTITUTE(SUBSTITUTE(SUBSTITUTE(SUBSTITUTE(SUBSTITUTE(SUBSTITUTE(SUBSTITUTE('Input Sheet'!D11,$D$3,$E$3),$D$4,$E$4),$D$5,$E$5),$D$6,$E$6),$D$7,$E$7),$D$8,$E$8),$D$9,$E$9),$D$10,$E$10),$D$11,$E$11),$D$12,$E$12),$D$13,$E$13),$D$14,$E$14),$D$15,$E$15),$D$16,$E$16),$D$17,$E$17),$D$18,$E$18),$D$19,$E$19),$D$20,$E$20),$D$21,$E$21),$D$22,$E$22),$D$23,$E$23),$D$24,$E$24),$D$25,$E$25),$D$26,$E$26),$D$27,$E$27),$D$28,$E$28),$D$29,$E$29),$D$30,$E$30),$D$31,$E$31),$D$32,$E$32),$D$33,$E$33) -> veryfine to fine | I9: =SUBSTITUTE(H9, "veryfine", "very fine") -> very fine to fine | J9: =SUBSTITUTE(SUBSTITUTE(SUBSTITUTE(SUBSTITUTE(SUBSTITUTE(SUBSTITUTE(SUBSTITUTE(SUBSTITUTE(SUBSTITUTE(SUBSTITUTE(SUBSTITUTE(SUBSTITUTE(SUBSTITUTE(SUBSTITUTE(SUBSTITUTE(SUBSTITUTE(SUBSTITUTE(SUBSTITUTE(SUBSTITUTE(SUBSTITUTE(SUBSTITUTE(SUBSTITUTE(SUBSTITUTE(SUBSTITUTE(SUBSTITUTE(SUBSTITUTE(SUBSTITUTE(SUBSTITUTE(SUBSTITUTE(SUBSTITUTE(SUBSTITUTE('Input Sheet'!G11,$D$3,$E$3),$D$4,$E$4),$D$5,$E$5),$D$6,$E$6),$D$7,$E$7),$D$8,$E$8),$D$9,$E$9),$D$10,$E$10),$D$11,$E$11),$D$12,$E$12),$D$13,$E$13),$D$14,$E$14),$D$15,$E$15),$D$16,$E$16),$D$17,$E$17),$D$18,$E$18),$D$19,$E$19),$D$20,$E$20),$D$21,$E$21),$D$22,$E$22),$D$23,$E$23),$D$24,$E$24),$D$25,$E$25),$D$26,$E$26),$D$27,$E$27),$D$28,$E$28),$D$29,$E$29),$D$30,$E$30),$D$31,$E$31),$D$32,$E$32),$D$33,$E$33) | K9: =IF('Input Sheet'!F11=0, "NO",CONCATENATE('Input Sheet'!F11, IF('Input Sheet'!F11>0,"% ",""))) -> NO | L9: =SUBSTITUTE(SUBSTITUTE(SUBSTITUTE(SUBSTITUTE(SUBSTITUTE(SUBSTITUTE(SUBSTITUTE(SUBSTITUTE(SUBSTITUTE(SUBSTITUTE(SUBSTITUTE(SUBSTITUTE(SUBSTITUTE(SUBSTITUTE(SUBSTITUTE(SUBSTITUTE(SUBSTITUTE(SUBSTITUTE(SUBSTITUTE(SUBSTITUTE(SUBSTITUTE(SUBSTITUTE(SUBSTITUTE(SUBSTITUTE(SUBSTITUTE(SUBSTITUTE(SUBSTITUTE(SUBSTITUTE(SUBSTITUTE(SUBSTITUTE(SUBSTITUTE('Input Sheet'!J11,$D$3,$E$3),$D$4,$E$4),$D$5,$E$5),$D$6,$E$6),$D$7,$E$7),$D$8,$E$8),$D$9,$E$9),$D$10,$E$10),$D$11,$E$11),$D$12,$E$12),$D$13,$E$13),$D$14,$E$14),$D$15,$E$15),$D$16,$E$16),$D$17,$E$17),$D$18,$E$18),$D$19,$E$19),$D$20,$E$20),$D$21,$E$21),$D$22,$E$22),$D$23,$E$23),$D$24,$E$24),$D$25,$E$25),$D$26,$E$26),$D$27,$E$27),$D$28,$E$28),$D$29,$E$29),$D$30,$E$30),$D$31,$E$31),$D$32,$E$32),$D$33,$E$33) | M9: =CONCATENATE(L9, IF('Input Sheet'!J11="",""," siderite in ")) | N9: =SUBSTITUTE(SUBSTITUTE(SUBSTITUTE(SUBSTITUTE(SUBSTITUTE(SUBSTITUTE(SUBSTITUTE(SUBSTITUTE(SUBSTITUTE(SUBSTITUTE(SUBSTITUTE(SUBSTITUTE(SUBSTITUTE(SUBSTITUTE(SUBSTITUTE(SUBSTITUTE(SUBSTITUTE(SUBSTITUTE(SUBSTITUTE(SUBSTITUTE(SUBSTITUTE(SUBSTITUTE(SUBSTITUTE(SUBSTITUTE(SUBSTITUTE(SUBSTITUTE(SUBSTITUTE(SUBSTITUTE(SUBSTITUTE(SUBSTITUTE(SUBSTITUTE('Input Sheet'!K11,$D$3,$E$3),$D$4,$E$4),$D$5,$E$5),$D$6,$E$6),$D$7,$E$7),$D$8,$E$8),$D$9,$E$9),$D$10,$E$10),$D$11,$E$11),$D$12,$E$12),$D$13,$E$13),$D$14,$E$14),$D$15,$E$15),$D$16,$E$16),$D$17,$E$17),$D$18,$E$18),$D$19,$E$19),$D$20,$E$20),$D$21,$E$21),$D$22,$E$22),$D$23,$E$23),$D$24,$E$24),$D$25,$E$25),$D$26,$E$26),$D$27,$E$27),$D$28,$E$28),$D$29,$E$29),$D$30,$E$30),$D$31,$E$31),$D$32,$E$32),$D$33,$E$33) | O9: =CONCATENATE(N9, IF('Input Sheet'!K11="",""," siderite in "))
A10: =IF('Input Sheet'!C12="","",CONCATENATE("Sample ", 'Input Sheet'!B12, "m: ", M10, G10, "% ", "Siltstone, ", O10, 'Input Sheet'!C12, "% ", I10, " Sandstone, ", K10, J10, " FLUOR in SST. ", "TG ", 'Input Sheet'!I12, "U")) -> Sample 1605m: 55% Siltstone, 45% very fine to fine Sandstone, NO FLUOR in SST. TG 13U | B10: =IF('Input Sheet'!C12="","",CONCATENATE("Sample ", 'Input Sheet'!B12, "m: ", N10, H10, "% ", "Siltstone, ", P10, 'Input Sheet'!C12, "% ", J10, " Sandstone ")) -> Sample 1605m: veryfine to fine% Siltstone, 45% Sandstone | C10: =IF('Input Sheet'!C12="","",CONCATENATE("Sample ", 'Input Sheet'!B12, "m: ", M10,, K10, J10, " FLUOR in SST. ", "TG ", 'Input Sheet'!I12, "U")) -> Sample 1605m: NO FLUOR in SST. TG 13U | D10: mnr | E10: minor | G10: =IF('Input Sheet'!C12="","",100-'Input Sheet'!C12) -> 55 | H10: =SUBSTITUTE(SUBSTITUTE(SUBSTITUTE(SUBSTITUTE(SUBSTITUTE(SUBSTITUTE(SUBSTITUTE(SUBSTITUTE(SUBSTITUTE(SUBSTITUTE(SUBSTITUTE(SUBSTITUTE(SUBSTITUTE(SUBSTITUTE(SUBSTITUTE(SUBSTITUTE(SUBSTITUTE(SUBSTITUTE(SUBSTITUTE(SUBSTITUTE(SUBSTITUTE(SUBSTITUTE(SUBSTITUTE(SUBSTITUTE(SUBSTITUTE(SUBSTITUTE(SUBSTITUTE(SUBSTITUTE(SUBSTITUTE(SUBSTITUTE(SUBSTITUTE('Input Sheet'!D12,$D$3,$E$3),$D$4,$E$4),$D$5,$E$5),$D$6,$E$6),$D$7,$E$7),$D$8,$E$8),$D$9,$E$9),$D$10,$E$10),$D$11,$E$11),$D$12,$E$12),$D$13,$E$13),$D$14,$E$14),$D$15,$E$15),$D$16,$E$16),$D$17,$E$17),$D$18,$E$18),$D$19,$E$19),$D$20,$E$20),$D$21,$E$21),$D$22,$E$22),$D$23,$E$23),$D$24,$E$24),$D$25,$E$25),$D$26,$E$26),$D$27,$E$27),$D$28,$E$28),$D$29,$E$29),$D$30,$E$30),$D$31,$E$31),$D$32,$E$32),$D$33,$E$33) -> veryfine to fine | I10: =SUBSTITUTE(H10, "veryfine", "very fine") -> very fine to fine | J10: =SUBSTITUTE(SUBSTITUTE(SUBSTITUTE(SUBSTITUTE(SUBSTITUTE(SUBSTITUTE(SUBSTITUTE(SUBSTITUTE(SUBSTITUTE(SUBSTITUTE(SUBSTITUTE(SUBSTITUTE(SUBSTITUTE(SUBSTITUTE(SUBSTITUTE(SUBSTITUTE(SUBSTITUTE(SUBSTITUTE(SUBSTITUTE(SUBSTITUTE(SUBSTITUTE(SUBSTITUTE(SUBSTITUTE(SUBSTITUTE(SUBSTITUTE(SUBSTITUTE(SUBSTITUTE(SUBSTITUTE(SUBSTITUTE(SUBSTITUTE(SUBSTITUTE('Input Sheet'!G12,$D$3,$E$3),$D$4,$E$4),$D$5,$E$5),$D$6,$E$6),$D$7,$E$7),$D$8,$E$8),$D$9,$E$9),$D$10,$E$10),$D$11,$E$11),$D$12,$E$12),$D$13,$E$13),$D$14,$E$14),$D$15,$E$15),$D$16,$E$16),$D$17,$E$17),$D$18,$E$18),$D$19,$E$19),$D$20,$E$20),$D$21,$E$21),$D$22,$E$22),$D$23,$E$23),$D$24,$E$24),$D$25,$E$25),$D$26,$E$26),$D$27,$E$27),$D$28,$E$28),$D$29,$E$29),$D$30,$E$30),$D$31,$E$31),$D$32,$E$32),$D$33,$E$33) | K10: =IF('Input Sheet'!F12=0, "NO",CONCATENATE('Input Sheet'!F12, IF('Input Sheet'!F12>0,"% ",""))) -> NO | L10: =SUBSTITUTE(SUBSTITUTE(SUBSTITUTE(SUBSTITUTE(SUBSTITUTE(SUBSTITUTE(SUBSTITUTE(SUBSTITUTE(SUBSTITUTE(SUBSTITUTE(SUBSTITUTE(SUBSTITUTE(SUBSTITUTE(SUBSTITUTE(SUBSTITUTE(SUBSTITUTE(SUBSTITUTE(SUBSTITUTE(SUBSTITUTE(SUBSTITUTE(SUBSTITUTE(SUBSTITUTE(SUBSTITUTE(SUBSTITUTE(SUBSTITUTE(SUBSTITUTE(SUBSTITUTE(SUBSTITUTE(SUBSTITUTE(SUBSTITUTE(SUBSTITUTE('Input Sheet'!J12,$D$3,$E$3),$D$4,$E$4),$D$5,$E$5),$D$6,$E$6),$D$7,$E$7),$D$8,$E$8),$D$9,$E$9),$D$10,$E$10),$D$11,$E$11),$D$12,$E$12),$D$13,$E$13),$D$14,$E$14),$D$15,$E$15),$D$16,$E$16),$D$17,$E$17),$D$18,$E$18),$D$19,$E$19),$D$20,$E$20),$D$21,$E$21),$D$22,$E$22),$D$23,$E$23),$D$24,$E$24),$D$25,$E$25),$D$26,$E$26),$D$27,$E$27),$D$28,$E$28),$D$29,$E$29),$D$30,$E$30),$D$31,$E$31),$D$32,$E$32),$D$33,$E$33) | M10: =CONCATENATE(L10, IF('Input Sheet'!J12="",""," siderite in ")) | N10: =SUBSTITUTE(SUBSTITUTE(SUBSTITUTE(SUBSTITUTE(SUBSTITUTE(SUBSTITUTE(SUBSTITUTE(SUBSTITUTE(SUBSTITUTE(SUBSTITUTE(SUBSTITUTE(SUBSTITUTE(SUBSTITUTE(SUBSTITUTE(SUBSTITUTE(SUBSTITUTE(SUBSTITUTE(SUBSTITUTE(SUBSTITUTE(SUBSTITUTE(SUBSTITUTE(SUBSTITUTE(SUBSTITUTE(SUBSTITUTE(SUBSTITUTE(SUBSTITUTE(SUBSTITUTE(SUBSTITUTE(SUBSTITUTE(SUBSTITUTE(SUBSTITUTE('Input Sheet'!K12,$D$3,$E$3),$D$4,$E$4),$D$5,$E$5),$D$6,$E$6),$D$7,$E$7),$D$8,$E$8),$D$9,$E$9),$D$10,$E$10),$D$11,$E$11),$D$12,$E$12),$D$13,$E$13),$D$14,$E$14),$D$15,$E$15),$D$16,$E$16),$D$17,$E$17),$D$18,$E$18),$D$19,$E$19),$D$20,$E$20),$D$21,$E$21),$D$22,$E$22),$D$23,$E$23),$D$24,$E$24),$D$25,$E$25),$D$26,$E$26),$D$27,$E$27),$D$28,$E$28),$D$29,$E$29),$D$30,$E$30),$D$31,$E$31),$D$32,$E$32),$D$33,$E$33) | O10: =CONCATENATE(N10, IF('Input Sheet'!K12="",""," siderite in "))
A11: =IF('Input Sheet'!C13="","",CONCATENATE("Sample ", 'Input Sheet'!B13, "m: ", M11, G11, "% ", "Siltstone, ", O11, 'Input Sheet'!C13, "% ", I11, " Sandstone, ", K11, J11, " FLUOR in SST. ", "TG ", 'Input Sheet'!I13, "U")) -> Sample 1610m: 55% Siltstone, 45% very fine to fine Sandstone, NO FLUOR in SST. TG 9U | B11: =IF('Input Sheet'!C13="","",CONCATENATE("Sample ", 'Input Sheet'!B13, "m: ", N11, H11, "% ", "Siltstone, ", P11, 'Input Sheet'!C13, "% ", J11, " Sandstone ")) -> Sample 1610m: veryfine to fine% Siltstone, 45% Sandstone | C11: =IF('Input Sheet'!C13="","",CONCATENATE("Sample ", 'Input Sheet'!B13, "m: ", M11,, K11, J11, " FLUOR in SST. ", "TG ", 'Input Sheet'!I13, "U")) -> Sample 1610m: NO FLUOR in SST. TG 9U | D11: rr | E11: rare | G11: =IF('Input Sheet'!C13="","",100-'Input Sheet'!C13) -> 55 | H11: =SUBSTITUTE(SUBSTITUTE(SUBSTITUTE(SUBSTITUTE(SUBSTITUTE(SUBSTITUTE(SUBSTITUTE(SUBSTITUTE(SUBSTITUTE(SUBSTITUTE(SUBSTITUTE(SUBSTITUTE(SUBSTITUTE(SUBSTITUTE(SUBSTITUTE(SUBSTITUTE(SUBSTITUTE(SUBSTITUTE(SUBSTITUTE(SUBSTITUTE(SUBSTITUTE(SUBSTITUTE(SUBSTITUTE(SUBSTITUTE(SUBSTITUTE(SUBSTITUTE(SUBSTITUTE(SUBSTITUTE(SUBSTITUTE(SUBSTITUTE(SUBSTITUTE('Input Sheet'!D13,$D$3,$E$3),$D$4,$E$4),$D$5,$E$5),$D$6,$E$6),$D$7,$E$7),$D$8,$E$8),$D$9,$E$9),$D$10,$E$10),$D$11,$E$11),$D$12,$E$12),$D$13,$E$13),$D$14,$E$14),$D$15,$E$15),$D$16,$E$16),$D$17,$E$17),$D$18,$E$18),$D$19,$E$19),$D$20,$E$20),$D$21,$E$21),$D$22,$E$22),$D$23,$E$23),$D$24,$E$24),$D$25,$E$25),$D$26,$E$26),$D$27,$E$27),$D$28,$E$28),$D$29,$E$29),$D$30,$E$30),$D$31,$E$31),$D$32,$E$32),$D$33,$E$33) -> veryfine to fine | I11: =SUBSTITUTE(H11, "veryfine", "very fine") -> very fine to fine | J11: =SUBSTITUTE(SUBSTITUTE(SUBSTITUTE(SUBSTITUTE(SUBSTITUTE(SUBSTITUTE(SUBSTITUTE(SUBSTITUTE(SUBSTITUTE(SUBSTITUTE(SUBSTITUTE(SUBSTITUTE(SUBSTITUTE(SUBSTITUTE(SUBSTITUTE(SUBSTITUTE(SUBSTITUTE(SUBSTITUTE(SUBSTITUTE(SUBSTITUTE(SUBSTITUTE(SUBSTITUTE(SUBSTITUTE(SUBSTITUTE(SUBSTITUTE(SUBSTITUTE(SUBSTITUTE(SUBSTITUTE(SUBSTITUTE(SUBSTITUTE(SUBSTITUTE('Input Sheet'!G13,$D$3,$E$3),$D$4,$E$4),$D$5,$E$5),$D$6,$E$6),$D$7,$E$7),$D$8,$E$8),$D$9,$E$9),$D$10,$E$10),$D$11,$E$11),$D$12,$E$12),$D$13,$E$13),$D$14,$E$14),$D$15,$E$15),$D$16,$E$16),$D$17,$E$17),$D$18,$E$18),$D$19,$E$19),$D$20,$E$20),$D$21,$E$21),$D$22,$E$22),$D$23,$E$23),$D$24,$E$24),$D$25,$E$25),$D$26,$E$26),$D$27,$E$27),$D$28,$E$28),$D$29,$E$29),$D$30,$E$30),$D$31,$E$31),$D$32,$E$32),$D$33,$E$33) | K11: =IF('Input Sheet'!F13=0, "NO",CONCATENATE('Input Sheet'!F13, IF('Input Sheet'!F13>0,"% ",""))) -> NO | L11: =SUBSTITUTE(SUBSTITUTE(SUBSTITUTE(SUBSTITUTE(SUBSTITUTE(SUBSTITUTE(SUBSTITUTE(SUBSTITUTE(SUBSTITUTE(SUBSTITUTE(SUBSTITUTE(SUBSTITUTE(SUBSTITUTE(SUBSTITUTE(SUBSTITUTE(SUBSTITUTE(SUBSTITUTE(SUBSTITUTE(SUBSTITUTE(SUBSTITUTE(SUBSTITUTE(SUBSTITUTE(SUBSTITUTE(SUBSTITUTE(SUBSTITUTE(SUBSTITUTE(SUBSTITUTE(SUBSTITUTE(SUBSTITUTE(SUBSTITUTE(SUBSTITUTE('Input Sheet'!J13,$D$3,$E$3),$D$4,$E$4),$D$5,$E$5),$D$6,$E$6),$D$7,$E$7),$D$8,$E$8),$D$9,$E$9),$D$10,$E$10),$D$11,$E$11),$D$12,$E$12),$D$13,$E$13),$D$14,$E$14),$D$15,$E$15),$D$16,$E$16),$D$17,$E$17),$D$18,$E$18),$D$19,$E$19),$D$20,$E$20),$D$21,$E$21),$D$22,$E$22),$D$23,$E$23),$D$24,$E$24),$D$25,$E$25),$D$26,$E$26),$D$27,$E$27),$D$28,$E$28),$D$29,$E$29),$D$30,$E$30),$D$31,$E$31),$D$32,$E$32),$D$33,$E$33) | M11: =CONCATENATE(L11, IF('Input Sheet'!J13="",""," siderite in ")) | N11: =SUBSTITUTE(SUBSTITUTE(SUBSTITUTE(SUBSTITUTE(SUBSTITUTE(SUBSTITUTE(SUBSTITUTE(SUBSTITUTE(SUBSTITUTE(SUBSTITUTE(SUBSTITUTE(SUBSTITUTE(SUBSTITUTE(SUBSTITUTE(SUBSTITUTE(SUBSTITUTE(SUBSTITUTE(SUBSTITUTE(SUBSTITUTE(SUBSTITUTE(SUBSTITUTE(SUBSTITUTE(SUBSTITUTE(SUBSTITUTE(SUBSTITUTE(SUBSTITUTE(SUBSTITUTE(SUBSTITUTE(SUBSTITUTE(SUBSTITUTE(SUBSTITUTE('Input Sheet'!K13,$D$3,$E$3),$D$4,$E$4),$D$5,$E$5),$D$6,$E$6),$D$7,$E$7),$D$8,$E$8),$D$9,$E$9),$D$10,$E$10),$D$11,$E$11),$D$12,$E$12),$D$13,$E$13),$D$14,$E$14),$D$15,$E$15),$D$16,$E$16),$D$17,$E$17),$D$18,$E$18),$D$19,$E$19),$D$20,$E$20),$D$21,$E$21),$D$22,$E$22),$D$23,$E$23),$D$24,$E$24),$D$25,$E$25),$D$26,$E$26),$D$27,$E$27),$D$28,$E$28),$D$29,$E$29),$D$30,$E$30),$D$31,$E$31),$D$32,$E$32),$D$33,$E$33) | O11: =CONCATENATE(N11, IF('Input Sheet'!K13="",""," siderite in "))
