Workbook

Sheet Example Sheet
B1: Sample Descriptions
B3: Depth (mMD) | C3: % Sandstone | D3: Grain Size | E3: Max Grain Size | F3: % Fluor | G3: Brightness | H3: Gas (U) | I3: FeCO3 in SLTST | J3: FeCO3 in SST | K3: Date | L3: Time | O3: Short Hand
B4: 1596 | C4: 50 | D4: vf-f | E4: F | H4: 5 | I4: mnr | K4: 45161 | L4: 0.54166667 | O4: f | P4: fine
B5: 1599 | C5: 60 | D5: vf-f, tr med | E5: M | H5: 5 | I5: mnr | K5: 45161 | L5: 0.54861111 | O5: med | P5: medium
B6: 1602 | C6: 65 | D6: vf-f | E6: F | H6: 5 | I6: mnr | K6: 45161 | L6: 0.55208333 | O6: crs | P6: coarse
B7: 1605 | C7: 50 | D7: vf, occ f | E7: F | H7: 6 | I7: tr | K7: 45161 | L7: 0.5625 | O7: v | P7: very
B8: 1608 | C8: 30 | D8: vf-f | E8: F | H8: 7 | I8: tr | J8: tr | K8: 45161 | L8: 0.58333333 | O8: - | P8: to
B9: 1611 | C9: 40 | D9: vf-f | E9: F | F9: Tr | H9: 7 | I9: tr | J9: tr | K9: 45161 | L9: 0.60416667 | O9: occ | P9: occasional
B10: 1614 | C10: 60 | D10: vf-f | E10: F | F10: 10 | G10: pl-mod bri | H10: 8 | I10: tr | K10: 45161 | L10: 0.625 | O10: mnr | P10: minor
B11: 1617 | C11: 40 | D11: vf-f | E11: F | F11: Tr | G11: pl-mod bri | H11: 7 | I11: tr | J11: mnr | K11: 45161 | L11: 0.64583333 | O11: rr | P11: rare
B12: 1620 | C12: 30 | D12: vf-f | E12: F | F12: 10 | G12: pl-mod bri | H12: 7 | I12: mnr | J12: mnr | K12: 45161 | L12: 0.66666667 | O12: tr | P12: trace
B13: 1623 | C13: 30 | D13: vff-f | E13: F | F13: 10 | G13: pl-mod bri | H13: 5 | I13: mnr | J13: tr | K13: 45161 | L13: 0.6875 | O13: mod | P13: moderately
B14: 1626 | C14: 80 | D14: vf-med, tr crs-v crs | E14: C | F14: 80 | G14: mod bri | H14: 77 | I14: tr | K14: 45161 | L14: 0.70833333 | O14: bri | P14: bright
B15: 1629 | C15: 90 | D15: f-med, tr crs-v crs | E15: C | F15: 100 | G15: mod bri-bri | H15: 100 | K15: 45161 | L15: 0.72916667 | O15: dll | P15: dull
B16: 1632 | C16: 95 | D16: f-med, tr crs-v crs | E16: C | F16: 100 | G16: mod bri-bri | H16: 94 | K16: 45161 | L16: 0.75 | O16: com | P16: common
B17: 1635 | C17: 100 | D17: f-med,tr crs | E17: C | F17: 100 | G17: mod bri-bri | H17: 102 | K17: 45161 | L17: 0.77083333 | O17: i/p | P17: in part
O18: dom | P18: dominantly
O19: pl | P19: pale

Sheet Input Sheet
B1: Sample Descriptions
B3: Depth (mMD) | C3: % Sandstone | D3: Grain Size | E3: Max Grain Size | F3: % Fluor | G3: Brightness | H3: Brightness Code | I3: Gas (U) | J3: FeCO3 in SLTST | K3: FeCO3 in SST | L3: Date | M3: Time | P3: Short Hand | S3: Brightness
A4: Stimpee 6_OP | B4: 1545 | C4: 30 | D4: vf | E4: VF | H4: =_xlfn.XLOOKUP(G4,$S$4:$S$9,$T$4:$T$9,"",0,1) | I4: 4 | J4: Tr | L4: 45194 | M4: 0.10416667 | P4: f | Q4: fine | S4: bri | T4: 3 | U4: =IF(C4="","",IF(OR(L4="",AND(ISNUMBER(U4),C4=U4)),U4,C4)) -> 0 | V4: =IF(C4="","",IF(OR(M4="",AND(ISNUMBER(V4),C4=V4)),V4,C4)) -> 0
A5: Stimpee 6_OP | B5: 1550 | C5: 20 | D5: vf-f | E5: F | H5: =_xlfn.XLOOKUP(G5,$S$4:$S$9,$T$4:$T$9,"",0,1) | I5: 6 | J5: Tr | L5: 45194 | P5: med | Q5: medium | S5: mod bri - bri | T5: 2.5 | U5: =IF(C5="","",IF(OR(L5="",AND(ISNUMBER(U5),C5=U5)),U5,C5)) -> 0 | V5: =IF(C5="","",IF(OR(M5="",AND(ISNUMBER(V5),C5=V5)),V5,C5)) -> 0
A6: Stimpee 6_OP | B6: 1555 | C6: 20 | D6: vf-f | E6: F | H6: =_xlfn.XLOOKUP(G6,$S$4:$S$9,$T$4:$T$9,"",0,1) | I6: 5 | J6: Tr | L6: 45194 | P6: crs | Q6: coarse | S6: mod bri | T6: 2 | U6: =IF(C6="","",IF(OR(L6="",AND(ISNUMBER(U6),C6=U6)),U6,C6)) -> 0 | V6: =IF(C6="","",IF(OR(M6="",AND(ISNUMBER(V6),C6=V6)),V6,C6)) -> 0
A7: Stimpee 6_OP | B7: 1560 | C7: 30 | D7: vf-f | E7: F | H7: =_xlfn.XLOOKUP(G7,$S$4:$S$9,$T$4:$T$9,"",0,1) | I7: 6 | J7: Tr | L7: 45194 | P7: v | Q7: very | S7: dll - bri | T7: 1.5 | U7: =IF(C7="","",IF(OR(L7="",AND(ISNUMBER(U7),C7=U7)),U7,C7)) -> 0 | V7: =IF(C7="","",IF(OR(M7="",AND(ISNUMBER(V7),C7=V7)),V7,C7)) -> 0
A8: Stimpee 6_OP | B8: 1565 | C8: 20 | D8: vf-f | E8: F | H8: =_xlfn.XLOOKUP(G8,$S$4:$S$9,$T$4:$T$9,"",0,1) | I8: 7 | J8: Tr | L8: 45194 | P8: - | Q8: to | S8: dll - mod bri | T8: 1 | U8: =IF(C8="","",IF(OR(L8="",AND(ISNUMBER(U8),C8=U8)),U8,C8)) -> 0 | V8: =IF(C8="","",IF(OR(M8="",AND(ISNUMBER(V8),C8=V8)),V8,C8)) -> 0
A9: Stimpee 6_OP | B9: 1570 | C9: 30 | D9: vf-f | E9: F | H9: =_xlfn.XLOOKUP(G9,$S$4:$S$9,$T$4:$T$9,"",0,1) | I9: 6 | J9: Tr | L9: 45194 | P9: occ | Q9: occasional | S9: dll | T9: 0.5 | U9: =IF(C9="","",IF(OR(L9="",AND(ISNUMBER(U9),C9=U9)),U9,C9)) -> 0 | V9: =IF(C9="","",IF(OR(M9="",AND(ISNUMBER(V9),C9=V9)),V9,C9)) -> 0
A10: Stimpee 6_OP | B10: 1575 | C10: 25 | D10: vf-f | E10: F | H10: =_xlfn.XLOOKUP(G10,$S$4:$S$9,$T$4:$T$9,"",0,1) | I10: 7 | J10: Tr | L10: 45194 | P10: mnr | Q10: minor | U10: =IF(C10="","",IF(OR(L10="",AND(ISNUMBER(U10),C10=U10)),U10,C10)) -> 0 | V10: =IF(C10="","",IF(OR(M10="",AND(ISNUMBER(V10),C10=V10)),V10,C10)) -> 0
A11: Stimpee 6_OP | B11: 1580 | C11: 20 | D11: vf-f | E11: F | H11: =_xlfn.XLOOKUP(G11,$S$4:$S$9,$T$4:$T$9,"",0,1) | I11: 7 | J11: Tr | L11: 45194 | P11: rr | Q11: rare | U11: =IF(C11="","",IF(OR(L11="",AND(ISNUMBER(U11),C11=U11)),U11,C11)) -> 0 | V11: =IF(C11="","",IF(OR(M11="",AND(ISNUMBER(V11),C11=V11)),V11,C11)) -> 0
A12: Stimpee 6_OP | B12: 1585 | C12: 20 | D12: vf-f | E12: F | H12: =_xlfn.XLOOKUP(G12,$S$4:$S$9,$T$4:$T$9,"",0,1) | I12: 8 | J12: Tr | L12: 45194 | P12: tr | Q12: trace | U12: =IF(C12="","",IF(OR(L12="",AND(ISNUMBER(U12),C12=U12)),U12,C12)) -> 0 | V12: =IF(C12="","",IF(OR(M12="",AND(ISNUMBER(V12),C12=V12)),V12,C12)) -> 0
A13: Stimpee 6_OP | B13: 1590 | C13: 20 | D13: vf-f | E13: F | H13: =_xlfn.XLOOKUP(G13,$S$4:$S$9,$T$4:$T$9,"",0,1) | I13: 7 | J13: Tr | L13: 45194 | P13: mod | Q13: moderately | U13: =IF(C13="","",IF(OR(L13="",AND(ISNUMBER(U13),C13=U13)),U13,C13)) -> 0 | V13: =IF(C13="","",IF(OR(M13="",AND(ISNUMBER(V13),C13=V13)),V13,C13)) -> 0
A14: Stimpee 6_OP | B14: 1595 | C14: 40 | D14: vf-f | E14: F | H14: =_xlfn.XLOOKUP(G14,$S$4:$S$9,$T$4:$T$9,"",0,1) | I14: 5 | J14: Tr | L14: 45194 | M14: 0.24166667 | P14: bri | Q14: bright | U14: =IF(C14="","",IF(OR(L14="",AND(ISNUMBER(U14),C14=U14)),U14,C14)) -> 0 | V14: =IF(C14="","",IF(OR(M14="",AND(ISNUMBER(V14),C14=V14)),V14,C14)) -> 0
A15: Stimpee 6_OP | B15: 1600 | C15: 30 | D15: vf-f | E15: F | H15: =_xlfn.XLOOKUP(G15,$S$4:$S$9,$T$4:$T$9,"",0,1) | I15: 5 | L15: 45194 | M15: 0.25416667 | P15: dll | Q15: dull | U15: =IF(C15="","",IF(OR(L15="",AND(ISNUMBER(U15),C15=U15)),U15,C15)) -> 0 | V15: =IF(C15="","",IF(OR(M15="",AND(ISNUMBER(V15),C15=V15)),V15,C15)) -> 0
A16: Stimpee 6_OP | B16: 1605 | C16: 30 | D16: vf-f | E16: F | H16: =_xlfn.XLOOKUP(G16,$S$4:$S$9,$T$4:$T$9,"",0,1) | I16: 5 | L16: 45194 | M16: 0.26527778 | P16: com | Q16: common | U16: =IF(C16="","",IF(OR(L16="",AND(ISNUMBER(U16),C16=U16)),U16,C16)) -> 0 | V16: =IF(C16="","",IF(OR(M16="",AND(ISNUMBER(V16),C16=V16)),V16,C16)) -> 0
A17: Stimpee 6_OP | B17: 1607 | C17: 50 | D17: vf-f | E17: F | F17: 50 | G17: mod bri - bri | H17: =_xlfn.XLOOKUP(G17,$S$4:$S$9,$T$4:$T$9,"",0,1) -> 2.5 | I17: 13 | L17: 45194 | M17: 0.26736111 | P17: i/p | Q17: in part | U17: =IF(C17="","",IF(OR(L17="",AND(ISNUMBER(U17),C17=U17)),U17,C17)) | V17: =IF(C17="","",IF(OR(M17="",AND(ISNUMBER(V17),C17=V17)),V17,C17))
A18: Stimpee 6_OP | B18: 1610 | C18: 50 | D18: vf-med | E18: M | F18: 30 | G18: mod bri - bri | H18: =_xlfn.XLOOKUP(G18,$S$4:$S$9,$T$4:$T$9,"",0,1) -> 2.5 | I18: 24 | L18: 45194 | M18: 0.28125 | P18: dom | Q18: dominantly | U18: =IF(C18="","",IF(OR(L18="",AND(ISNUMBER(U18),C18=U18)),U18,C18)) | V18: =IF(C18="","",IF(OR(M18="",AND(ISNUMBER(V18),C18=V18)),V18,C18))
A19: Stimpee 6_OP | B19: 1615 | C19: 40 | D19: vf-f | E19: F | F19: 40 | G19: mod bri - bri | H19: =_xlfn.XLOOKUP(G19,$S$4:$S$9,$T$4:$T$9,"",0,1) -> 2.5 | I19: 15 | L19: 45194 | M19: 0.30416667 | P19: pl | Q19: pale | U19: =IF(C19="","",IF(OR(L19="",AND(ISNUMBER(U19),C19=U19)),U19,C19)) | V19: =IF(C19="","",IF(OR(M19="",AND(ISNUMBER(V19),C19=V19)),V19,C19))
A20: Stimpee 6_OP | B20: 1620 | C20: 60 | D20: vf-med | E20: M | F20: 50 | G20: dll - bri | H20: =_xlfn.XLOOKUP(G20,$S$4:$S$9,$T$4:$T$9,"",0,1) -> 1.5 | I20: 32 | J20: Tr | L20: 45194 | M20: 0.31597222 | U20: =IF(C20="","",IF(OR(L20="",AND(ISNUMBER(U20),C20=U20)),U20,C20)) | V20: =IF(C20="","",IF(OR(M20="",AND(ISNUMBER(V20),C20=V20)),V20,C20))
A21: Stimpee 6_OP | B21: 1625 | C21: 50 | D21: vf-med | E21: M | F21: 30 | G21: dll - bri | H21: =_xlfn.XLOOKUP(G21,$S$4:$S$9,$T$4:$T$9,"",0,1) -> 1.5 | I21: 50 | J21: Mnr | K21: Mnr | L21: 45194 | M21: 0.325 | U21: =IF(C21="","",IF(OR(L21="",AND(ISNUMBER(U21),C21=U21)),U21,C21)) | V21: =IF(C21="","",IF(OR(M21="",AND(ISNUMBER(V21),C21=V21)),V21,C21))
A22: Stimpee 6_OP | B22: 1630 | C22: 50 | D22: vf-med | E22: M | F22: 20 | G22: dll - bri | H22: =_xlfn.XLOOKUP(G22,$S$4:$S$9,$T$4:$T$9,"",0,1) -> 1.5 | I22: 20 | J22: Mnr | K22: Mnr | L22: 45194 | M22: 0.33888889 | U22: =IF(C22="","",IF(OR(L22="",AND(ISNUMBER(U22),C22=U22)),U22,C22)) | V22: =IF(C22="","",IF(OR(M22="",AND(ISNUMBER(V22),C22=V22)),V22,C22))
A23: Stimpee 6_OP | B23: 1635 | C23: 70 | D23: vf-med | E23: M | F23: 60 | G23: dll - bri | H23: =_xlfn.XLOOKUP(G23,$S$4:$S$9,$T$4:$T$9,"",0,1) -> 1.5 | I23: 250 | J23: Tr | K23: Tr | L23: 45194 | M23: 0.35763889 | U23: =IF(C23="","",IF(OR(L23="",AND(ISNUMBER(U23),C23=U23)),U23,C23)) | V23: =IF(C23="","",IF(OR(M23="",AND(ISNUMBER(V23),C23=V23)),V23,C23))
A24: Stimpee 6_OP | B24: 1640 | C24: 90 | D24: f-med | E24: M | F24: 100 | G24: mod bri - bri | H24: =_xlfn.XLOOKUP(G24,$S$4:$S$9,$T$4:$T$9,"",0,1) -> 2.5 | I24: 255 | K24: Tr | L24: 45194 | M24: 0.37152778 | U24: =IF(C24="","",IF(OR(L24="",AND(ISNUMBER(U24),C24=U24)),U24,C24)) | V24: =IF(C24="","",IF(OR(M24="",AND(ISNUMBER(V24),C24=V24)),V24,C24))
A25: Stimpee 6_OP | B25: 1645 | C25: 100 | D25: f-med, rr crs | E25: C | F25: 100 | G25: mod bri - bri | H25: =_xlfn.XLOOKUP(G25,$S$4:$S$9,$T$4:$T$9,"",0,1) -> 2.5 | I25: 267 | K25: Tr | L25: 45194 | M25: 0.38055556 | U25: =IF(C25="","",IF(OR(L25="",AND(ISNUMBER(U25),C25=U25)),U25,C25)) | V25: =IF(C25="","",IF(OR(M25="",AND(ISNUMBER(V25),C25=V25)),V25,C25))
A26: Stimpee 6_OP | B26: 1650 | C26: 95 | D26: f-crs | E26: C | F26: 100 | G26: bri | H26: =_xlfn.XLOOKUP(G26,$S$4:$S$9,$T$4:$T$9,"",0,1) -> 3 | I26: 224 | L26: 45194 | M26: 0.39236111 | U26: =IF(C26="","",IF(OR(L26="",AND(ISNUMBER(U26),C26=U26)),U26,C26)) | V26: =IF(C26="","",IF(OR(M26="",AND(ISNUMBER(V26),C26=V26)),V26,C26))
A27: Stimpee 6_OP | B27: 1655 | C27: 100 | D27: f-crs | E27: C | F27: 100 | G27: bri | H27: =_xlfn.XLOOKUP(G27,$S$4:$S$9,$T$4:$T$9,"",0,1) -> 3 | I27: 235 | K27: Tr | L27: 45194 | M27: 0.40763889 | U27: =IF(C27="","",IF(OR(L27="",AND(ISNUMBER(U27),C27=U27)),U27,C27)) | V27: =IF(C27="","",IF(OR(M27="",AND(ISNUMBER(V27),C27=V27)),V27,C27))
A28: Stimpee 6_OP | B28: 1660 | C28: 100 | D28: dom f-med, rr crs | E28: =IF(ISNUMBER(SEARCH("v crs",D28))=TRUE,"VC",IF(ISNUMBER(SEARCH("crs",D28))=TRUE,"C",IF(ISNUMBER(SEARCH("med",D28))=TRUE,"M",IF(ISNUMBER(SEARCH("vf",D28))=TRUE,"VF",IF(ISNUMBER(SEARCH("f",D28))=TRUE,"F",""))))) -> C | F28: 100 | G28: bri | H28: =_xlfn.XLOOKUP(G28,$S$4:$S$9,$T$4:$T$9,"",0,1) -> 3 | I28: 185 | K28: rr | L28: 45194 | M28: 0.42013889 | U28: =IF(C28="","",IF(OR(L28="",AND(ISNUMBER(U28),C28=U28)),U28,C28)) | V28: =IF(C28="","",IF(OR(M28="",AND(ISNUMBER(V28),C28=V28)),V28,C28))
A29: Stimpee 6_OP | B29: 1665 | C29: 95 | D29: vf-med, rr crs | E29: C | F29: 100 | G29: bri | H29: =_xlfn.XLOOKUP(G29,$S$4:$S$9,$T$4:$T$9,"",0,1) -> 3 | I29: 179 | K29: rr | L29: 45194 | M29: 0.43402778 | U29: =IF(C29="","",IF(OR(L29="",AND(ISNUMBER(U29),C29=U29)),U29,C29)) | V29: =IF(C29="","",IF(OR(M29="",AND(ISNUMBER(V29),C29=V29)),V29,C29))
A30: Stimpee 6_OP | B30: 1670 | C30: 100 | D30: vf-crs | E30: =IF(ISNUMBER(SEARCH("v crs",D30))=TRUE,"VC",IF(ISNUMBER(SEARCH("crs",D30))=TRUE,"C",IF(ISNUMBER(SEARCH("med",D30))=TRUE,"M",IF(ISNUMBER(SEARCH("vf",D30))=TRUE,"VF",IF(ISNUMBER(SEARCH("f",D30))=TRUE,"F",""))))) -> C | F30: 100 | G30: bri | H30: =_xlfn.XLOOKUP(G30,$S$4:$S$9,$T$4:$T$9,"",0,1) -> 3 | I30: 218 | K30: rr | L30: 45194 | M30: 0.44375 | U30: =IF(C30="","",IF(OR(L30="",AND(ISNUMBER(U30),C30=U30)),U30,C30)) | V30: =IF(C30="","",IF(OR(M30="",AND(ISNUMBER(V30),C30=V30)),V30,C30))
A31: Stimpee 6_OP | B31: 1675 | C31: 100 | D31: vf-crs | E31: =IF(ISNUMBER(SEARCH("v crs",D31))=TRUE,"VC",IF(ISNUMBER(SEARCH("crs",D31))=TRUE,"C",IF(ISNUMBER(SEARCH("med",D31))=TRUE,"M",IF(ISNUMBER(SEARCH("vf",D31))=TRUE,"VF",IF(ISNUMBER(SEARCH("f",D31))=TRUE,"F",""))))) -> C | F31: 100 | G31: mod bri - bri | H31: =_xlfn.XLOOKUP(G31,$S$4:$S$9,$T$4:$T$9,"",0,1) -> 2.5 | I31: 378 | K31: rr | L31: 45194 | M31: 0.45486111 | U31: =IF(C31="","",IF(OR(L31="",AND(ISNUMBER(U31),C31=U31)),U31,C31)) | V31: =IF(C31="","",IF(OR(M31="",AND(ISNUMBER(V31),C31=V31)),V31,C31))
A32: Stimpee 6_OP | B32: 1680 | C32: 100 | D32: f-crs | E32: =IF(ISNUMBER(SEARCH("v crs",D32))=TRUE,"VC",IF(ISNUMBER(SEARCH("crs",D32))=TRUE,"C",IF(ISNUMBER(SEARCH("med",D32))=TRUE,"M",IF(ISNUMBER(SEARCH("vf",D32))=TRUE,"VF",IF(ISNUMBER(SEARCH("f",D32))=TRUE,"F",""))))) -> C | F32: 100 | G32: mod bri - bri | H32: =_xlfn.XLOOKUP(G32,$S$4:$S$9,$T$4:$T$9,"",0,1) -> 2.5 | I32: 370 | K32: rr | L32: 45194 | M32: 0.46388889 | U32: =IF(C32="","",IF(OR(L32="",AND(ISNUMBER(U32),C32=U32)),U32,C32)) | V32: =IF(C32="","",IF(OR(M32="",AND(ISNUMBER(V32),C32=V32)),V32,C32))
A33: Stimpee 6_OP | B33: 1690 | C33: 100 | D33: f-vcrs | E33: VC | F33: 100 | G33: bri | H33: =_xlfn.XLOOKUP(G33,$S$4:$S$9,$T$4:$T$9,"",0,1) -> 3 | I33: 312 | L33: 45194 | M33: 0.48055556 | U33: =IF(C33="","",IF(OR(L33="",AND(ISNUMBER(U33),C33=U33)),U33,C33)) | V33: =IF(C33="","",IF(OR(M33="",AND(ISNUMBER(V33),C33=V33)),V33,C33))
A34: Stimpee 6_OP | B34: 1700 | C34: 100 | D34: vf-vcrs | E34: VC | F34: 100 | G34: bri | H34: =_xlfn.XLOOKUP(G34,$S$4:$S$9,$T$4:$T$9,"",0,1) -> 3 | I34: 399 | L34: 45194 | M34: 0.49930556 | U34: =IF(C34="","",IF(OR(L34="",AND(ISNUMBER(U34),C34=U34)),U34,C34)) | V34: =IF(C34="","",IF(OR(M34="",AND(ISNUMBER(V34),C34=V34)),V34,C34))
A35: Stimpee 6_OP | B35: 1710 | C35: 100 | D35: f-crs | E35: =IF(ISNUMBER(SEARCH("v crs",D35))=TRUE,"VC",IF(ISNUMBER(SEARCH("crs",D35))=TRUE,"C",IF(ISNUMBER(SEARCH("med",D35))=TRUE,"M",IF(ISNUMBER(SEARCH("vf",D35))=TRUE,"VF",IF(ISNUMBER(SEARCH("f",D35))=TRUE,"F",""))))) -> C | F35: 100 | G35: bri | H35: =_xlfn.XLOOKUP(G35,$S$4:$S$9,$T$4:$T$9,"",0,1) -> 3 | I35: 340 | L35: 45194 | M35: 0.53125 | U35: =IF(C35="","",IF(OR(L35="",AND(ISNUMBER(U35),C35=U35)),U35,C35)) | V35: =IF(C35="","",IF(OR(M35="",AND(ISNUMBER(V35),C35=V35)),V35,C35))
A36: Stimpee 6_OP | B36: 1720 | C36: 100 | D36: f-crs | E36: C | F36: 100 | G36: bri | H36: =_xlfn.XLOOKUP(G36,$S$4:$S$9,$T$4:$T$9,"",0,1) -> 3 | I36: 432 | L36: 45194 | M36: 0.54861111 | U36: =IF(C36="","",IF(OR(L36="",AND(ISNUMBER(U36),C36=U36)),U36,C36)) | V36: =IF(C36="","",IF(OR(M36="",AND(ISNUMBER(V36),C36=V36)),V36,C36))
A37: Stimpee 6_OP | B37: 1730 | C37: 95 | D37: f-med,tr crs | E37: C | F37: 100 | G37: bri | H37: =_xlfn.XLOOKUP(G37,$S$4:$S$9,$T$4:$T$9,"",0,1) -> 3 | I37: 404 | L37: 45194 | M37: 0.57291667 | U37: =IF(C37="","",IF(OR(L37="",AND(ISNUMBER(U37),C37=U37)),U37,C37)) | V37: =IF(C37="","",IF(OR(M37="",AND(ISNUMBER(V37),C37=V37)),V37,C37))
A38: Stimpee 6_OP | B38: 1740 | C38: 90 | D38: f-crs | E38: =IF(ISNUMBER(SEARCH("v crs",D38))=TRUE,"VC",IF(ISNUMBER(SEARCH("crs",D38))=TRUE,"C",IF(ISNUMBER(SEARCH("med",D38))=TRUE,"M",IF(ISNUMBER(SEARCH("vf",D38))=TRUE,"VF",IF(ISNUMBER(SEARCH("f",D38))=TRUE,"F",""))))) -> C | F38: 100 | G38: bri | H38: =_xlfn.XLOOKUP(G38,$S$4:$S$9,$T$4:$T$9,"",0,1) -> 3 | I38: 351 | L38: 45194 | M38: 0.59236111 | U38: =IF(C38="","",IF(OR(L38="",AND(ISNUMBER(U38),C38=U38)),U38,C38)) | V38: =IF(C38="","",IF(OR(M38="",AND(ISNUMBER(V38),C38=V38)),V38,C38))
A39: Stimpee 6_OP | B39: 1750 | C39: 100 | D39: f-med,tr crs | E39: =IF(ISNUMBER(SEARCH("v crs",D39))=TRUE,"VC",IF(ISNUMBER(SEARCH("crs",D39))=TRUE,"C",IF(ISNUMBER(SEARCH("med",D39))=TRUE,"M",IF(ISNUMBER(SEARCH("vf",D39))=TRUE,"VF",IF(ISNUMBER(SEARCH("f",D39))=TRUE,"F",""))))) -> C | F39: 100 | G39: mod bri - bri | H39: =_xlfn.XLOOKUP(G39,$S$4:$S$9,$T$4:$T$9,"",0,1) -> 2.5 | I39: 478 | L39: 45194 | M39: 0.61111111 | U39: =IF(C39="","",IF(OR(L39="",AND(ISNUMBER(U39),C39=U39)),U39,C39)) | V39: =IF(C39="","",IF(OR(M39="",AND(ISNUMBER(V39),C39=V39)),V39,C39))
A40: Stimpee 6_OP | B40: 1760 | C40: 100 | D40: vf-med, rr crs | E40: M | F40: 100 | G40: mod bri - bri | H40: =_xlfn.XLOOKUP(G40,$S$4:$S$9,$T$4:$T$9,"",0,1) -> 2.5 | I40: 311 | L40: 45194 | M40: 0.63055556 | U40: =IF(C40="","",IF(OR(L40="",AND(ISNUMBER(U40),C40=U40)),U40,C40)) | V40: =IF(C40="","",IF(OR(M40="",AND(ISNUMBER(V40),C40=V40)),V40,C40))
A41: Stimpee 6_OP | B41: 1770 | C41: 95 | D41: f-vcrs | E41: =IF(ISNUMBER(SEARCH("v crs",D41))=TRUE,"VC",IF(ISNUMBER(SEARCH("crs",D41))=TRUE,"C",IF(ISNUMBER(SEARCH("med",D41))=TRUE,"M",IF(ISNUMBER(SEARCH("vf",D41))=TRUE,"VF",IF(ISNUMBER(SEARCH("f",D41))=TRUE,"F",""))))) -> C | F41: 100 | G41: mod bri-bri | H41: 2.5 | I41: 183 | L41: 45194 | M41: 0.66666667 | U41: =IF(C41="","",IF(OR(L41="",AND(ISNUMBER(U41),C41=U41)),U41,C41)) | V41: =IF(C41="","",IF(OR(M41="",AND(ISNUMBER(V41),C41=V41)),V41,C41))
...

Sheet Long Sample Name
A1: Description | B1: Reservoir Description | C1: Show Description
A2: =IF('Input Sheet'!C4="","",CONCATENATE("Sample ", 'Input Sheet'!B4, "m: ", N2, H2, "% ", "Siltstone, ", P2, 'Input Sheet'!C4, "% ", J2, " Sandstone, ", L2, K2, " FLUOR in SST. ", "TG ", 'Input Sheet'!I4, "U")) -> Sample 1545m: Tr siderite in 70% Siltstone, 30% very fine Sandstone, NO FLUOR in SST. TG 4U | B2: =IF('Input Sheet'!C4="","",CONCATENATE("Sample ", 'Input Sheet'!B4, "m: ", O2, I2, "% ", "Siltstone, ", Q2, 'Input Sheet'!C4, "% ", K2, " Sandstone ")) -> Sample 1545m: veryfine% Siltstone, 30% Sandstone | C2: =IF('Input Sheet'!C4="","",CONCATENATE("Sample ", 'Input Sheet'!B4, "m: ", N2,, L2, K2, " FLUOR in SST. ", "TG ", 'Input Sheet'!I4, "U")) -> Sample 1545m: Tr siderite in NO FLUOR in SST. TG 4U | H2: =IF('Input Sheet'!C4="","",100-'Input Sheet'!C4) -> 70 | I2: =SUBSTITUTE(SUBSTITUTE(SUBSTITUTE(SUBSTITUTE(SUBSTITUTE(SUBSTITUTE(SUBSTITUTE(SUBSTITUTE(SUBSTITUTE(SUBSTITUTE(SUBSTITUTE(SUBSTITUTE(SUBSTITUTE(SUBSTITUTE(SUBSTITUTE(SUBSTITUTE(SUBSTITUTE(SUBSTITUTE(SUBSTITUTE(SUBSTITUTE(SUBSTITUTE(SUBSTITUTE(SUBSTITUTE(SUBSTITUTE(SUBSTITUTE(SUBSTITUTE(SUBSTITUTE(SUBSTITUTE(SUBSTITUTE(SUBSTITUTE(SUBSTITUTE('Input Sheet'!D4,$E$3,$F$3),$E$4,$F$4),$E$5,$F$5),$E$6,$F$6),$E$7,$F$7),$E$8,$F$8),$E$9,$F$9),$E$10,$F$10),$E$11,$F$11),$E$12,$F$12),$E$13,$F$13),$E$14,$F$14),$E$15,$F$15),$E$16,$F$16),$E$17,$F$17),$E$18,$F$18),$E$19,$F$19),$E$20,$F$20),$E$21,$F$21),$E$22,$F$22),$E$23,$F$23),$E$24,$F$24),$E$25,$F$25),$E$26,$F$26),$E$27,$F$27),$E$28,$F$28),$E$29,$F$29),$E$30,$F$30),$E$31,$F$31),$E$32,$F$32),$E$33,$F$33) -> veryfine | J2: =SUBSTITUTE(I2, "veryfine", "very fine") -> very fine | K2: =SUBSTITUTE(SUBSTITUTE(SUBSTITUTE(SUBSTITUTE(SUBSTITUTE(SUBSTITUTE(SUBSTITUTE(SUBSTITUTE(SUBSTITUTE(SUBSTITUTE(SUBSTITUTE(SUBSTITUTE(SUBSTITUTE(SUBSTITUTE(SUBSTITUTE(SUBSTITUTE(SUBSTITUTE(SUBSTITUTE(SUBSTITUTE(SUBSTITUTE(SUBSTITUTE(SUBSTITUTE(SUBSTITUTE(SUBSTITUTE(SUBSTITUTE(SUBSTITUTE(SUBSTITUTE(SUBSTITUTE(SUBSTITUTE(SUBSTITUTE(SUBSTITUTE('Input Sheet'!G4,$E$3,$F$3),$E$4,$F$4),$E$5,$F$5),$E$6,$F$6),$E$7,$F$7),$E$8,$F$8),$E$9,$F$9),$E$10,$F$10),$E$11,$F$11),$E$12,$F$12),$E$13,$F$13),$E$14,$F$14),$E$15,$F$15),$E$16,$F$16),$E$17,$F$17),$E$18,$F$18),$E$19,$F$19),$E$20,$F$20),$E$21,$F$21),$E$22,$F$22),$E$23,$F$23),$E$24,$F$24),$E$25,$F$25),$E$26,$F$26),$E$27,$F$27),$E$28,$F$28),$E$29,$F$29),$E$30,$F$30),$E$31,$F$31),$E$32,$F$32),$E$33,$F$33) | L2: =IF('Input Sheet'!F4=0, "NO",CONCATENATE('Input Sheet'!F4, IF('Input Sheet'!F4>0,"% ",""))) -> NO | M2: =SUBSTITUTE(SUBSTITUTE(SUBSTITUTE(SUBSTITUTE(SUBSTITUTE(SUBSTITUTE(SUBSTITUTE(SUBSTITUTE(SUBSTITUTE(SUBSTITUTE(SUBSTITUTE(SUBSTITUTE(SUBSTITUTE(SUBSTITUTE(SUBSTITUTE(SUBSTITUTE(SUBSTITUTE(SUBSTITUTE(SUBSTITUTE(SUBSTITUTE(SUBSTITUTE(SUBSTITUTE(SUBSTITUTE(SUBSTITUTE(SUBSTITUTE(SUBSTITUTE(SUBSTITUTE(SUBSTITUTE(SUBSTITUTE(SUBSTITUTE(SUBSTITUTE('Input Sheet'!J4,$E$3,$F$3),$E$4,$F$4),$E$5,$F$5),$E$6,$F$6),$E$7,$F$7),$E$8,$F$8),$E$9,$F$9),$E$10,$F$10),$E$11,$F$11),$E$12,$F$12),$E$13,$F$13),$E$14,$F$14),$E$15,$F$15),$E$16,$F$16),$E$17,$F$17),$E$18,$F$18),$E$19,$F$19),$E$20,$F$20),$E$21,$F$21),$E$22,$F$22),$E$23,$F$23),$E$24,$F$24),$E$25,$F$25),$E$26,$F$26),$E$27,$F$27),$E$28,$F$28),$E$29,$F$29),$E$30,$F$30),$E$31,$F$31),$E$32,$F$32),$E$33,$F$33) -> Tr | N2: =CONCATENATE(M2, IF('Input Sheet'!J4="",""," siderite in ")) -> Tr siderite in | O2: =SUBSTITUTE(SUBSTITUTE(SUBSTITUTE(SUBSTITUTE(SUBSTITUTE(SUBSTITUTE(SUBSTITUTE(SUBSTITUTE(SUBSTITUTE(SUBSTITUTE(SUBSTITUTE(SUBSTITUTE(SUBSTITUTE(SUBSTITUTE(SUBSTITUTE(SUBSTITUTE(SUBSTITUTE(SUBSTITUTE(SUBSTITUTE(SUBSTITUTE(SUBSTITUTE(SUBSTITUTE(SUBSTITUTE(SUBSTITUTE(SUBSTITUTE(SUBSTITUTE(SUBSTITUTE(SUBSTITUTE(SUBSTITUTE(SUBSTITUTE(SUBSTITUTE('Input Sheet'!K4,$E$3,$F$3),$E$4,$F$4),$E$5,$F$5),$E$6,$F$6),$E$7,$F$7),$E$8,$F$8),$E$9,$F$9),$E$10,$F$10),$E$11,$F$11),$E$12,$F$12),$E$13,$F$13),$E$14,$F$14),$E$15,$F$15),$E$16,$F$16),$E$17,$F$17),$E$18,$F$18),$E$19,$F$19),$E$20,$F$20),$E$21,$F$21),$E$22,$F$22),$E$23,$F$23),$E$24,$F$24),$E$25,$F$25),$E$26,$F$26),$E$27,$F$27),$E$28,$F$28),$E$29,$F$29),$E$30,$F$30),$E$31,$F$31),$E$32,$F$32),$E$33,$F$33) | P2: =CONCATENATE(O2, IF('Input Sheet'!K4="",""," siderite in "))
A3: =IF('Input Sheet'!C5="","",CONCATENATE("Sample ", 'Input Sheet'!B5, "m: ", N3, H3, "% ", "Siltstone, ", P3, 'Input Sheet'!C5, "% ", J3, " Sandstone, ", L3, K3, " FLUOR in SST. ", "TG ", 'Input Sheet'!I5, "U")) -> Sample 1550m: Tr siderite in 80% Siltstone, 20% very fine to fine Sandstone, NO FLUOR in SST. TG 6U | B3: =IF('Input Sheet'!C5="","",CONCATENATE("Sample ", 'Input Sheet'!B5, "m: ", O3, I3, "% ", "Siltstone, ", Q3, 'Input Sheet'!C5, "% ", K3, " Sandstone ")) -> Sample 1550m: veryfine to fine% Siltstone, 20% Sandstone | C3: =IF('Input Sheet'!C5="","",CONCATENATE("Sample ", 'Input Sheet'!B5, "m: ", N3,, L3, K3, " FLUOR in SST. ", "TG ", 'Input Sheet'!I5, "U")) -> Sample 1550m: Tr siderite in NO FLUOR in SST. TG 6U | H3: =IF('Input Sheet'!C5="","",100-'Input Sheet'!C5) -> 80 | I3: =SUBSTITUTE(SUBSTITUTE(SUBSTITUTE(SUBSTITUTE(SUBSTITUTE(SUBSTITUTE(SUBSTITUTE(SUBSTITUTE(SUBSTITUTE(SUBSTITUTE(SUBSTITUTE(SUBSTITUTE(SUBSTITUTE(SUBSTITUTE(SUBSTITUTE(SUBSTITUTE(SUBSTITUTE(SUBSTITUTE(SUBSTITUTE(SUBSTITUTE(SUBSTITUTE(SUBSTITUTE(SUBSTITUTE(SUBSTITUTE(SUBSTITUTE(SUBSTITUTE(SUBSTITUTE(SUBSTITUTE(SUBSTITUTE(SUBSTITUTE(SUBSTITUTE('Input Sheet'!D5,$E$3,$F$3),$E$4,$F$4),$E$5,$F$5),$E$6,$F$6),$E$7,$F$7),$E$8,$F$8),$E$9,$F$9),$E$10,$F$10),$E$11,$F$11),$E$12,$F$12),$E$13,$F$13),$E$14,$F$14),$E$15,$F$15),$E$16,$F$16),$E$17,$F$17),$E$18,$F$18),$E$19,$F$19),$E$20,$F$20),$E$21,$F$21),$E$22,$F$22),$E$23,$F$23),$E$24,$F$24),$E$25,$F$25),$E$26,$F$26),$E$27,$F$27),$E$28,$F$28),$E$29,$F$29),$E$30,$F$30),$E$31,$F$31),$E$32,$F$32),$E$33,$F$33) -> veryfine to fine | J3: =SUBSTITUTE(I3, "veryfine", "very fine") -> very fine to fine | K3: =SUBSTITUTE(SUBSTITUTE(SUBSTITUTE(SUBSTITUTE(SUBSTITUTE(SUBSTITUTE(SUBSTITUTE(SUBSTITUTE(SUBSTITUTE(SUBSTITUTE(SUBSTITUTE(SUBSTITUTE(SUBSTITUTE(SUBSTITUTE(SUBSTITUTE(SUBSTITUTE(SUBSTITUTE(SUBSTITUTE(SUBSTITUTE(SUBSTITUTE(SUBSTITUTE(SUBSTITUTE(SUBSTITUTE(SUBSTITUTE(SUBSTITUTE(SUBSTITUTE(SUBSTITUTE(SUBSTITUTE(SUBSTITUTE(SUBSTITUTE(SUBSTITUTE('Input Sheet'!G5,$E$3,$F$3),$E$4,$F$4),$E$5,$F$5),$E$6,$F$6),$E$7,$F$7),$E$8,$F$8),$E$9,$F$9),$E$10,$F$10),$E$11,$F$11),$E$12,$F$12),$E$13,$F$13),$E$14,$F$14),$E$15,$F$15),$E$16,$F$16),$E$17,$F$17),$E$18,$F$18),$E$19,$F$19),$E$20,$F$20),$E$21,$F$21),$E$22,$F$22),$E$23,$F$23),$E$24,$F$24),$E$25,$F$25),$E$26,$F$26),$E$27,$F$27),$E$28,$F$28),$E$29,$F$29),$E$30,$F$30),$E$31,$F$31),$E$32,$F$32),$E$33,$F$33) | L3: =IF('Input Sheet'!F5=0, "NO",CONCATENATE('Input Sheet'!F5, IF('Input Sheet'!F5>0,"% ",""))) -> NO | M3: =SUBSTITUTE(SUBSTITUTE(SUBSTITUTE(SUBSTITUTE(SUBSTITUTE(SUBSTITUTE(SUBSTITUTE(SUBSTITUTE(SUBSTITUTE(SUBSTITUTE(SUBSTITUTE(SUBSTITUTE(SUBSTITUTE(SUBSTITUTE(SUBSTITUTE(SUBSTITUTE(SUBSTITUTE(SUBSTITUTE(SUBSTITUTE(SUBSTITUTE(SUBSTITUTE(SUBSTITUTE(SUBSTITUTE(SUBSTITUTE(SUBSTITUTE(SUBSTITUTE(SUBSTITUTE(SUBSTITUTE(SUBSTITUTE(SUBSTITUTE(SUBSTITUTE('Input Sheet'!J5,$E$3,$F$3),$E$4,$F$4),$E$5,$F$5),$E$6,$F$6),$E$7,$F$7),$E$8,$F$8),$E$9,$F$9),$E$10,$F$10),$E$11,$F$11),$E$12,$F$12),$E$13,$F$13),$E$14,$F$14),$E$15,$F$15),$E$16,$F$16),$E$17,$F$17),$E$18,$F$18),$E$19,$F$19),$E$20,$F$20),$E$21,$F$21),$E$22,$F$22),$E$23,$F$23),$E$24,$F$24),$E$25,$F$25),$E$26,$F$26),$E$27,$F$27),$E$28,$F$28),$E$29,$F$29),$E$30,$F$30),$E$31,$F$31),$E$32,$F$32),$E$33,$F$33) -> Tr | N3: =CONCATENATE(M3, IF('Input Sheet'!J5="",""," siderite in ")) -> Tr siderite in | O3: =SUBSTITUTE(SUBSTITUTE(SUBSTITUTE(SUBSTITUTE(SUBSTITUTE(SUBSTITUTE(SUBSTITUTE(SUBSTITUTE(SUBSTITUTE(SUBSTITUTE(SUBSTITUTE(SUBSTITUTE(SUBSTITUTE(SUBSTITUTE(SUBSTITUTE(SUBSTITUTE(SUBSTITUTE(SUBSTITUTE(SUBSTITUTE(SUBSTITUTE(SUBSTITUTE(SUBSTITUTE(SUBSTITUTE(SUBSTITUTE(SUBSTITUTE(SUBSTITUTE(SUBSTITUTE(SUBSTITUTE(SUBSTITUTE(SUBSTITUTE(SUBSTITUTE('Input Sheet'!K5,$E$3,$F$3),$E$4,$F$4),$E$5,$F$5),$E$6,$F$6),$E$7,$F$7),$E$8,$F$8),$E$9,$F$9),$E$10,$F$10),$E$11,$F$11),$E$12,$F$12),$E$13,$F$13),$E$14,$F$14),$E$15,$F$15),$E$16,$F$16),$E$17,$F$17),$E$18,$F$18),$E$19,$F$19),$E$20,$F$20),$E$21,$F$21),$E$22,$F$22),$E$23,$F$23),$E$24,$F$24),$E$25,$F$25),$E$26,$F$26),$E$27,$F$27),$E$28,$F$28),$E$29,$F$29),$E$30,$F$30),$E$31,$F$31),$E$32,$F$32),$E$33,$F$33) | P3: =CONCATENATE(O3, IF('Input Sheet'!K5="",""," siderite in "))
A4: =IF('Input Sheet'!C6="","",CONCATENATE("Sample ", 'Input Sheet'!B6, "m: ", N4, H4, "% ", "Siltstone, ", P4, 'Input Sheet'!C6, "% ", J4, " Sandstone, ", L4, K4, " FLUOR in SST. ", "TG ", 'Input Sheet'!I6, "U")) -> Sample 1555m: Tr siderite in 80% Siltstone, 20% very fine to fine Sandstone, NO FLUOR in SST. TG 5U | B4: =IF('Input Sheet'!C6="","",CONCATENATE("Sample ", 'Input Sheet'!B6, "m: ", O4, I4, "% ", "Siltstone, ", Q4, 'Input Sheet'!C6, "% ", K4, " Sandstone ")) -> Sample 1555m: veryfine to fine% Siltstone, 20% Sandstone | C4: =IF('Input Sheet'!C6="","",CONCATENATE("Sample ", 'Input Sheet'!B6, "m: ", N4,, L4, K4, " FLUOR in SST. ", "TG ", 'Input Sheet'!I6, "U")) -> Sample 1555m: Tr siderite in NO FLUOR in SST. TG 5U | E4: f | F4: fine | H4: =IF('Input Sheet'!C6="","",100-'Input Sheet'!C6) -> 80 | I4: =SUBSTITUTE(SUBSTITUTE(SUBSTITUTE(SUBSTITUTE(SUBSTITUTE(SUBSTITUTE(SUBSTITUTE(SUBSTITUTE(SUBSTITUTE(SUBSTITUTE(SUBSTITUTE(SUBSTITUTE(SUBSTITUTE(SUBSTITUTE(SUBSTITUTE(SUBSTITUTE(SUBSTITUTE(SUBSTITUTE(SUBSTITUTE(SUBSTITUTE(SUBSTITUTE(SUBSTITUTE(SUBSTITUTE(SUBSTITUTE(SUBSTITUTE(SUBSTITUTE(SUBSTITUTE(SUBSTITUTE(SUBSTITUTE(SUBSTITUTE(SUBSTITUTE('Input Sheet'!D6,$E$3,$F$3),$E$4,$F$4),$E$5,$F$5),$E$6,$F$6),$E$7,$F$7),$E$8,$F$8),$E$9,$F$9),$E$10,$F$10),$E$11,$F$11),$E$12,$F$12),$E$13,$F$13),$E$14,$F$14),$E$15,$F$15),$E$16,$F$16),$E$17,$F$17),$E$18,$F$18),$E$19,$F$19),$E$20,$F$20),$E$21,$F$21),$E$22,$F$22),$E$23,$F$23),$E$24,$F$24),$E$25,$F$25),$E$26,$F$26),$E$27,$F$27),$E$28,$F$28),$E$29,$F$29),$E$30,$F$30),$E$31,$F$31),$E$32,$F$32),$E$33,$F$33) -> veryfine to fine | J4: =SUBSTITUTE(I4, "veryfine", "very fine") -> very fine to fine | K4: =SUBSTITUTE(SUBSTITUTE(SUBSTITUTE(SUBSTITUTE(SUBSTITUTE(SUBSTITUTE(SUBSTITUTE(SUBSTITUTE(SUBSTITUTE(SUBSTITUTE(SUBSTITUTE(SUBSTITUTE(SUBSTITUTE(SUBSTITUTE(SUBSTITUTE(SUBSTITUTE(SUBSTITUTE(SUBSTITUTE(SUBSTITUTE(SUBSTITUTE(SUBSTITUTE(SUBSTITUTE(SUBSTITUTE(SUBSTITUTE(SUBSTITUTE(SUBSTITUTE(SUBSTITUTE(SUBSTITUTE(SUBSTITUTE(SUBSTITUTE(SUBSTITUTE('Input Sheet'!G6,$E$3,$F$3),$E$4,$F$4),$E$5,$F$5),$E$6,$F$6),$E$7,$F$7),$E$8,$F$8),$E$9,$F$9),$E$10,$F$10),$E$11,$F$11),$E$12,$F$12),$E$13,$F$13),$E$14,$F$14),$E$15,$F$15),$E$16,$F$16),$E$17,$F$17),$E$18,$F$18),$E$19,$F$19),$E$20,$F$20),$E$21,$F$21),$E$22,$F$22),$E$23,$F$23),$E$24,$F$24),$E$25,$F$25),$E$26,$F$26),$E$27,$F$27),$E$28,$F$28),$E$29,$F$29),$E$30,$F$30),$E$31,$F$31),$E$32,$F$32),$E$33,$F$33) | L4: =IF('Input Sheet'!F6=0, "NO",CONCATENATE('Input Sheet'!F6, IF('Input Sheet'!F6>0,"% ",""))) -> NO | M4: =SUBSTITUTE(SUBSTITUTE(SUBSTITUTE(SUBSTITUTE(SUBSTITUTE(SUBSTITUTE(SUBSTITUTE(SUBSTITUTE(SUBSTITUTE(SUBSTITUTE(SUBSTITUTE(SUBSTITUTE(SUBSTITUTE(SUBSTITUTE(SUBSTITUTE(SUBSTITUTE(SUBSTITUTE(SUBSTITUTE(SUBSTITUTE(SUBSTITUTE(SUBSTITUTE(SUBSTITUTE(SUBSTITUTE(SUBSTITUTE(SUBSTITUTE(SUBSTITUTE(SUBSTITUTE(SUBSTITUTE(SUBSTITUTE(SUBSTITUTE(SUBSTITUTE('Input Sheet'!J6,$E$3,$F$3),$E$4,$F$4),$E$5,$F$5),$E$6,$F$6),$E$7,$F$7),$E$8,$F$8),$E$9,$F$9),$E$10,$F$10),$E$11,$F$11),$E$12,$F$12),$E$13,$F$13),$E$14,$F$14),$E$15,$F$15),$E$16,$F$16),$E$17,$F$17),$E$18,$F$18),$E$19,$F$19),$E$20,$F$20),$E$21,$F$21),$E$22,$F$22),$E$23,$F$23),$E$24,$F$24),$E$25,$F$25),$E$26,$F$26),$E$27,$F$27),$E$28,$F$28),$E$29,$F$29),$E$30,$F$30),$E$31,$F$31),$E$32,$F$32),$E$33,$F$33) -> Tr | N4: =CONCATENATE(M4, IF('Input Sheet'!J6="",""," siderite in ")) -> Tr siderite in | O4: =SUBSTITUTE(SUBSTITUTE(SUBSTITUTE(SUBSTITUTE(SUBSTITUTE(SUBSTITUTE(SUBSTITUTE(SUBSTITUTE(SUBSTITUTE(SUBSTITUTE(SUBSTITUTE(SUBSTITUTE(SUBSTITUTE(SUBSTITUTE(SUBSTITUTE(SUBSTITUTE(SUBSTITUTE(SUBSTITUTE(SUBSTITUTE(SUBSTITUTE(SUBSTITUTE(SUBSTITUTE(SUBSTITUTE(SUBSTITUTE(SUBSTITUTE(SUBSTITUTE(SUBSTITUTE(SUBSTITUTE(SUBSTITUTE(SUBSTITUTE(SUBSTITUTE('Input Sheet'!K6,$E$3,$F$3),$E$4,$F$4),$E$5,$F$5),$E$6,$F$6),$E$7,$F$7),$E$8,$F$8),$E$9,$F$9),$E$10,$F$10),$E$11,$F$11),$E$12,$F$12),$E$13,$F$13),$E$14,$F$14),$E$15,$F$15),$E$16,$F$16),$E$17,$F$17),$E$18,$F$18),$E$19,$F$19),$E$20,$F$20),$E$21,$F$21),$E$22,$F$22),$E$23,$F$23),$E$24,$F$24),$E$25,$F$25),$E$26,$F$26),$E$27,$F$27),$E$28,$F$28),$E$29,$F$29),$E$30,$F$30),$E$31,$F$31),$E$32,$F$32),$E$33,$F$33) | P4: =CONCATENATE(O4, IF('Input Sheet'!K6="",""," siderite in "))
A5: =IF('Input Sheet'!C7="","",CONCATENATE("Sample ", 'Input Sheet'!B7, "m: ", N5, H5, "% ", "Siltstone, ", P5, 'Input Sheet'!C7, "% ", J5, " Sandstone, ", L5, K5, " FLUOR in SST. ", "TG ", 'Input Sheet'!I7, "U")) -> Sample 1560m: Tr siderite in 70% Siltstone, 30% very fine to fine Sandstone, NO FLUOR in SST. TG 6U | B5: =IF('Input Sheet'!C7="","",CONCATENATE("Sample ", 'Input Sheet'!B7, "m: ", O5, I5, "% ", "Siltstone, ", Q5, 'Input Sheet'!C7, "% ", K5, " Sandstone ")) -> Sample 1560m: veryfine to fine% Siltstone, 30% Sandstone | C5: =IF('Input Sheet'!C7="","",CONCATENATE("Sample ", 'Input Sheet'!B7, "m: ", N5,, L5, K5, " FLUOR in SST. ", "TG ", 'Input Sheet'!I7, "U")) -> Sample 1560m: Tr siderite in NO FLUOR in SST. TG 6U | E5: med | F5: medium | H5: =IF('Input Sheet'!C7="","",100-'Input Sheet'!C7) -> 70 | I5: =SUBSTITUTE(SUBSTITUTE(SUBSTITUTE(SUBSTITUTE(SUBSTITUTE(SUBSTITUTE(SUBSTITUTE(SUBSTITUTE(SUBSTITUTE(SUBSTITUTE(SUBSTITUTE(SUBSTITUTE(SUBSTITUTE(SUBSTITUTE(SUBSTITUTE(SUBSTITUTE(SUBSTITUTE(SUBSTITUTE(SUBSTITUTE(SUBSTITUTE(SUBSTITUTE(SUBSTITUTE(SUBSTITUTE(SUBSTITUTE(SUBSTITUTE(SUBSTITUTE(SUBSTITUTE(SUBSTITUTE(SUBSTITUTE(SUBSTITUTE(SUBSTITUTE('Input Sheet'!D7,$E$3,$F$3),$E$4,$F$4),$E$5,$F$5),$E$6,$F$6),$E$7,$F$7),$E$8,$F$8),$E$9,$F$9),$E$10,$F$10),$E$11,$F$11),$E$12,$F$12),$E$13,$F$13),$E$14,$F$14),$E$15,$F$15),$E$16,$F$16),$E$17,$F$17),$E$18,$F$18),$E$19,$F$19),$E$20,$F$20),$E$21,$F$21),$E$22,$F$22),$E$23,$F$23),$E$24,$F$24),$E$25,$F$25),$E$26,$F$26),$E$27,$F$27),$E$28,$F$28),$E$29,$F$29),$E$30,$F$30),$E$31,$F$31),$E$32,$F$32),$E$33,$F$33) -> veryfine to fine | J5: =SUBSTITUTE(I5, "veryfine", "very fine") -> very fine to fine | K5: =SUBSTITUTE(SUBSTITUTE(SUBSTITUTE(SUBSTITUTE(SUBSTITUTE(SUBSTITUTE(SUBSTITUTE(SUBSTITUTE(SUBSTITUTE(SUBSTITUTE(SUBSTITUTE(SUBSTITUTE(SUBSTITUTE(SUBSTITUTE(SUBSTITUTE(SUBSTITUTE(SUBSTITUTE(SUBSTITUTE(SUBSTITUTE(SUBSTITUTE(SUBSTITUTE(SUBSTITUTE(SUBSTITUTE(SUBSTITUTE(SUBSTITUTE(SUBSTITUTE(SUBSTITUTE(SUBSTITUTE(SUBSTITUTE(SUBSTITUTE(SUBSTITUTE('Input Sheet'!G7,$E$3,$F$3),$E$4,$F$4),$E$5,$F$5),$E$6,$F$6),$E$7,$F$7),$E$8,$F$8),$E$9,$F$9),$E$10,$F$10),$E$11,$F$11),$E$12,$F$12),$E$13,$F$13),$E$14,$F$14),$E$15,$F$15),$E$16,$F$16),$E$17,$F$17),$E$18,$F$18),$E$19,$F$19),$E$20,$F$20),$E$21,$F$21),$E$22,$F$22),$E$23,$F$23),$E$24,$F$24),$E$25,$F$25),$E$26,$F$26),$E$27,$F$27),$E$28,$F$28),$E$29,$F$29),$E$30,$F$30),$E$31,$F$31),$E$32,$F$32),$E$33,$F$33) | L5: =IF('Input Sheet'!F7=0, "NO",CONCATENATE('Input Sheet'!F7, IF('Input Sheet'!F7>0,"% ",""))) -> NO | M5: =SUBSTITUTE(SUBSTITUTE(SUBSTITUTE(SUBSTITUTE(SUBSTITUTE(SUBSTITUTE(SUBSTITUTE(SUBSTITUTE(SUBSTITUTE(SUBSTITUTE(SUBSTITUTE(SUBSTITUTE(SUBSTITUTE(SUBSTITUTE(SUBSTITUTE(SUBSTITUTE(SUBSTITUTE(SUBSTITUTE(SUBSTITUTE(SUBSTITUTE(SUBSTITUTE(SUBSTITUTE(SUBSTITUTE(SUBSTITUTE(SUBSTITUTE(SUBSTITUTE(SUBSTITUTE(SUBSTITUTE(SUBSTITUTE(SUBSTITUTE(SUBSTITUTE('Input Sheet'!J7,$E$3,$F$3),$E$4,$F$4),$E$5,$F$5),$E$6,$F$6),$E$7,$F$7),$E$8,$F$8),$E$9,$F$9),$E$10,$F$10),$E$11,$F$11),$E$12,$F$12),$E$13,$F$13),$E$14,$F$14),$E$15,$F$15),$E$16,$F$16),$E$17,$F$17),$E$18,$F$18),$E$19,$F$19),$E$20,$F$20),$E$21,$F$21),$E$22,$F$22),$E$23,$F$23),$E$24,$F$24),$E$25,$F$25),$E$26,$F$26),$E$27,$F$27),$E$28,$F$28),$E$29,$F$29),$E$30,$F$30),$E$31,$F$31),$E$32,$F$32),$E$33,$F$33) -> Tr | N5: =CONCATENATE(M5, IF('Input Sheet'!J7="",""," siderite in ")) -> Tr siderite in | O5: =SUBSTITUTE(SUBSTITUTE(SUBSTITUTE(SUBSTITUTE(SUBSTITUTE(SUBSTITUTE(SUBSTITUTE(SUBSTITUTE(SUBSTITUTE(SUBSTITUTE(SUBSTITUTE(SUBSTITUTE(SUBSTITUTE(SUBSTITUTE(SUBSTITUTE(SUBSTITUTE(SUBSTITUTE(SUBSTITUTE(SUBSTITUTE(SUBSTITUTE(SUBSTITUTE(SUBSTITUTE(SUBSTITUTE(SUBSTITUTE(SUBSTITUTE(SUBSTITUTE(SUBSTITUTE(SUBSTITUTE(SUBSTITUTE(SUBSTITUTE(SUBSTITUTE('Input Sheet'!K7,$E$3,$F$3),$E$4,$F$4),$E$5,$F$5),$E$6,$F$6),$E$7,$F$7),$E$8,$F$8),$E$9,$F$9),$E$10,$F$10),$E$11,$F$11),$E$12,$F$12),$E$13,$F$13),$E$14,$F$14),$E$15,$F$15),$E$16,$F$16),$E$17,$F$17),$E$18,$F$18),$E$19,$F$19),$E$20,$F$20),$E$21,$F$21),$E$22,$F$22),$E$23,$F$23),$E$24,$F$24),$E$25,$F$25),$E$26,$F$26),$E$27,$F$27),$E$28,$F$28),$E$29,$F$29),$E$30,$F$30),$E$31,$F$31),$E$32,$F$32),$E$33,$F$33) | P5: =CONCATENATE(O5, IF('Input Sheet'!K7="",""," siderite in "))
A6: =IF('Input Sheet'!C8="","",CONCATENATE("Sample ", 'Input Sheet'!B8, "m: ", N6, H6, "% ", "Siltstone, ", P6, 'Input Sheet'!C8, "% ", J6, " Sandstone, ", L6, K6, " FLUOR in SST. ", "TG ", 'Input Sheet'!I8, "U")) -> Sample 1565m: Tr siderite in 80% Siltstone, 20% very fine to fine Sandstone, NO FLUOR in SST. TG 7U | B6: =IF('Input Sheet'!C8="","",CONCATENATE("Sample ", 'Input Sheet'!B8, "m: ", O6, I6, "% ", "Siltstone, ", Q6, 'Input Sheet'!C8, "% ", K6, " Sandstone ")) -> Sample 1565m: veryfine to fine% Siltstone, 20% Sandstone | C6: =IF('Input Sheet'!C8="","",CONCATENATE("Sample ", 'Input Sheet'!B8, "m: ", N6,, L6, K6, " FLUOR in SST. ", "TG ", 'Input Sheet'!I8, "U")) -> Sample 1565m: Tr siderite in NO FLUOR in SST. TG 7U | E6: crs | F6: coarse | H6: =IF('Input Sheet'!C8="","",100-'Input Sheet'!C8) -> 80 | I6: =SUBSTITUTE(SUBSTITUTE(SUBSTITUTE(SUBSTITUTE(SUBSTITUTE(SUBSTITUTE(SUBSTITUTE(SUBSTITUTE(SUBSTITUTE(SUBSTITUTE(SUBSTITUTE(SUBSTITUTE(SUBSTITUTE(SUBSTITUTE(SUBSTITUTE(SUBSTITUTE(SUBSTITUTE(SUBSTITUTE(SUBSTITUTE(SUBSTITUTE(SUBSTITUTE(SUBSTITUTE(SUBSTITUTE(SUBSTITUTE(SUBSTITUTE(SUBSTITUTE(SUBSTITUTE(SUBSTITUTE(SUBSTITUTE(SUBSTITUTE(SUBSTITUTE('Input Sheet'!D8,$E$3,$F$3),$E$4,$F$4),$E$5,$F$5),$E$6,$F$6),$E$7,$F$7),$E$8,$F$8),$E$9,$F$9),$E$10,$F$10),$E$11,$F$11),$E$12,$F$12),$E$13,$F$13),$E$14,$F$14),$E$15,$F$15),$E$16,$F$16),$E$17,$F$17),$E$18,$F$18),$E$19,$F$19),$E$20,$F$20),$E$21,$F$21),$E$22,$F$22),$E$23,$F$23),$E$24,$F$24),$E$25,$F$25),$E$26,$F$26),$E$27,$F$27),$E$28,$F$28),$E$29,$F$29),$E$30,$F$30),$E$31,$F$31),$E$32,$F$32),$E$33,$F$33) -> veryfine to fine | J6: =SUBSTITUTE(I6, "veryfine", "very fine") -> very fine to fine | K6: =SUBSTITUTE(SUBSTITUTE(SUBSTITUTE(SUBSTITUTE(SUBSTITUTE(SUBSTITUTE(SUBSTITUTE(SUBSTITUTE(SUBSTITUTE(SUBSTITUTE(SUBSTITUTE(SUBSTITUTE(SUBSTITUTE(SUBSTITUTE(SUBSTITUTE(SUBSTITUTE(SUBSTITUTE(SUBSTITUTE(SUBSTITUTE(SUBSTITUTE(SUBSTITUTE(SUBSTITUTE(SUBSTITUTE(SUBSTITUTE(SUBSTITUTE(SUBSTITUTE(SUBSTITUTE(SUBSTITUTE(SUBSTITUTE(SUBSTITUTE(SUBSTITUTE('Input Sheet'!G8,$E$3,$F$3),$E$4,$F$4),$E$5,$F$5),$E$6,$F$6),$E$7,$F$7),$E$8,$F$8),$E$9,$F$9),$E$10,$F$10),$E$11,$F$11),$E$12,$F$12),$E$13,$F$13),$E$14,$F$14),$E$15,$F$15),$E$16,$F$16),$E$17,$F$17),$E$18,$F$18),$E$19,$F$19),$E$20,$F$20),$E$21,$F$21),$E$22,$F$22),$E$23,$F$23),$E$24,$F$24),$E$25,$F$25),$E$26,$F$26),$E$27,$F$27),$E$28,$F$28),$E$29,$F$29),$E$30,$F$30),$E$31,$F$31),$E$32,$F$32),$E$33,$F$33) | L6: =IF('Input Sheet'!F8=0, "NO",CONCATENATE('Input Sheet'!F8, IF('Input Sheet'!F8>0,"% ",""))) -> NO | M6: =SUBSTITUTE(SUBSTITUTE(SUBSTITUTE(SUBSTITUTE(SUBSTITUTE(SUBSTITUTE(SUBSTITUTE(SUBSTITUTE(SUBSTITUTE(SUBSTITUTE(SUBSTITUTE(SUBSTITUTE(SUBSTITUTE(SUBSTITUTE(SUBSTITUTE(SUBSTITUTE(SUBSTITUTE(SUBSTITUTE(SUBSTITUTE(SUBSTITUTE(SUBSTITUTE(SUBSTITUTE(SUBSTITUTE(SUBSTITUTE(SUBSTITUTE(SUBSTITUTE(SUBSTITUTE(SUBSTITUTE(SUBSTITUTE(SUBSTITUTE(SUBSTITUTE('Input Sheet'!J8,$E$3,$F$3),$E$4,$F$4),$E$5,$F$5),$E$6,$F$6),$E$7,$F$7),$E$8,$F$8),$E$9,$F$9),$E$10,$F$10),$E$11,$F$11),$E$12,$F$12),$E$13,$F$13),$E$14,$F$14),$E$15,$F$15),$E$16,$F$16),$E$17,$F$17),$E$18,$F$18),$E$19,$F$19),$E$20,$F$20),$E$21,$F$21),$E$22,$F$22),$E$23,$F$23),$E$24,$F$24),$E$25,$F$25),$E$26,$F$26),$E$27,$F$27),$E$28,$F$28),$E$29,$F$29),$E$30,$F$30),$E$31,$F$31),$E$32,$F$32),$E$33,$F$33) -> Tr | N6: =CONCATENATE(M6, IF('Input Sheet'!J8="",""," siderite in ")) -> Tr siderite in | O6: =SUBSTITUTE(SUBSTITUTE(SUBSTITUTE(SUBSTITUTE(SUBSTITUTE(SUBSTITUTE(SUBSTITUTE(SUBSTITUTE(SUBSTITUTE(SUBSTITUTE(SUBSTITUTE(SUBSTITUTE(SUBSTITUTE(SUBSTITUTE(SUBSTITUTE(SUBSTITUTE(SUBSTITUTE(SUBSTITUTE(SUBSTITUTE(SUBSTITUTE(SUBSTITUTE(SUBSTITUTE(SUBSTITUTE(SUBSTITUTE(SUBSTITUTE(SUBSTITUTE(SUBSTITUTE(SUBSTITUTE(SUBSTITUTE(SUBSTITUTE(SUBSTITUTE('Input Sheet'!K8,$E$3,$F$3),$E$4,$F$4),$E$5,$F$5),$E$6,$F$6),$E$7,$F$7),$E$8,$F$8),$E$9,$F$9),$E$10,$F$10),$E$11,$F$11),$E$12,$F$12),$E$13,$F$13),$E$14,$F$14),$E$15,$F$15),$E$16,$F$16),$E$17,$F$17),$E$18,$F$18),$E$19,$F$19),$E$20,$F$20),$E$21,$F$21),$E$22,$F$22),$E$23,$F$23),$E$24,$F$24),$E$25,$F$25),$E$26,$F$26),$E$27,$F$27),$E$28,$F$28),$E$29,$F$29),$E$30,$F$30),$E$31,$F$31),$E$32,$F$32),$E$33,$F$33) | P6: =CONCATENATE(O6, IF('Input Sheet'!K8="",""," siderite in "))
A7: =IF('Input Sheet'!C9="","",CONCATENATE("Sample ", 'Input Sheet'!B9, "m: ", N7, H7, "% ", "Siltstone, ", P7, 'Input Sheet'!C9, "% ", J7, " Sandstone, ", L7, K7, " FLUOR in SST. ", "TG ", 'Input Sheet'!I9, "U")) -> Sample 1570m: Tr siderite in 70% Siltstone, 30% very fine to fine Sandstone, NO FLUOR in SST. TG 6U | B7: =IF('Input Sheet'!C9="","",CONCATENATE("Sample ", 'Input Sheet'!B9, "m: ", O7, I7, "% ", "Siltstone, ", Q7, 'Input Sheet'!C9, "% ", K7, " Sandstone ")) -> Sample 1570m: veryfine to fine% Siltstone, 30% Sandstone | C7: =IF('Input Sheet'!C9="","",CONCATENATE("Sample ", 'Input Sheet'!B9, "m: ", N7,, L7, K7, " FLUOR in SST. ", "TG ", 'Input Sheet'!I9, "U")) -> Sample 1570m: Tr siderite in NO FLUOR in SST. TG 6U | E7: v | F7: very | H7: =IF('Input Sheet'!C9="","",100-'Input Sheet'!C9) -> 70 | I7: =SUBSTITUTE(SUBSTITUTE(SUBSTITUTE(SUBSTITUTE(SUBSTITUTE(SUBSTITUTE(SUBSTITUTE(SUBSTITUTE(SUBSTITUTE(SUBSTITUTE(SUBSTITUTE(SUBSTITUTE(SUBSTITUTE(SUBSTITUTE(SUBSTITUTE(SUBSTITUTE(SUBSTITUTE(SUBSTITUTE(SUBSTITUTE(SUBSTITUTE(SUBSTITUTE(SUBSTITUTE(SUBSTITUTE(SUBSTITUTE(SUBSTITUTE(SUBSTITUTE(SUBSTITUTE(SUBSTITUTE(SUBSTITUTE(SUBSTITUTE(SUBSTITUTE('Input Sheet'!D9,$E$3,$F$3),$E$4,$F$4),$E$5,$F$5),$E$6,$F$6),$E$7,$F$7),$E$8,$F$8),$E$9,$F$9),$E$10,$F$10),$E$11,$F$11),$E$12,$F$12),$E$13,$F$13),$E$14,$F$14),$E$15,$F$15),$E$16,$F$16),$E$17,$F$17),$E$18,$F$18),$E$19,$F$19),$E$20,$F$20),$E$21,$F$21),$E$22,$F$22),$E$23,$F$23),$E$24,$F$24),$E$25,$F$25),$E$26,$F$26),$E$27,$F$27),$E$28,$F$28),$E$29,$F$29),$E$30,$F$30),$E$31,$F$31),$E$32,$F$32),$E$33,$F$33) -> veryfine to fine | J7: =SUBSTITUTE(I7, "veryfine", "very fine") -> very fine to fine | K7: =SUBSTITUTE(SUBSTITUTE(SUBSTITUTE(SUBSTITUTE(SUBSTITUTE(SUBSTITUTE(SUBSTITUTE(SUBSTITUTE(SUBSTITUTE(SUBSTITUTE(SUBSTITUTE(SUBSTITUTE(SUBSTITUTE(SUBSTITUTE(SUBSTITUTE(SUBSTITUTE(SUBSTITUTE(SUBSTITUTE(SUBSTITUTE(SUBSTITUTE(SUBSTITUTE(SUBSTITUTE(SUBSTITUTE(SUBSTITUTE(SUBSTITUTE(SUBSTITUTE(SUBSTITUTE(SUBSTITUTE(SUBSTITUTE(SUBSTITUTE(SUBSTITUTE('Input Sheet'!G9,$E$3,$F$3),$E$4,$F$4),$E$5,$F$5),$E$6,$F$6),$E$7,$F$7),$E$8,$F$8),$E$9,$F$9),$E$10,$F$10),$E$11,$F$11),$E$12,$F$12),$E$13,$F$13),$E$14,$F$14),$E$15,$F$15),$E$16,$F$16),$E$17,$F$17),$E$18,$F$18),$E$19,$F$19),$E$20,$F$20),$E$21,$F$21),$E$22,$F$22),$E$23,$F$23),$E$24,$F$24),$E$25,$F$25),$E$26,$F$26),$E$27,$F$27),$E$28,$F$28),$E$29,$F$29),$E$30,$F$30),$E$31,$F$31),$E$32,$F$32),$E$33,$F$33) | L7: =IF('Input Sheet'!F9=0, "NO",CONCATENATE('Input Sheet'!F9, IF('Input Sheet'!F9>0,"% ",""))) -> NO | M7: =SUBSTITUTE(SUBSTITUTE(SUBSTITUTE(SUBSTITUTE(SUBSTITUTE(SUBSTITUTE(SUBSTITUTE(SUBSTITUTE(SUBSTITUTE(SUBSTITUTE(SUBSTITUTE(SUBSTITUTE(SUBSTITUTE(SUBSTITUTE(SUBSTITUTE(SUBSTITUTE(SUBSTITUTE(SUBSTITUTE(SUBSTITUTE(SUBSTITUTE(SUBSTITUTE(SUBSTITUTE(SUBSTITUTE(SUBSTITUTE(SUBSTITUTE(SUBSTITUTE(SUBSTITUTE(SUBSTITUTE(SUBSTITUTE(SUBSTITUTE(SUBSTITUTE('Input Sheet'!J9,$E$3,$F$3),$E$4,$F$4),$E$5,$F$5),$E$6,$F$6),$E$7,$F$7),$E$8,$F$8),$E$9,$F$9),$E$10,$F$10),$E$11,$F$11),$E$12,$F$12),$E$13,$F$13),$E$14,$F$14),$E$15,$F$15),$E$16,$F$16),$E$17,$F$17),$E$18,$F$18),$E$19,$F$19),$E$20,$F$20),$E$21,$F$21),$E$22,$F$22),$E$23,$F$23),$E$24,$F$24),$E$25,$F$25),$E$26,$F$26),$E$27,$F$27),$E$28,$F$28),$E$29,$F$29),$E$30,$F$30),$E$31,$F$31),$E$32,$F$32),$E$33,$F$33) -> Tr | N7: =CONCATENATE(M7, IF('Input Sheet'!J9="",""," siderite in ")) -> Tr siderite in | O7: =SUBSTITUTE(SUBSTITUTE(SUBSTITUTE(SUBSTITUTE(SUBSTITUTE(SUBSTITUTE(SUBSTITUTE(SUBSTITUTE(SUBSTITUTE(SUBSTITUTE(SUBSTITUTE(SUBSTITUTE(SUBSTITUTE(SUBSTITUTE(SUBSTITUTE(SUBSTITUTE(SUBSTITUTE(SUBSTITUTE(SUBSTITUTE(SUBSTITUTE(SUBSTITUTE(SUBSTITUTE(SUBSTITUTE(SUBSTITUTE(SUBSTITUTE(SUBSTITUTE(SUBSTITUTE(SUBSTITUTE(SUBSTITUTE(SUBSTITUTE(SUBSTITUTE('Input Sheet'!K9,$E$3,$F$3),$E$4,$F$4),$E$5,$F$5),$E$6,$F$6),$E$7,$F$7),$E$8,$F$8),$E$9,$F$9),$E$10,$F$10),$E$11,$F$11),$E$12,$F$12),$E$13,$F$13),$E$14,$F$14),$E$15,$F$15),$E$16,$F$16),$E$17,$F$17),$E$18,$F$18),$E$19,$F$19),$E$20,$F$20),$E$21,$F$21),$E$22,$F$22),$E$23,$F$23),$E$24,$F$24),$E$25,$F$25),$E$26,$F$26),$E$27,$F$27),$E$28,$F$28),$E$29,$F$29),$E$30,$F$30),$E$31,$F$31),$E$32,$F$32),$E$33,$F$33) | P7: =CONCATENATE(O7, IF('Input Sheet'!K9="",""," siderite in "))
A8: =IF('Input Sheet'!C10="","",CONCATENATE("Sample ", 'Input Sheet'!B10, "m: ", N8, H8, "% ", "Siltstone, ", P8, 'Input Sheet'!C10, "% ", J8, " Sandstone, ", L8, K8, " FLUOR in SST. ", "TG ", 'Input Sheet'!I10, "U")) -> Sample 1575m: Tr siderite in 75% Siltstone, 25% very fine to fine Sandstone, NO FLUOR in SST. TG 7U | B8: =IF('Input Sheet'!C10="","",CONCATENATE("Sample ", 'Input Sheet'!B10, "m: ", O8, I8, "% ", "Siltstone, ", Q8, 'Input Sheet'!C10, "% ", K8, " Sandstone ")) -> Sample 1575m: veryfine to fine% Siltstone, 25% Sandstone | C8: =IF('Input Sheet'!C10="","",CONCATENATE("Sample ", 'Input Sheet'!B10, "m: ", N8,, L8, K8, " FLUOR in SST. ", "TG ", 'Input Sheet'!I10, "U")) -> Sample 1575m: Tr siderite in NO FLUOR in SST. TG 7U | E8: - | F8: to | H8: =IF('Input Sheet'!C10="","",100-'Input Sheet'!C10) -> 75 | I8: =SUBSTITUTE(SUBSTITUTE(SUBSTITUTE(SUBSTITUTE(SUBSTITUTE(SUBSTITUTE(SUBSTITUTE(SUBSTITUTE(SUBSTITUTE(SUBSTITUTE(SUBSTITUTE(SUBSTITUTE(SUBSTITUTE(SUBSTITUTE(SUBSTITUTE(SUBSTITUTE(SUBSTITUTE(SUBSTITUTE(SUBSTITUTE(SUBSTITUTE(SUBSTITUTE(SUBSTITUTE(SUBSTITUTE(SUBSTITUTE(SUBSTITUTE(SUBSTITUTE(SUBSTITUTE(SUBSTITUTE(SUBSTITUTE(SUBSTITUTE(SUBSTITUTE('Input Sheet'!D10,$E$3,$F$3),$E$4,$F$4),$E$5,$F$5),$E$6,$F$6),$E$7,$F$7),$E$8,$F$8),$E$9,$F$9),$E$10,$F$10),$E$11,$F$11),$E$12,$F$12),$E$13,$F$13),$E$14,$F$14),$E$15,$F$15),$E$16,$F$16),$E$17,$F$17),$E$18,$F$18),$E$19,$F$19),$E$20,$F$20),$E$21,$F$21),$E$22,$F$22),$E$23,$F$23),$E$24,$F$24),$E$25,$F$25),$E$26,$F$26),$E$27,$F$27),$E$28,$F$28),$E$29,$F$29),$E$30,$F$30),$E$31,$F$31),$E$32,$F$32),$E$33,$F$33) -> veryfine to fine | J8: =SUBSTITUTE(I8, "veryfine", "very fine") -> very fine to fine | K8: =SUBSTITUTE(SUBSTITUTE(SUBSTITUTE(SUBSTITUTE(SUBSTITUTE(SUBSTITUTE(SUBSTITUTE(SUBSTITUTE(SUBSTITUTE(SUBSTITUTE(SUBSTITUTE(SUBSTITUTE(SUBSTITUTE(SUBSTITUTE(SUBSTITUTE(SUBSTITUTE(SUBSTITUTE(SUBSTITUTE(SUBSTITUTE(SUBSTITUTE(SUBSTITUTE(SUBSTITUTE(SUBSTITUTE(SUBSTITUTE(SUBSTITUTE(SUBSTITUTE(SUBSTITUTE(SUBSTITUTE(SUBSTITUTE(SUBSTITUTE(SUBSTITUTE('Input Sheet'!G10,$E$3,$F$3),$E$4,$F$4),$E$5,$F$5),$E$6,$F$6),$E$7,$F$7),$E$8,$F$8),$E$9,$F$9),$E$10,$F$10),$E$11,$F$11),$E$12,$F$12),$E$13,$F$13),$E$14,$F$14),$E$15,$F$15),$E$16,$F$16),$E$17,$F$17),$E$18,$F$18),$E$19,$F$19),$E$20,$F$20),$E$21,$F$21),$E$22,$F$22),$E$23,$F$23),$E$24,$F$24),$E$25,$F$25),$E$26,$F$26),$E$27,$F$27),$E$28,$F$28),$E$29,$F$29),$E$30,$F$30),$E$31,$F$31),$E$32,$F$32),$E$33,$F$33) | L8: =IF('Input Sheet'!F10=0, "NO",CONCATENATE('Input Sheet'!F10, IF('Input Sheet'!F10>0,"% ",""))) -> NO | M8: =SUBSTITUTE(SUBSTITUTE(SUBSTITUTE(SUBSTITUTE(SUBSTITUTE(SUBSTITUTE(SUBSTITUTE(SUBSTITUTE(SUBSTITUTE(SUBSTITUTE(SUBSTITUTE(SUBSTITUTE(SUBSTITUTE(SUBSTITUTE(SUBSTITUTE(SUBSTITUTE(SUBSTITUTE(SUBSTITUTE(SUBSTITUTE(SUBSTITUTE(SUBSTITUTE(SUBSTITUTE(SUBSTITUTE(SUBSTITUTE(SUBSTITUTE(SUBSTITUTE(SUBSTITUTE(SUBSTITUTE(SUBSTITUTE(SUBSTITUTE(SUBSTITUTE('Input Sheet'!J10,$E$3,$F$3),$E$4,$F$4),$E$5,$F$5),$E$6,$F$6),$E$7,$F$7),$E$8,$F$8),$E$9,$F$9),$E$10,$F$10),$E$11,$F$11),$E$12,$F$12),$E$13,$F$13),$E$14,$F$14),$E$15,$F$15),$E$16,$F$16),$E$17,$F$17),$E$18,$F$18),$E$19,$F$19),$E$20,$F$20),$E$21,$F$21),$E$22,$F$22),$E$23,$F$23),$E$24,$F$24),$E$25,$F$25),$E$26,$F$26),$E$27,$F$27),$E$28,$F$28),$E$29,$F$29),$E$30,$F$30),$E$31,$F$31),$E$32,$F$32),$E$33,$F$33) -> Tr | N8: =CONCATENATE(M8, IF('Input Sheet'!J10="",""," siderite in ")) -> Tr siderite in | O8: =SUBSTITUTE(SUBSTITUTE(SUBSTITUTE(SUBSTITUTE(SUBSTITUTE(SUBSTITUTE(SUBSTITUTE(SUBSTITUTE(SUBSTITUTE(SUBSTITUTE(SUBSTITUTE(SUBSTITUTE(SUBSTITUTE(SUBSTITUTE(SUBSTITUTE(SUBSTITUTE(SUBSTITUTE(SUBSTITUTE(SUBSTITUTE(SUBSTITUTE(SUBSTITUTE(SUBSTITUTE(SUBSTITUTE(SUBSTITUTE(SUBSTITUTE(SUBSTITUTE(SUBSTITUTE(SUBSTITUTE(SUBSTITUTE(SUBSTITUTE(SUBSTITUTE('Input Sheet'!K10,$E$3,$F$3),$E$4,$F$4),$E$5,$F$5),$E$6,$F$6),$E$7,$F$7),$E$8,$F$8),$E$9,$F$9),$E$10,$F$10),$E$11,$F$11),$E$12,$F$12),$E$13,$F$13),$E$14,$F$14),$E$15,$F$15),$E$16,$F$16),$E$17,$F$17),$E$18,$F$18),$E$19,$F$19),$E$20,$F$20),$E$21,$F$21),$E$22,$F$22),$E$23,$F$23),$E$24,$F$24),$E$25,$F$25),$E$26,$F$26),$E$27,$F$27),$E$28,$F$28),$E$29,$F$29),$E$30,$F$30),$E$31,$F$31),$E$32,$F$32),$E$33,$F$33) | P8: =CONCATENATE(O8, IF('Input Sheet'!K10="",""," siderite in "))
A9: =IF('Input Sheet'!C11="","",CONCATENATE("Sample ", 'Input Sheet'!B11, "m: ", N9, H9, "% ", "Siltstone, ", P9, 'Input Sheet'!C11, "% ", J9, " Sandstone, ", L9, K9, " FLUOR in SST. ", "TG ", 'Input Sheet'!I11, "U")) -> Sample 1580m: Tr siderite in 80% Siltstone, 20% very fine to fine Sandstone, NO FLUOR in SST. TG 7U | B9: =IF('Input Sheet'!C11="","",CONCATENATE("Sample ", 'Input Sheet'!B11, "m: ", O9, I9, "% ", "Siltstone, ", Q9, 'Input Sheet'!C11, "% ", K9, " Sandstone ")) -> Sample 1580m: veryfine to fine% Siltstone, 20% Sandstone | C9: =IF('Input Sheet'!C11="","",CONCATENATE("Sample ", 'Input Sheet'!B11, "m: ", N9,, L9, K9, " FLUOR in SST. ", "TG ", 'Input Sheet'!I11, "U")) -> Sample 1580m: Tr siderite in NO FLUOR in SST. TG 7U | E9: occ | F9: occasional | H9: =IF('Input Sheet'!C11="","",100-'Input Sheet'!C11) -> 80 | I9: =SUBSTITUTE(SUBSTITUTE(SUBSTITUTE(SUBSTITUTE(SUBSTITUTE(SUBSTITUTE(SUBSTITUTE(SUBSTITUTE(SUBSTITUTE(SUBSTITUTE(SUBSTITUTE(SUBSTITUTE(SUBSTITUTE(SUBSTITUTE(SUBSTITUTE(SUBSTITUTE(SUBSTITUTE(SUBSTITUTE(SUBSTITUTE(SUBSTITUTE(SUBSTITUTE(SUBSTITUTE(SUBSTITUTE(SUBSTITUTE(SUBSTITUTE(SUBSTITUTE(SUBSTITUTE(SUBSTITUTE(SUBSTITUTE(SUBSTITUTE(SUBSTITUTE('Input Sheet'!D11,$E$3,$F$3),$E$4,$F$4),$E$5,$F$5),$E$6,$F$6),$E$7,$F$7),$E$8,$F$8),$E$9,$F$9),$E$10,$F$10),$E$11,$F$11),$E$12,$F$12),$E$13,$F$13),$E$14,$F$14),$E$15,$F$15),$E$16,$F$16),$E$17,$F$17),$E$18,$F$18),$E$19,$F$19),$E$20,$F$20),$E$21,$F$21),$E$22,$F$22),$E$23,$F$23),$E$24,$F$24),$E$25,$F$25),$E$26,$F$26),$E$27,$F$27),$E$28,$F$28),$E$29,$F$29),$E$30,$F$30),$E$31,$F$31),$E$32,$F$32),$E$33,$F$33) -> veryfine to fine | J9: =SUBSTITUTE(I9, "veryfine", "very fine") -> very fine to fine | K9: =SUBSTITUTE(SUBSTITUTE(SUBSTITUTE(SUBSTITUTE(SUBSTITUTE(SUBSTITUTE(SUBSTITUTE(SUBSTITUTE(SUBSTITUTE(SUBSTITUTE(SUBSTITUTE(SUBSTITUTE(SUBSTITUTE(SUBSTITUTE(SUBSTITUTE(SUBSTITUTE(SUBSTITUTE(SUBSTITUTE(SUBSTITUTE(SUBSTITUTE(SUBSTITUTE(SUBSTITUTE(SUBSTITUTE(SUBSTITUTE(SUBSTITUTE(SUBSTITUTE(SUBSTITUTE(SUBSTITUTE(SUBSTITUTE(SUBSTITUTE(SUBSTITUTE('Input Sheet'!G11,$E$3,$F$3),$E$4,$F$4),$E$5,$F$5),$E$6,$F$6),$E$7,$F$7),$E$8,$F$8),$E$9,$F$9),$E$10,$F$10),$E$11,$F$11),$E$12,$F$12),$E$13,$F$13),$E$14,$F$14),$E$15,$F$15),$E$16,$F$16),$E$17,$F$17),$E$18,$F$18),$E$19,$F$19),$E$20,$F$20),$E$21,$F$21),$E$22,$F$22),$E$23,$F$23),$E$24,$F$24),$E$25,$F$25),$E$26,$F$26),$E$27,$F$27),$E$28,$F$28),$E$29,$F$29),$E$30,$F$30),$E$31,$F$31),$E$32,$F$32),$E$33,$F$33) | L9: =IF('Input Sheet'!F11=0, "NO",CONCATENATE('Input Sheet'!F11, IF('Input Sheet'!F11>0,"% ",""))) -> NO | M9: =SUBSTITUTE(SUBSTITUTE(SUBSTITUTE(SUBSTITUTE(SUBSTITUTE(SUBSTITUTE(SUBSTITUTE(SUBSTITUTE(SUBSTITUTE(SUBSTITUTE(SUBSTITUTE(SUBSTITUTE(SUBSTITUTE(SUBSTITUTE(SUBSTITUTE(SUBSTITUTE(SUBSTITUTE(SUBSTITUTE(SUBSTITUTE(SUBSTITUTE(SUBSTITUTE(SUBSTITUTE(SUBSTITUTE(SUBSTITUTE(SUBSTITUTE(SUBSTITUTE(SUBSTITUTE(SUBSTITUTE(SUBSTITUTE(SUBSTITUTE(SUBSTITUTE('Input Sheet'!J11,$E$3,$F$3),$E$4,$F$4),$E$5,$F$5),$E$6,$F$6),$E$7,$F$7),$E$8,$F$8),$E$9,$F$9),$E$10,$F$10),$E$11,$F$11),$E$12,$F$12),$E$13,$F$13),$E$14,$F$14),$E$15,$F$15),$E$16,$F$16),$E$17,$F$17),$E$18,$F$18),$E$19,$F$19),$E$20,$F$20),$E$21,$F$21),$E$22,$F$22),$E$23,$F$23),$E$24,$F$24),$E$25,$F$25),$E$26,$F$26),$E$27,$F$27),$E$28,$F$28),$E$29,$F$29),$E$30,$F$30),$E$31,$F$31),$E$32,$F$32),$E$33,$F$33) -> Tr | N9: =CONCATENATE(M9, IF('Input Sheet'!J11="",""," siderite in ")) -> Tr siderite in | O9: =SUBSTITUTE(SUBSTITUTE(SUBSTITUTE(SUBSTITUTE(SUBSTITUTE(SUBSTITUTE(SUBSTITUTE(SUBSTITUTE(SUBSTITUTE(SUBSTITUTE(SUBSTITUTE(SUBSTITUTE(SUBSTITUTE(SUBSTITUTE(SUBSTITUTE(SUBSTITUTE(SUBSTITUTE(SUBSTITUTE(SUBSTITUTE(SUBSTITUTE(SUBSTITUTE(SUBSTITUTE(SUBSTITUTE(SUBSTITUTE(SUBSTITUTE(SUBSTITUTE(SUBSTITUTE(SUBSTITUTE(SUBSTITUTE(SUBSTITUTE(SUBSTITUTE('Input Sheet'!K11,$E$3,$F$3),$E$4,$F$4),$E$5,$F$5),$E$6,$F$6),$E$7,$F$7),$E$8,$F$8),$E$9,$F$9),$E$10,$F$10),$E$11,$F$11),$E$12,$F$12),$E$13,$F$13),$E$14,$F$14),$E$15,$F$15),$E$16,$F$16),$E$17,$F$17),$E$18,$F$18),$E$19,$F$19),$E$20,$F$20),$E$21,$F$21),$E$22,$F$22),$E$23,$F$23),$E$24,$F$24),$E$25,$F$25),$E$26,$F$26),$E$27,$F$27),$E$28,$F$28),$E$29,$F$29),$E$30,$F$30),$E$31,$F$31),$E$32,$F$32),$E$33,$F$33) | P9: =CONCATENATE(O9, IF('Input Sheet'!K11="",""," siderite in "))
A10: =IF('Input Sheet'!C12="","",CONCATENATE("Sample ", 'Input Sheet'!B12, "m: ", N10, H10, "% ", "Siltstone, ", P10, 'Input Sheet'!C12, "% ", J10, " Sandstone, ", L10, K10, " FLUOR in SST. ", "TG ", 'Input Sheet'!I12, "U")) -> Sample 1585m: Tr siderite in 80% Siltstone, 20% very fine to fine Sandstone, NO FLUOR in SST. TG 8U | B10: =IF('Input Sheet'!C12="","",CONCATENATE("Sample ", 'Input Sheet'!B12, "m: ", O10, I10, "% ", "Siltstone, ", Q10, 'Input Sheet'!C12, "% ", K10, " Sandstone ")) -> Sample 1585m: veryfine to fine% Siltstone, 20% Sandstone | C10: =IF('Input Sheet'!C12="","",CONCATENATE("Sample ", 'Input Sheet'!B12, "m: ", N10,, L10, K10, " FLUOR in SST. ", "TG ", 'Input Sheet'!I12, "U")) -> Sample 1585m: Tr siderite in NO FLUOR in SST. TG 8U | E10: mnr | F10: minor | H10: =IF('Input Sheet'!C12="","",100-'Input Sheet'!C12) -> 80 | I10: =SUBSTITUTE(SUBSTITUTE(SUBSTITUTE(SUBSTITUTE(SUBSTITUTE(SUBSTITUTE(SUBSTITUTE(SUBSTITUTE(SUBSTITUTE(SUBSTITUTE(SUBSTITUTE(SUBSTITUTE(SUBSTITUTE(SUBSTITUTE(SUBSTITUTE(SUBSTITUTE(SUBSTITUTE(SUBSTITUTE(SUBSTITUTE(SUBSTITUTE(SUBSTITUTE(SUBSTITUTE(SUBSTITUTE(SUBSTITUTE(SUBSTITUTE(SUBSTITUTE(SUBSTITUTE(SUBSTITUTE(SUBSTITUTE(SUBSTITUTE(SUBSTITUTE('Input Sheet'!D12,$E$3,$F$3),$E$4,$F$4),$E$5,$F$5),$E$6,$F$6),$E$7,$F$7),$E$8,$F$8),$E$9,$F$9),$E$10,$F$10),$E$11,$F$11),$E$12,$F$12),$E$13,$F$13),$E$14,$F$14),$E$15,$F$15),$E$16,$F$16),$E$17,$F$17),$E$18,$F$18),$E$19,$F$19),$E$20,$F$20),$E$21,$F$21),$E$22,$F$22),$E$23,$F$23),$E$24,$F$24),$E$25,$F$25),$E$26,$F$26),$E$27,$F$27),$E$28,$F$28),$E$29,$F$29),$E$30,$F$30),$E$31,$F$31),$E$32,$F$32),$E$33,$F$33) -> veryfine to fine | J10: =SUBSTITUTE(I10, "veryfine", "very fine") -> very fine to fine | K10: =SUBSTITUTE(SUBSTITUTE(SUBSTITUTE(SUBSTITUTE(SUBSTITUTE(SUBSTITUTE(SUBSTITUTE(SUBSTITUTE(SUBSTITUTE(SUBSTITUTE(SUBSTITUTE(SUBSTITUTE(SUBSTITUTE(SUBSTITUTE(SUBSTITUTE(SUBSTITUTE(SUBSTITUTE(SUBSTITUTE(SUBSTITUTE(SUBSTITUTE(SUBSTITUTE(SUBSTITUTE(SUBSTITUTE(SUBSTITUTE(SUBSTITUTE(SUBSTITUTE(SUBSTITUTE(SUBSTITUTE(SUBSTITUTE(SUBSTITUTE(SUBSTITUTE('Input Sheet'!G12,$E$3,$F$3),$E$4,$F$4),$E$5,$F$5),$E$6,$F$6),$E$7,$F$7),$E$8,$F$8),$E$9,$F$9),$E$10,$F$10),$E$11,$F$11),$E$12,$F$12),$E$13,$F$13),$E$14,$F$14),$E$15,$F$15),$E$16,$F$16),$E$17,$F$17),$E$18,$F$18),$E$19,$F$19),$E$20,$F$20),$E$21,$F$21),$E$22,$F$22),$E$23,$F$23),$E$24,$F$24),$E$25,$F$25),$E$26,$F$26),$E$27,$F$27),$E$28,$F$28),$E$29,$F$29),$E$30,$F$30),$E$31,$F$31),$E$32,$F$32),$E$33,$F$33) | L10: =IF('Input Sheet'!F12=0, "NO",CONCATENATE('Input Sheet'!F12, IF('Input Sheet'!F12>0,"% ",""))) -> NO | M10: =SUBSTITUTE(SUBSTITUTE(SUBSTITUTE(SUBSTITUTE(SUBSTITUTE(SUBSTITUTE(SUBSTITUTE(SUBSTITUTE(SUBSTITUTE(SUBSTITUTE(SUBSTITUTE(SUBSTITUTE(SUBSTITUTE(SUBSTITUTE(SUBSTITUTE(SUBSTITUTE(SUBSTITUTE(SUBSTITUTE(SUBSTITUTE(SUBSTITUTE(SUBSTITUTE(SUBSTITUTE(SUBSTITUTE(SUBSTITUTE(SUBSTITUTE(SUBSTITUTE(SUBSTITUTE(SUBSTITUTE(SUBSTITUTE(SUBSTITUTE(SUBSTITUTE('Input Sheet'!J12,$E$3,$F$3),$E$4,$F$4),$E$5,$F$5),$E$6,$F$6),$E$7,$F$7),$E$8,$F$8),$E$9,$F$9),$E$10,$F$10),$E$11,$F$11),$E$12,$F$12),$E$13,$F$13),$E$14,$F$14),$E$15,$F$15),$E$16,$F$16),$E$17,$F$17),$E$18,$F$18),$E$19,$F$19),$E$20,$F$20),$E$21,$F$21),$E$22,$F$22),$E$23,$F$23),$E$24,$F$24),$E$25,$F$25),$E$26,$F$26),$E$27,$F$27),$E$28,$F$28),$E$29,$F$29),$E$30,$F$30),$E$31,$F$31),$E$32,$F$32),$E$33,$F$33) -> Tr | N10: =CONCATENATE(M10, IF('Input Sheet'!J12="",""," siderite in ")) -> Tr siderite in | O10: =SUBSTITUTE(SUBSTITUTE(SUBSTITUTE(SUBSTITUTE(SUBSTITUTE(SUBSTITUTE(SUBSTITUTE(SUBSTITUTE(SUBSTITUTE(SUBSTITUTE(SUBSTITUTE(SUBSTITUTE(SUBSTITUTE(SUBSTITUTE(SUBSTITUTE(SUBSTITUTE(SUBSTITUTE(SUBSTITUTE(SUBSTITUTE(SUBSTITUTE(SUBSTITUTE(SUBSTITUTE(SUBSTITUTE(SUBSTITUTE(SUBSTITUTE(SUBSTITUTE(SUBSTITUTE(SUBSTITUTE(SUBSTITUTE(SUBSTITUTE(SUBSTITUTE('Input Sheet'!K12,$E$3,$F$3),$E$4,$F$4),$E$5,$F$5),$E$6,$F$6),$E$7,$F$7),$E$8,$F$8),$E$9,$F$9),$E$10,$F$10),$E$11,$F$11),$E$12,$F$12),$E$13,$F$13),$E$14,$F$14),$E$15,$F$15),$E$16,$F$16),$E$17,$F$17),$E$18,$F$18),$E$19,$F$19),$E$20,$F$20),$E$21,$F$21),$E$22,$F$22),$E$23,$F$23),$E$24,$F$24),$E$25,$F$25),$E$26,$F$26),$E$27,$F$27),$E$28,$F$28),$E$29,$F$29),$E$30,$F$30),$E$31,$F$31),$E$32,$F$32),$E$33,$F$33) | P10: =CONCATENATE(O10, IF('Input Sheet'!K12="",""," siderite in "))
A11: =IF('Input Sheet'!C13="","",CONCATENATE("Sample ", 'Input Sheet'!B13, "m: ", N11, H11, "% ", "Siltstone, ", P11, 'Input Sheet'!C13, "% ", J11, " Sandstone, ", L11, K11, " FLUOR in SST. ", "TG ", 'Input Sheet'!I13, "U")) -> Sample 1590m: Tr siderite in 80% Siltstone, 20% very fine to fine Sandstone, NO FLUOR in SST. TG 7U | B11: =IF('Input Sheet'!C13="","",CONCATENATE("Sample ", 'Input Sheet'!B13, "m: ", O11, I11, "% ", "Siltstone, ", Q11, 'Input Sheet'!C13, "% ", K11, " Sandstone ")) -> Sample 1590m: veryfine to fine% Siltstone, 20% Sandstone | C11: =IF('Input Sheet'!C13="","",CONCATENATE("Sample ", 'Input Sheet'!B13, "m: ", N11,, L11, K11, " FLUOR in SST. ", "TG ", 'Input Sheet'!I13, "U")) -> Sample 1590m: Tr siderite in NO FLUOR in SST. TG 7U | E11: rr | F11: rare | H11: =IF('Input Sheet'!C13="","",100-'Input Sheet'!C13) -> 80 | I11: =SUBSTITUTE(SUBSTITUTE(SUBSTITUTE(SUBSTITUTE(SUBSTITUTE(SUBSTITUTE(SUBSTITUTE(SUBSTITUTE(SUBSTITUTE(SUBSTITUTE(SUBSTITUTE(SUBSTITUTE(SUBSTITUTE(SUBSTITUTE(SUBSTITUTE(SUBSTITUTE(SUBSTITUTE(SUBSTITUTE(SUBSTITUTE(SUBSTITUTE(SUBSTITUTE(SUBSTITUTE(SUBSTITUTE(SUBSTITUTE(SUBSTITUTE(SUBSTITUTE(SUBSTITUTE(SUBSTITUTE(SUBSTITUTE(SUBSTITUTE(SUBSTITUTE('Input Sheet'!D13,$E$3,$F$3),$E$4,$F$4),$E$5,$F$5),$E$6,$F$6),$E$7,$F$7),$E$8,$F$8),$E$9,$F$9),$E$10,$F$10),$E$11,$F$11),$E$12,$F$12),$E$13,$F$13),$E$14,$F$14),$E$15,$F$15),$E$16,$F$16),$E$17,$F$17),$E$18,$F$18),$E$19,$F$19),$E$20,$F$20),$E$21,$F$21),$E$22,$F$22),$E$23,$F$23),$E$24,$F$24),$E$25,$F$25),$E$26,$F$26),$E$27,$F$27),$E$28,$F$28),$E$29,$F$29),$E$30,$F$30),$E$31,$F$31),$E$32,$F$32),$E$33,$F$33) -> veryfine to fine | J11: =SUBSTITUTE(I11, "veryfine", "very fine") -> very fine to fine | K11: =SUBSTITUTE(SUBSTITUTE(SUBSTITUTE(SUBSTITUTE(SUBSTITUTE(SUBSTITUTE(SUBSTITUTE(SUBSTITUTE(SUBSTITUTE(SUBSTITUTE(SUBSTITUTE(SUBSTITUTE(SUBSTITUTE(SUBSTITUTE(SUBSTITUTE(SUBSTITUTE(SUBSTITUTE(SUBSTITUTE(SUBSTITUTE(SUBSTITUTE(SUBSTITUTE(SUBSTITUTE(SUBSTITUTE(SUBSTITUTE(SUBSTITUTE(SUBSTITUTE(SUBSTITUTE(SUBSTITUTE(SUBSTITUTE(SUBSTITUTE(SUBSTITUTE('Input Sheet'!G13,$E$3,$F$3),$E$4,$F$4),$E$5,$F$5),$E$6,$F$6),$E$7,$F$7),$E$8,$F$8),$E$9,$F$9),$E$10,$F$10),$E$11,$F$11),$E$12,$F$12),$E$13,$F$13),$E$14,$F$14),$E$15,$F$15),$E$16,$F$16),$E$17,$F$17),$E$18,$F$18),$E$19,$F$19),$E$20,$F$20),$E$21,$F$21),$E$22,$F$22),$E$23,$F$23),$E$24,$F$24),$E$25,$F$25),$E$26,$F$26),$E$27,$F$27),$E$28,$F$28),$E$29,$F$29),$E$30,$F$30),$E$31,$F$31),$E$32,$F$32),$E$33,$F$33) | L11: =IF('Input Sheet'!F13=0, "NO",CONCATENATE('Input Sheet'!F13, IF('Input Sheet'!F13>0,"% ",""))) -> NO | M11: =SUBSTITUTE(SUBSTITUTE(SUBSTITUTE(SUBSTITUTE(SUBSTITUTE(SUBSTITUTE(SUBSTITUTE(SUBSTITUTE(SUBSTITUTE(SUBSTITUTE(SUBSTITUTE(SUBSTITUTE(SUBSTITUTE(SUBSTITUTE(SUBSTITUTE(SUBSTITUTE(SUBSTITUTE(SUBSTITUTE(SUBSTITUTE(SUBSTITUTE(SUBSTITUTE(SUBSTITUTE(SUBSTITUTE(SUBSTITUTE(SUBSTITUTE(SUBSTITUTE(SUBSTITUTE(SUBSTITUTE(SUBSTITUTE(SUBSTITUTE(SUBSTITUTE('Input Sheet'!J13,$E$3,$F$3),$E$4,$F$4),$E$5,$F$5),$E$6,$F$6),$E$7,$F$7),$E$8,$F$8),$E$9,$F$9),$E$10,$F$10),$E$11,$F$11),$E$12,$F$12),$E$13,$F$13),$E$14,$F$14),$E$15,$F$15),$E$16,$F$16),$E$17,$F$17),$E$18,$F$18),$E$19,$F$19),$E$20,$F$20),$E$21,$F$21),$E$22,$F$22),$E$23,$F$23),$E$24,$F$24),$E$25,$F$25),$E$26,$F$26),$E$27,$F$27),$E$28,$F$28),$E$29,$F$29),$E$30,$F$30),$E$31,$F$31),$E$32,$F$32),$E$33,$F$33) -> Tr | N11: =CONCATENATE(M11, IF('Input Sheet'!J13="",""," siderite in ")) -> Tr siderite in | O11: =SUBSTITUTE(SUBSTITUTE(SUBSTITUTE(SUBSTITUTE(SUBSTITUTE(SUBSTITUTE(SUBSTITUTE(SUBSTITUTE(SUBSTITUTE(SUBSTITUTE(SUBSTITUTE(SUBSTITUTE(SUBSTITUTE(SUBSTITUTE(SUBSTITUTE(SUBSTITUTE(SUBSTITUTE(SUBSTITUTE(SUBSTITUTE(SUBSTITUTE(SUBSTITUTE(SUBSTITUTE(SUBSTITUTE(SUBSTITUTE(SUBSTITUTE(SUBSTITUTE(SUBSTITUTE(SUBSTITUTE(SUBSTITUTE(SUBSTITUTE(SUBSTITUTE('Input Sheet'!K13,$E$3,$F$3),$E$4,$F$4),$E$5,$F$5),$E$6,$F$6),$E$7,$F$7),$E$8,$F$8),$E$9,$F$9),$E$10,$F$10),$E$11,$F$11),$E$12,$F$12),$E$13,$F$13),$E$14,$F$14),$E$15,$F$15),$E$16,$F$16),$E$17,$F$17),$E$18,$F$18),$E$19,$F$19),$E$20,$F$20),$E$21,$F$21),$E$22,$F$22),$E$23,$F$23),$E$24,$F$24),$E$25,$F$25),$E$26,$F$26),$E$27,$F$27),$E$28,$F$28),$E$29,$F$29),$E$30,$F$30),$E$31,$F$31),$E$32,$F$32),$E$33,$F$33) | P11: =CONCATENATE(O11, IF('Input Sheet'!K13="",""," siderite in "))
